Workbook

Sheet Sheet1
A1: Citation (APA 7th-Annotated) | B1: sequence | C1: DOI if different from article or doi Alt | D1: Item number | E1: end | F1: Publication name | G1: 1st Author | H1: other author(s) | I1: year | J1: DOI (or Alt) | K1: Item name | L1: Item encoded | M1: Item in directory FileList | N1: Item full original title | O1: Note about item | P1: Progress stage | Q1: Online Database | R1: Snapshot | S1: Adjustment made | T1: Data readable file, can use this | U1: Source Type | V1: Source format | W1: Source URL direct access | X1: Source URL link | Y1: Team | Z1: Collection | AA1: Possible Traits | AB1: Note | AC1: Flags pre-addressed | AD1: Flags possible | AE1: Flags active (skips) | AF1: Sample type | AG1: Method | AH1: Subcategory | AI1: Main Trait(s) | AJ1: Taxon group | AK1: Source type | AL1: Data role (primary/secondary/both) | AM1: Measure type
A2: Andelin, A. K., Olavarria, J. F., Fine, I., Taber, E. N., Schwartz, D., Kroenke, C. D., & Stevens, A. A. (2019). The Effect of Onset Age of Visual Deprivation on Visual Cortex Surface Area Across-Species. Cereb Cortex, 29(10), 4321-4333. https://doi.org/10.1093/cercor/bhy315 | D2: Table 4 | E2: =RIGHT(A2,1) -> 5 | F2: =G2 & IF(H2<>"", "_" & H2, "_") & IF(I2<>"", "_" & I2, "_") & IF(B2<>"", "_" & B2, "") -> Andelin_etal_2019 | G2: =SUBSTITUTE(SUBSTITUTE(_xlfn.TEXTBEFORE(A2,","), "-", ""), " ", "") -> Andelin | H2: =_xlfn.LET( _xlpm.authors,_xlfn.TEXTBEFORE(A2," ("&I2&")"), _xlpm.hasAmp,ISNUMBER(SEARCH("&",_xlpm.authors)), _xlpm.commasBeforeAmp,IF(_xlpm.hasAmp,LEN(_xlfn.TEXTBEFORE(_xlpm.authors,"&"))-LEN(SUBSTITUTE(_xlfn.TEXTBEFORE(_xlpm.authors,"&"),",","")),0), IF(NOT(_xlpm.hasAmp),"",IF(_xlpm.commasBeforeAmp>2,"etal",TRIM(_xlfn.TEXTBEFORE(_xlfn.TEXTAFTER(_xlpm.authors,"& "),",")))) ) -> etal | I2: =_xlfn.TEXTBEFORE(_xlfn.TEXTAFTER(A2, "("), ")") -> 2019 | J2: =_xlfn.LET( _xlpm.doi,IF(C2<>"",C2,_xlfn.TEXTAFTER(A2,"https://doi.org/")), SUBSTITUTE( SUBSTITUTE( SUBSTITUTE( SUBSTITUTE( _xlpm.doi, "/","%2F"), ":","%3A"), "<","%3C"), ">","%3E") ) -> 10.1093%2Fcercor%2Fbhy315 | K2: =TRIM(_xlfn.TEXTJOIN("_",FALSE(),F2,(SUBSTITUTE(SUBSTITUTE(D2," ",""), "_", "")))) -> Andelin_etal_2019_Table4 | L2: =J2 & "_" & SUBSTITUTE(SUBSTITUTE(SUBSTITUTE(D2,CHAR(160),"")," ",""),"_","") -> 10.1093%2Fcercor%2Fbhy315_Table4 | M2: {=IFERROR(INDEX(FileList!$A$1:$A$100,MATCH(TRUE(),EXACT(L2,_xlfn.TEXTBEFORE(FileList!$A$1:$A$100,".tsv")),0)),"notfound")} -> 10.1093%2Fcercor%2Fbhy315_Table4.tsv | P2: FINISHED | V2: table | AJ2: review | AL2: review | AM2: review
A3: Ashwell, K. W. S. (2020). Quantitative analysis of cerebellar morphology in monotreme, metatherian and eutherian mammals. Zoology (Jena), 139, 125753. https://doi.org/10.1016/j.zool.2020.125753 | D3: Supplementary Table | E3: =RIGHT(A3,1) -> 3 | F3: =G3 & IF(H3<>"", "_" & H3, "_") & IF(I3<>"", "_" & I3, "_") & IF(B3<>"", "_" & B3, "") -> Ashwell__2020 | G3: =SUBSTITUTE(SUBSTITUTE(_xlfn.TEXTBEFORE(A3,","), "-", ""), " ", "") -> Ashwell | H3: =_xlfn.LET( _xlpm.authors,_xlfn.TEXTBEFORE(A3," ("&I3&")"), _xlpm.hasAmp,ISNUMBER(SEARCH("&",_xlpm.authors)), _xlpm.commasBeforeAmp,IF(_xlpm.hasAmp,LEN(_xlfn.TEXTBEFORE(_xlpm.authors,"&"))-LEN(SUBSTITUTE(_xlfn.TEXTBEFORE(_xlpm.authors,"&"),",","")),0), IF(NOT(_xlpm.hasAmp),"",IF(_xlpm.commasBeforeAmp>2,"etal",TRIM(_xlfn.TEXTBEFORE(_xlfn.TEXTAFTER(_xlpm.authors,"& "),",")))) ) | I3: =_xlfn.TEXTBEFORE(_xlfn.TEXTAFTER(A3, "("), ")") -> 2020 | J3: =_xlfn.LET( _xlpm.doi,IF(C3<>"",C3,_xlfn.TEXTAFTER(A3,"https://doi.org/")), SUBSTITUTE( SUBSTITUTE( SUBSTITUTE( SUBSTITUTE( _xlpm.doi, "/","%2F"), ":","%3A"), "<","%3C"), ">","%3E") ) -> 10.1016%2Fj.zool.2020.125753 | K3: =TRIM(_xlfn.TEXTJOIN("_",FALSE(),F3,(SUBSTITUTE(SUBSTITUTE(D3," ",""), "_", "")))) -> Ashwell__2020_SupplementaryTable | L3: =J3 & "_" & SUBSTITUTE(SUBSTITUTE(SUBSTITUTE(D3,CHAR(160),"")," ",""),"_","") -> 10.1016%2Fj.zool.2020.125753_SupplementaryTable | M3: {=IFERROR(INDEX(FileList!$A$1:$A$100,MATCH(TRUE(),EXACT(L3,_xlfn.TEXTBEFORE(FileList!$A$1:$A$100,".tsv")),0)),"notfound")} -> 10.1016%2Fj.zool.2020.125753_SupplementaryTable.tsv | N3: Supplementary Table. Cerebellar Morphology Data | P3: FINISHED | Y3: Ashwell
A4: Avelino-de-Souza, K., Patzke, N., Karlsson, K. A. E., Manger, P. R., & Herculano-Houzel, S. (2025). Cellular Composition of the Brain of a Northern Minke Whale. J Comp Neurol, 533(9), e70089. https://doi.org/10.1002/cne.70089 | D4: TABLE 1 | E4: =RIGHT(A4,1) -> 9 | F4: =G4 & IF(H4<>"", "_" & H4, "_") & IF(I4<>"", "_" & I4, "_") & IF(B4<>"", "_" & B4, "") -> AvelinodeSouza_etal_2025 | G4: =SUBSTITUTE(SUBSTITUTE(_xlfn.TEXTBEFORE(A4,","), "-", ""), " ", "") -> AvelinodeSouza | H4: =_xlfn.LET( _xlpm.authors,_xlfn.TEXTBEFORE(A4," ("&I4&")"), _xlpm.hasAmp,ISNUMBER(SEARCH("&",_xlpm.authors)), _xlpm.commasBeforeAmp,IF(_xlpm.hasAmp,LEN(_xlfn.TEXTBEFORE(_xlpm.authors,"&"))-LEN(SUBSTITUTE(_xlfn.TEXTBEFORE(_xlpm.authors,"&"),",","")),0), IF(NOT(_xlpm.hasAmp),"",IF(_xlpm.commasBeforeAmp>2,"etal",TRIM(_xlfn.TEXTBEFORE(_xlfn.TEXTAFTER(_xlpm.authors,"& "),",")))) ) -> etal | I4: =_xlfn.TEXTBEFORE(_xlfn.TEXTAFTER(A4, "("), ")") -> 2025 | J4: =_xlfn.LET( _xlpm.doi,IF(C4<>"",C4,_xlfn.TEXTAFTER(A4,"https://doi.org/")), SUBSTITUTE( SUBSTITUTE( SUBSTITUTE( SUBSTITUTE( _xlpm.doi, "/","%2F"), ":","%3A"), "<","%3C"), ">","%3E") ) -> 10.1002%2Fcne.70089 | K4: =TRIM(_xlfn.TEXTJOIN("_",FALSE(),F4,(SUBSTITUTE(SUBSTITUTE(D4," ",""), "_", "")))) -> AvelinodeSouza_etal_2025_TABLE1 | L4: =J4 & "_" & SUBSTITUTE(SUBSTITUTE(SUBSTITUTE(D4,CHAR(160),"")," ",""),"_","") -> 10.1002%2Fcne.70089_TABLE1 | M4: {=IFERROR(INDEX(FileList!$A$1:$A$100,MATCH(TRUE(),EXACT(L4,_xlfn.TEXTBEFORE(FileList!$A$1:$A$100,".tsv")),0)),"notfound")} -> 10.1002%2Fcne.70089_TABLE1.tsv | N4: Table 1. Cellular composition of the brain of a Northern minke whale (Balaenoptera acutorostrata) | P4: FINISHED | Q4: added | R4: AvelinodeSouza_etal_2025_TABLE1_snapshot.csv | S4: Y | T4: AvelinodeSouza_etal_2025_TABLE1.csv | U4: pdf | V4: table | W4: https://onlinelibrary.wiley.com/doi/10.1002/cne.70089 | X4: https://doi.org/10.1002/cne.70089 | Y4: HH | AG4: isotropic fractionator | AH4: placental mammals | AI4: neuron number | AJ4: Cetaceans & other placental mammals | AK4: primary | AL4: primary | AM4: cell count (isotropic fractionator)
A5: Balzeau, A., Holloway, R. L., & Grimaud-Herve, D. (2012). Variations and asymmetries in regional brain surface in the genus Homo. J Hum Evol, 62(6), 696-706. https://doi.org/10.1016/j.jhevol.2012.03.007 | D5: Table 3 | E5: =RIGHT(A5,1) -> 7 | F5: =G5 & IF(H5<>"", "_" & H5, "_") & IF(I5<>"", "_" & I5, "_") & IF(B5<>"", "_" & B5, "") -> Balzeau_etal_2012 | G5: =SUBSTITUTE(SUBSTITUTE(_xlfn.TEXTBEFORE(A5,","), "-", ""), " ", "") -> Balzeau | H5: =_xlfn.LET( _xlpm.authors,_xlfn.TEXTBEFORE(A5," ("&I5&")"), _xlpm.hasAmp,ISNUMBER(SEARCH("&",_xlpm.authors)), _xlpm.commasBeforeAmp,IF(_xlpm.hasAmp,LEN(_xlfn.TEXTBEFORE(_xlpm.authors,"&"))-LEN(SUBSTITUTE(_xlfn.TEXTBEFORE(_xlpm.authors,"&"),",","")),0), IF(NOT(_xlpm.hasAmp),"",IF(_xlpm.commasBeforeAmp>2,"etal",TRIM(_xlfn.TEXTBEFORE(_xlfn.TEXTAFTER(_xlpm.authors,"& "),",")))) ) -> etal | I5: =_xlfn.TEXTBEFORE(_xlfn.TEXTAFTER(A5, "("), ")") -> 2012 | J5: =_xlfn.LET( _xlpm.doi,IF(C5<>"",C5,_xlfn.TEXTAFTER(A5,"https://doi.org/")), SUBSTITUTE( SUBSTITUTE( SUBSTITUTE( SUBSTITUTE( _xlpm.doi, "/","%2F"), ":","%3A"), "<","%3C"), ">","%3E") ) -> 10.1016%2Fj.jhevol.2012.03.007 | K5: =TRIM(_xlfn.TEXTJOIN("_",FALSE(),F5,(SUBSTITUTE(SUBSTITUTE(D5," ",""), "_", "")))) -> Balzeau_etal_2012_Table3 | L5: =J5 & "_" & SUBSTITUTE(SUBSTITUTE(SUBSTITUTE(D5,CHAR(160),"")," ",""),"_","") -> 10.1016%2Fj.jhevol.2012.03.007_Table3 | M5: {=IFERROR(INDEX(FileList!$A$1:$A$100,MATCH(TRUE(),EXACT(L5,_xlfn.TEXTBEFORE(FileList!$A$1:$A$100,".tsv")),0)),"notfound")} -> 10.1016%2Fj.jhevol.2012.03.007_Table3.tsv | N5: Table 3 Size-corrected dimensions for the surface of the frontal, parieto-temporal and occipital lobes in the different analysed samples.
A6: Balzeau, A., Holloway, R. L., & Grimaud-Herve, D. (2012). Variations and asymmetries in regional brain surface in the genus Homo. J Hum Evol, 62(6), 696-706. https://doi.org/10.1016/j.jhevol.2012.03.007 | D6: Table 5 | E6: =RIGHT(A6,1) -> 7 | F6: =G6 & IF(H6<>"", "_" & H6, "_") & IF(I6<>"", "_" & I6, "_") & IF(B6<>"", "_" & B6, "") -> Balzeau_etal_2012 | G6: =SUBSTITUTE(SUBSTITUTE(_xlfn.TEXTBEFORE(A6,","), "-", ""), " ", "") -> Balzeau | H6: =_xlfn.LET( _xlpm.authors,_xlfn.TEXTBEFORE(A6," ("&I6&")"), _xlpm.hasAmp,ISNUMBER(SEARCH("&",_xlpm.authors)), _xlpm.commasBeforeAmp,IF(_xlpm.hasAmp,LEN(_xlfn.TEXTBEFORE(_xlpm.authors,"&"))-LEN(SUBSTITUTE(_xlfn.TEXTBEFORE(_xlpm.authors,"&"),",","")),0), IF(NOT(_xlpm.hasAmp),"",IF(_xlpm.commasBeforeAmp>2,"etal",TRIM(_xlfn.TEXTBEFORE(_xlfn.TEXTAFTER(_xlpm.authors,"& "),",")))) ) -> etal | I6: =_xlfn.TEXTBEFORE(_xlfn.TEXTAFTER(A6, "("), ")") -> 2012 | J6: =_xlfn.LET( _xlpm.doi,IF(C6<>"",C6,_xlfn.TEXTAFTER(A6,"https://doi.org/")), SUBSTITUTE( SUBSTITUTE( SUBSTITUTE( SUBSTITUTE( _xlpm.doi, "/","%2F"), ":","%3A"), "<","%3C"), ">","%3E") ) -> 10.1016%2Fj.jhevol.2012.03.007 | K6: =TRIM(_xlfn.TEXTJOIN("_",FALSE(),F6,(SUBSTITUTE(SUBSTITUTE(D6," ",""), "_", "")))) -> Balzeau_etal_2012_Table5 | L6: =J6 & "_" & SUBSTITUTE(SUBSTITUTE(SUBSTITUTE(D6,CHAR(160),"")," ",""),"_","") -> 10.1016%2Fj.jhevol.2012.03.007_Table5 | M6: {=IFERROR(INDEX(FileList!$A$1:$A$100,MATCH(TRUE(),EXACT(L6,_xlfn.TEXTBEFORE(FileList!$A$1:$A$100,".tsv")),0)),"notfound")} -> 10.1016%2Fj.jhevol.2012.03.007_Table5.tsv | N6: Table 5 Percentage contribution of frontal, parieto-temporal and occipital lobes to the hemispheres.
A7: Barbeito-Andres, J., Castro-Fonseca, E., Qiu, L. R., Bernal, V., Lent, R., Henkelman, M., Lukowiak, K., Gleiser, P. M., Hallgrimsson, B., & Gonzalez, P. N. (2019). Region-specific changes in Mus musculus brain size and cell composition under chronic nutrient restriction. J Exp Biol, 222(Pt 17). https://doi.org/10.1242/jeb.204651 | D7: cell density | E7: =RIGHT(A7,1) -> 1 | F7: =G7 & IF(H7<>"", "_" & H7, "_") & IF(I7<>"", "_" & I7, "_") & IF(B7<>"", "_" & B7, "") -> BarbeitoAndres_etal_2019 | G7: =SUBSTITUTE(SUBSTITUTE(_xlfn.TEXTBEFORE(A7,","), "-", ""), " ", "") -> BarbeitoAndres | H7: =_xlfn.LET( _xlpm.authors,_xlfn.TEXTBEFORE(A7," ("&I7&")"), _xlpm.hasAmp,ISNUMBER(SEARCH("&",_xlpm.authors)), _xlpm.commasBeforeAmp,IF(_xlpm.hasAmp,LEN(_xlfn.TEXTBEFORE(_xlpm.authors,"&"))-LEN(SUBSTITUTE(_xlfn.TEXTBEFORE(_xlpm.authors,"&"),",","")),0), IF(NOT(_xlpm.hasAmp),"",IF(_xlpm.commasBeforeAmp>2,"etal",TRIM(_xlfn.TEXTBEFORE(_xlfn.TEXTAFTER(_xlpm.authors,"& "),",")))) ) -> etal | I7: =_xlfn.TEXTBEFORE(_xlfn.TEXTAFTER(A7, "("), ")") -> 2019 | J7: =_xlfn.LET( _xlpm.doi,IF(C7<>"",C7,_xlfn.TEXTAFTER(A7,"https://doi.org/")), SUBSTITUTE( SUBSTITUTE( SUBSTITUTE( SUBSTITUTE( _xlpm.doi, "/","%2F"), ":","%3A"), "<","%3C"), ">","%3E") ) -> 10.1242%2Fjeb.204651 | K7: =TRIM(_xlfn.TEXTJOIN("_",FALSE(),F7,(SUBSTITUTE(SUBSTITUTE(D7," ",""), "_", "")))) -> BarbeitoAndres_etal_2019_celldensity | L7: =J7 & "_" & SUBSTITUTE(SUBSTITUTE(SUBSTITUTE(D7,CHAR(160),"")," ",""),"_","") -> 10.1242%2Fjeb.204651_celldensity | M7: {=IFERROR(INDEX(FileList!$A$1:$A$100,MATCH(TRUE(),EXACT(L7,_xlfn.TEXTBEFORE(FileList!$A$1:$A$100,".tsv")),0)),"notfound")} -> notfound | AG7: isotropic fractionator | AJ7: review | AL7: review | AM7: review
A8: Barbeito-Andres, J., Castro-Fonseca, E., Qiu, L. R., Bernal, V., Lent, R., Henkelman, M., Lukowiak, K., Gleiser, P. M., Hallgrimsson, B., & Gonzalez, P. N. (2019). Region-specific changes in Mus musculus brain size and cell composition under chronic nutrient restriction. J Exp Biol, 222(Pt 17). https://doi.org/10.1242/jeb.204651 | D8: cell number | E8: =RIGHT(A8,1) -> 1 | F8: =G8 & IF(H8<>"", "_" & H8, "_") & IF(I8<>"", "_" & I8, "_") & IF(B8<>"", "_" & B8, "") -> BarbeitoAndres_etal_2019 | G8: =SUBSTITUTE(SUBSTITUTE(_xlfn.TEXTBEFORE(A8,","), "-", ""), " ", "") -> BarbeitoAndres | H8: =_xlfn.LET( _xlpm.authors,_xlfn.TEXTBEFORE(A8," ("&I8&")"), _xlpm.hasAmp,ISNUMBER(SEARCH("&",_xlpm.authors)), _xlpm.commasBeforeAmp,IF(_xlpm.hasAmp,LEN(_xlfn.TEXTBEFORE(_xlpm.authors,"&"))-LEN(SUBSTITUTE(_xlfn.TEXTBEFORE(_xlpm.authors,"&"),",","")),0), IF(NOT(_xlpm.hasAmp),"",IF(_xlpm.commasBeforeAmp>2,"etal",TRIM(_xlfn.TEXTBEFORE(_xlfn.TEXTAFTER(_xlpm.authors,"& "),",")))) ) -> etal | I8: =_xlfn.TEXTBEFORE(_xlfn.TEXTAFTER(A8, "("), ")") -> 2019 | J8: =_xlfn.LET( _xlpm.doi,IF(C8<>"",C8,_xlfn.TEXTAFTER(A8,"https://doi.org/")), SUBSTITUTE( SUBSTITUTE( SUBSTITUTE( SUBSTITUTE( _xlpm.doi, "/","%2F"), ":","%3A"), "<","%3C"), ">","%3E") ) -> 10.1242%2Fjeb.204651 | K8: =TRIM(_xlfn.TEXTJOIN("_",FALSE(),F8,(SUBSTITUTE(SUBSTITUTE(D8," ",""), "_", "")))) -> BarbeitoAndres_etal_2019_cellnumber | L8: =J8 & "_" & SUBSTITUTE(SUBSTITUTE(SUBSTITUTE(D8,CHAR(160),"")," ",""),"_","") -> 10.1242%2Fjeb.204651_cellnumber | M8: {=IFERROR(INDEX(FileList!$A$1:$A$100,MATCH(TRUE(),EXACT(L8,_xlfn.TEXTBEFORE(FileList!$A$1:$A$100,".tsv")),0)),"notfound")} -> notfound | AG8: isotropic fractionator | AJ8: review | AL8: review | AM8: review
A9: Barbeito-Andres, J., Castro-Fonseca, E., Qiu, L. R., Bernal, V., Lent, R., Henkelman, M., Lukowiak, K., Gleiser, P. M., Hallgrimsson, B., & Gonzalez, P. N. (2019). Region-specific changes in Mus musculus brain size and cell composition under chronic nutrient restriction. J Exp Biol, 222(Pt 17). https://doi.org/10.1242/jeb.204651 | D9: volumes | E9: =RIGHT(A9,1) -> 1 | F9: =G9 & IF(H9<>"", "_" & H9, "_") & IF(I9<>"", "_" & I9, "_") & IF(B9<>"", "_" & B9, "") -> BarbeitoAndres_etal_2019 | G9: =SUBSTITUTE(SUBSTITUTE(_xlfn.TEXTBEFORE(A9,","), "-", ""), " ", "") -> BarbeitoAndres | H9: =_xlfn.LET( _xlpm.authors,_xlfn.TEXTBEFORE(A9," ("&I9&")"), _xlpm.hasAmp,ISNUMBER(SEARCH("&",_xlpm.authors)), _xlpm.commasBeforeAmp,IF(_xlpm.hasAmp,LEN(_xlfn.TEXTBEFORE(_xlpm.authors,"&"))-LEN(SUBSTITUTE(_xlfn.TEXTBEFORE(_xlpm.authors,"&"),",","")),0), IF(NOT(_xlpm.hasAmp),"",IF(_xlpm.commasBeforeAmp>2,"etal",TRIM(_xlfn.TEXTBEFORE(_xlfn.TEXTAFTER(_xlpm.authors,"& "),",")))) ) -> etal | I9: =_xlfn.TEXTBEFORE(_xlfn.TEXTAFTER(A9, "("), ")") -> 2019 | J9: =_xlfn.LET( _xlpm.doi,IF(C9<>"",C9,_xlfn.TEXTAFTER(A9,"https://doi.org/")), SUBSTITUTE( SUBSTITUTE( SUBSTITUTE( SUBSTITUTE( _xlpm.doi, "/","%2F"), ":","%3A"), "<","%3C"), ">","%3E") ) -> 10.1242%2Fjeb.204651 | K9: =TRIM(_xlfn.TEXTJOIN("_",FALSE(),F9,(SUBSTITUTE(SUBSTITUTE(D9," ",""), "_", "")))) -> BarbeitoAndres_etal_2019_volumes | L9: =J9 & "_" & SUBSTITUTE(SUBSTITUTE(SUBSTITUTE(D9,CHAR(160),"")," ",""),"_","") -> 10.1242%2Fjeb.204651_volumes | M9: {=IFERROR(INDEX(FileList!$A$1:$A$100,MATCH(TRUE(),EXACT(L9,_xlfn.TEXTBEFORE(FileList!$A$1:$A$100,".tsv")),0)),"notfound")} -> notfound | AG9: isotropic fractionator | AJ9: review | AL9: review | AM9: review
A10: Barger, N., Hanson, K. L., Teffer, K., Schenker-Ahmed, N. M., & Semendeferi, K. (2014). Evidence for evolutionary specialization in human limbic structures. Front Hum Neurosci, 8, 277. https://doi.org/10.3389/fnhum.2014.00277 | D10: Table 1 | E10: =RIGHT(A10,1) -> 7 | F10: =G10 & IF(H10<>"", "_" & H10, "_") & IF(I10<>"", "_" & I10, "_") & IF(B10<>"", "_" & B10, "") -> Barger_etal_2014 | G10: =SUBSTITUTE(SUBSTITUTE(_xlfn.TEXTBEFORE(A10,","), "-", ""), " ", "") -> Barger | H10: =_xlfn.LET( _xlpm.authors,_xlfn.TEXTBEFORE(A10," ("&I10&")"), _xlpm.hasAmp,ISNUMBER(SEARCH("&",_xlpm.authors)), _xlpm.commasBeforeAmp,IF(_xlpm.hasAmp,LEN(_xlfn.TEXTBEFORE(_xlpm.authors,"&"))-LEN(SUBSTITUTE(_xlfn.TEXTBEFORE(_xlpm.authors,"&"),",","")),0), IF(NOT(_xlpm.hasAmp),"",IF(_xlpm.commasBeforeAmp>2,"etal",TRIM(_xlfn.TEXTBEFORE(_xlfn.TEXTAFTER(_xlpm.authors,"& "),",")))) ) -> etal | I10: =_xlfn.TEXTBEFORE(_xlfn.TEXTAFTER(A10, "("), ")") -> 2014 | J10: =_xlfn.LET( _xlpm.doi,IF(C10<>"",C10,_xlfn.TEXTAFTER(A10,"https://doi.org/")), SUBSTITUTE( SUBSTITUTE( SUBSTITUTE( SUBSTITUTE( _xlpm.doi, "/","%2F"), ":","%3A"), "<","%3C"), ">","%3E") ) -> 10.3389%2Ffnhum.2014.00277 | K10: =TRIM(_xlfn.TEXTJOIN("_",FALSE(),F10,(SUBSTITUTE(SUBSTITUTE(D10," ",""), "_", "")))) -> Barger_etal_2014_Table1 | L10: =J10 & "_" & SUBSTITUTE(SUBSTITUTE(SUBSTITUTE(D10,CHAR(160),"")," ",""),"_","") -> 10.3389%2Ffnhum.2014.00277_Table1 | M10: {=IFERROR(INDEX(FileList!$A$1:$A$100,MATCH(TRUE(),EXACT(L10,_xlfn.TEXTBEFORE(FileList!$A$1:$A$100,".tsv")),0)),"notfound")} -> notfound | N10: Table 1 | Volume of amygdala, hippocampus, and striatum in hominoid species collected with stereological methods. | Z10: Zilles | AF10: histological sections | AG10: Zilles
A11: Barger, N., Stefanacci, L., & Semendeferi, K. (2007). A comparative volumetric analysis of the amygdaloid complex and basolateral division in the human and ape brain. Am J Phys Anthropol, 134(3), 392-403. https://doi.org/10.1002/ajpa.20684 | D11: TABLE 1 | E11: =RIGHT(A11,1) -> 4 | F11: =G11 & IF(H11<>"", "_" & H11, "_") & IF(I11<>"", "_" & I11, "_") & IF(B11<>"", "_" & B11, "") -> Barger_etal_2007 | G11: =SUBSTITUTE(SUBSTITUTE(_xlfn.TEXTBEFORE(A11,","), "-", ""), " ", "") -> Barger | H11: =_xlfn.LET( _xlpm.authors,_xlfn.TEXTBEFORE(A11," ("&I11&")"), _xlpm.hasAmp,ISNUMBER(SEARCH("&",_xlpm.authors)), _xlpm.commasBeforeAmp,IF(_xlpm.hasAmp,LEN(_xlfn.TEXTBEFORE(_xlpm.authors,"&"))-LEN(SUBSTITUTE(_xlfn.TEXTBEFORE(_xlpm.authors,"&"),",","")),0), IF(NOT(_xlpm.hasAmp),"",IF(_xlpm.commasBeforeAmp>2,"etal",TRIM(_xlfn.TEXTBEFORE(_xlfn.TEXTAFTER(_xlpm.authors,"& "),",")))) ) -> etal | I11: =_xlfn.TEXTBEFORE(_xlfn.TEXTAFTER(A11, "("), ")") -> 2007 | J11: =_xlfn.LET( _xlpm.doi,IF(C11<>"",C11,_xlfn.TEXTAFTER(A11,"https://doi.org/")), SUBSTITUTE( SUBSTITUTE( SUBSTITUTE( SUBSTITUTE( _xlpm.doi, "/","%2F"), ":","%3A"), "<","%3C"), ">","%3E") ) -> 10.1002%2Fajpa.20684 | K11: =TRIM(_xlfn.TEXTJOIN("_",FALSE(),F11,(SUBSTITUTE(SUBSTITUTE(D11," ",""), "_", "")))) -> Barger_etal_2007_TABLE1 | L11: =J11 & "_" & SUBSTITUTE(SUBSTITUTE(SUBSTITUTE(D11,CHAR(160),"")," ",""),"_","") -> 10.1002%2Fajpa.20684_TABLE1 | M11: {=IFERROR(INDEX(FileList!$A$1:$A$100,MATCH(TRUE(),EXACT(L11,_xlfn.TEXTBEFORE(FileList!$A$1:$A$100,".tsv")),0)),"notfound")} -> 10.1002%2Fajpa.20684_TABLE1.tsv | N11: TABLE 1. Volumetric estimates of the amygdaloid complex and the basolateral division | P11: FINISHED | Z11: Zilles | AG11: Zilles | AI11: amygdala subdivision volumes | AJ11: Apes & humans | AL11: primary | AM11: volume
A12: Barks, S. K., Calhoun, M. E., Hopkins, W. D., Cranfield, M. R., Mudakikwa, A., Stoinski, T. S., Patterson, F. G., Erwin, J. M., Hecht, E. E., Hof, P. R., & Sherwood, C. C. (2014). Brain organization of gorillas reflects species differences in ecology. Am J Phys Anthropol. https://doi.org/10.1002/ajpa.22646 | D12: Fig 4 A | E12: =RIGHT(A12,1) -> 6 | F12: =G12 & IF(H12<>"", "_" & H12, "_") & IF(I12<>"", "_" & I12, "_") & IF(B12<>"", "_" & B12, "") -> Barks_etal_2014 | G12: =SUBSTITUTE(SUBSTITUTE(_xlfn.TEXTBEFORE(A12,","), "-", ""), " ", "") -> Barks | H12: =_xlfn.LET( _xlpm.authors,_xlfn.TEXTBEFORE(A12," ("&I12&")"), _xlpm.hasAmp,ISNUMBER(SEARCH("&",_xlpm.authors)), _xlpm.commasBeforeAmp,IF(_xlpm.hasAmp,LEN(_xlfn.TEXTBEFORE(_xlpm.authors,"&"))-LEN(SUBSTITUTE(_xlfn.TEXTBEFORE(_xlpm.authors,"&"),",","")),0), IF(NOT(_xlpm.hasAmp),"",IF(_xlpm.commasBeforeAmp>2,"etal",TRIM(_xlfn.TEXTBEFORE(_xlfn.TEXTAFTER(_xlpm.authors,"& "),",")))) ) -> etal | I12: =_xlfn.TEXTBEFORE(_xlfn.TEXTAFTER(A12, "("), ")") -> 2014 | J12: =_xlfn.LET( _xlpm.doi,IF(C12<>"",C12,_xlfn.TEXTAFTER(A12,"https://doi.org/")), SUBSTITUTE( SUBSTITUTE( SUBSTITUTE( SUBSTITUTE( _xlpm.doi, "/","%2F"), ":","%3A"), "<","%3C"), ">","%3E") ) -> 10.1002%2Fajpa.22646 | K12: =TRIM(_xlfn.TEXTJOIN("_",FALSE(),F12,(SUBSTITUTE(SUBSTITUTE(D12," ",""), "_", "")))) -> Barks_etal_2014_Fig4A | L12: =J12 & "_" & SUBSTITUTE(SUBSTITUTE(SUBSTITUTE(D12,CHAR(160),"")," ",""),"_","") -> 10.1002%2Fajpa.22646_Fig4A | M12: {=IFERROR(INDEX(FileList!$A$1:$A$100,MATCH(TRUE(),EXACT(L12,_xlfn.TEXTBEFORE(FileList!$A$1:$A$100,".tsv")),0)),"notfound")} -> 10.1002%2Fajpa.22646_Fig4A.tsv | O12: Fig4A_allsubjects_volumes | P12: FINISHED | Y12: Barks
A13: Barks, S. K., Calhoun, M. E., Hopkins, W. D., Cranfield, M. R., Mudakikwa, A., Stoinski, T. S., Patterson, F. G., Erwin, J. M., Hecht, E. E., Hof, P. R., & Sherwood, C. C. (2014). Brain organization of gorillas reflects species differences in ecology. Am J Phys Anthropol. https://doi.org/10.1002/ajpa.22646 | D13: Fig 5 A | E13: =RIGHT(A13,1) -> 6 | F13: =G13 & IF(H13<>"", "_" & H13, "_") & IF(I13<>"", "_" & I13, "_") & IF(B13<>"", "_" & B13, "") -> Barks_etal_2014 | G13: =SUBSTITUTE(SUBSTITUTE(_xlfn.TEXTBEFORE(A13,","), "-", ""), " ", "") -> Barks | H13: =_xlfn.LET( _xlpm.authors,_xlfn.TEXTBEFORE(A13," ("&I13&")"), _xlpm.hasAmp,ISNUMBER(SEARCH("&",_xlpm.authors)), _xlpm.commasBeforeAmp,IF(_xlpm.hasAmp,LEN(_xlfn.TEXTBEFORE(_xlpm.authors,"&"))-LEN(SUBSTITUTE(_xlfn.TEXTBEFORE(_xlpm.authors,"&"),",","")),0), IF(NOT(_xlpm.hasAmp),"",IF(_xlpm.commasBeforeAmp>2,"etal",TRIM(_xlfn.TEXTBEFORE(_xlfn.TEXTAFTER(_xlpm.authors,"& "),",")))) ) -> etal | I13: =_xlfn.TEXTBEFORE(_xlfn.TEXTAFTER(A13, "("), ")") -> 2014 | J13: =_xlfn.LET( _xlpm.doi,IF(C13<>"",C13,_xlfn.TEXTAFTER(A13,"https://doi.org/")), SUBSTITUTE( SUBSTITUTE( SUBSTITUTE( SUBSTITUTE( _xlpm.doi, "/","%2F"), ":","%3A"), "<","%3C"), ">","%3E") ) -> 10.1002%2Fajpa.22646 | K13: =TRIM(_xlfn.TEXTJOIN("_",FALSE(),F13,(SUBSTITUTE(SUBSTITUTE(D13," ",""), "_", "")))) -> Barks_etal_2014_Fig5A | L13: =J13 & "_" & SUBSTITUTE(SUBSTITUTE(SUBSTITUTE(D13,CHAR(160),"")," ",""),"_","") -> 10.1002%2Fajpa.22646_Fig5A | M13: {=IFERROR(INDEX(FileList!$A$1:$A$100,MATCH(TRUE(),EXACT(L13,_xlfn.TEXTBEFORE(FileList!$A$1:$A$100,".tsv")),0)),"notfound")} -> 10.1002%2Fajpa.22646_Fig5A.tsv | O13: Fig5A_adultsonly_volumes | P13: FINISHED
A14: Barks, S. K., Calhoun, M. E., Hopkins, W. D., Cranfield, M. R., Mudakikwa, A., Stoinski, T. S., Patterson, F. G., Erwin, J. M., Hecht, E. E., Hof, P. R., & Sherwood, C. C. (2014). Brain organization of gorillas reflects species differences in ecology. Am J Phys Anthropol. https://doi.org/10.1002/ajpa.22646 | D14: TABLE 1 | E14: =RIGHT(A14,1) -> 6 | F14: =G14 & IF(H14<>"", "_" & H14, "_") & IF(I14<>"", "_" & I14, "_") & IF(B14<>"", "_" & B14, "") -> Barks_etal_2014 | G14: =SUBSTITUTE(SUBSTITUTE(_xlfn.TEXTBEFORE(A14,","), "-", ""), " ", "") -> Barks | H14: =_xlfn.LET( _xlpm.authors,_xlfn.TEXTBEFORE(A14," ("&I14&")"), _xlpm.hasAmp,ISNUMBER(SEARCH("&",_xlpm.authors)), _xlpm.commasBeforeAmp,IF(_xlpm.hasAmp,LEN(_xlfn.TEXTBEFORE(_xlpm.authors,"&"))-LEN(SUBSTITUTE(_xlfn.TEXTBEFORE(_xlpm.authors,"&"),",","")),0), IF(NOT(_xlpm.hasAmp),"",IF(_xlpm.commasBeforeAmp>2,"etal",TRIM(_xlfn.TEXTBEFORE(_xlfn.TEXTAFTER(_xlpm.authors,"& "),",")))) ) -> etal | I14: =_xlfn.TEXTBEFORE(_xlfn.TEXTAFTER(A14, "("), ")") -> 2014 | J14: =_xlfn.LET( _xlpm.doi,IF(C14<>"",C14,_xlfn.TEXTAFTER(A14,"https://doi.org/")), SUBSTITUTE( SUBSTITUTE( SUBSTITUTE( SUBSTITUTE( _xlpm.doi, "/","%2F"), ":","%3A"), "<","%3C"), ">","%3E") ) -> 10.1002%2Fajpa.22646 | K14: =TRIM(_xlfn.TEXTJOIN("_",FALSE(),F14,(SUBSTITUTE(SUBSTITUTE(D14," ",""), "_", "")))) -> Barks_etal_2014_TABLE1 | L14: =J14 & "_" & SUBSTITUTE(SUBSTITUTE(SUBSTITUTE(D14,CHAR(160),"")," ",""),"_","") -> 10.1002%2Fajpa.22646_TABLE1 | M14: {=IFERROR(INDEX(FileList!$A$1:$A$100,MATCH(TRUE(),EXACT(L14,_xlfn.TEXTBEFORE(FileList!$A$1:$A$100,".tsv")),0)),"notfound")} -> 10.1002%2Fajpa.22646_TABLE1.tsv | N14: TABLE 1. Individual data | P14: FINISHED | Y14: Barks
A15: Barks, S. K., Calhoun, M. E., Hopkins, W. D., Cranfield, M. R., Mudakikwa, A., Stoinski, T. S., Patterson, F. G., Erwin, J. M., Hecht, E. E., Hof, P. R., & Sherwood, C. C. (2014). Brain organization of gorillas reflects species differences in ecology. Am J Phys Anthropol. https://doi.org/10.1002/ajpa.22646 | D15: TABLE 2 | E15: =RIGHT(A15,1) -> 6 | F15: =G15 & IF(H15<>"", "_" & H15, "_") & IF(I15<>"", "_" & I15, "_") & IF(B15<>"", "_" & B15, "") -> Barks_etal_2014 | G15: =SUBSTITUTE(SUBSTITUTE(_xlfn.TEXTBEFORE(A15,","), "-", ""), " ", "") -> Barks | H15: =_xlfn.LET( _xlpm.authors,_xlfn.TEXTBEFORE(A15," ("&I15&")"), _xlpm.hasAmp,ISNUMBER(SEARCH("&",_xlpm.authors)), _xlpm.commasBeforeAmp,IF(_xlpm.hasAmp,LEN(_xlfn.TEXTBEFORE(_xlpm.authors,"&"))-LEN(SUBSTITUTE(_xlfn.TEXTBEFORE(_xlpm.authors,"&"),",","")),0), IF(NOT(_xlpm.hasAmp),"",IF(_xlpm.commasBeforeAmp>2,"etal",TRIM(_xlfn.TEXTBEFORE(_xlfn.TEXTAFTER(_xlpm.authors,"& "),",")))) ) -> etal | I15: =_xlfn.TEXTBEFORE(_xlfn.TEXTAFTER(A15, "("), ")") -> 2014 | J15: =_xlfn.LET( _xlpm.doi,IF(C15<>"",C15,_xlfn.TEXTAFTER(A15,"https://doi.org/")), SUBSTITUTE( SUBSTITUTE( SUBSTITUTE( SUBSTITUTE( _xlpm.doi, "/","%2F"), ":","%3A"), "<","%3C"), ">","%3E") ) -> 10.1002%2Fajpa.22646 | K15: =TRIM(_xlfn.TEXTJOIN("_",FALSE(),F15,(SUBSTITUTE(SUBSTITUTE(D15," ",""), "_", "")))) -> Barks_etal_2014_TABLE2 | L15: =J15 & "_" & SUBSTITUTE(SUBSTITUTE(SUBSTITUTE(D15,CHAR(160),"")," ",""),"_","") -> 10.1002%2Fajpa.22646_TABLE2 | M15: {=IFERROR(INDEX(FileList!$A$1:$A$100,MATCH(TRUE(),EXACT(L15,_xlfn.TEXTBEFORE(FileList!$A$1:$A$100,".tsv")),0)),"notfound")} -> 10.1002%2Fajpa.22646_TABLE2.tsv | N15: TABLE 2. Stereological sampling of brains | P15: FINISHED
A16: Barks, S. K., Calhoun, M. E., Hopkins, W. D., Cranfield, M. R., Mudakikwa, A., Stoinski, T. S., Patterson, F. G., Erwin, J. M., Hecht, E. E., Hof, P. R., & Sherwood, C. C. (2014). Brain organization of gorillas reflects species differences in ecology. Am J Phys Anthropol. https://doi.org/10.1002/ajpa.22646 | D16: unpublishedviaDeCasien | E16: =RIGHT(A16,1) -> 6 | F16: =G16 & IF(H16<>"", "_" & H16, "_") & IF(I16<>"", "_" & I16, "_") & IF(B16<>"", "_" & B16, "") -> Barks_etal_2014 | G16: =SUBSTITUTE(SUBSTITUTE(_xlfn.TEXTBEFORE(A16,","), "-", ""), " ", "") -> Barks | H16: =_xlfn.LET( _xlpm.authors,_xlfn.TEXTBEFORE(A16," ("&I16&")"), _xlpm.hasAmp,ISNUMBER(SEARCH("&",_xlpm.authors)), _xlpm.commasBeforeAmp,IF(_xlpm.hasAmp,LEN(_xlfn.TEXTBEFORE(_xlpm.authors,"&"))-LEN(SUBSTITUTE(_xlfn.TEXTBEFORE(_xlpm.authors,"&"),",","")),0), IF(NOT(_xlpm.hasAmp),"",IF(_xlpm.commasBeforeAmp>2,"etal",TRIM(_xlfn.TEXTBEFORE(_xlfn.TEXTAFTER(_xlpm.authors,"& "),",")))) ) -> etal | I16: =_xlfn.TEXTBEFORE(_xlfn.TEXTAFTER(A16, "("), ")") -> 2014 | J16: =_xlfn.LET( _xlpm.doi,IF(C16<>"",C16,_xlfn.TEXTAFTER(A16,"https://doi.org/")), SUBSTITUTE( SUBSTITUTE( SUBSTITUTE( SUBSTITUTE( _xlpm.doi, "/","%2F"), ":","%3A"), "<","%3C"), ">","%3E") ) -> 10.1002%2Fajpa.22646 | K16: =TRIM(_xlfn.TEXTJOIN("_",FALSE(),F16,(SUBSTITUTE(SUBSTITUTE(D16," ",""), "_", "")))) -> Barks_etal_2014_unpublishedviaDeCasien | L16: =J16 & "_" & SUBSTITUTE(SUBSTITUTE(SUBSTITUTE(D16,CHAR(160),"")," ",""),"_","") -> 10.1002%2Fajpa.22646_unpublishedviaDeCasien | M16: {=IFERROR(INDEX(FileList!$A$1:$A$100,MATCH(TRUE(),EXACT(L16,_xlfn.TEXTBEFORE(FileList!$A$1:$A$100,".tsv")),0)),"notfound")} -> 10.1002%2Fajpa.22646_unpublishedviaDeCasien.tsv | O16: "Sherwood et al.64 and Barks et al.65 provided neocortex, hippocampus, striatum, thalamus, cerebellum, amygdala and insula measures for multiple gorilla species (Gorilla gorilla gorilla, G. g. graueri and G. beringei) from post-mortem MRI scans" (DeCasien and Higham 2019)
A17: Baron, G., Frahm, H. D., & Stephan, H. (1988). Comparison of brain structure volumes in Insectivora and Primates. VIII. Vestibular complex. J Hirnforsch, 29(5), 509-523. http://www.ncbi.nlm.nih.gov/pubmed/3216099 | C17: PMID:3216099 | D17: Table 1 | E17: =RIGHT(A17,1) -> 9 | F17: =G17 & IF(H17<>"", "_" & H17, "_") & IF(I17<>"", "_" & I17, "_") & IF(B17<>"", "_" & B17, "") -> Baron_etal_1988 | G17: =SUBSTITUTE(SUBSTITUTE(_xlfn.TEXTBEFORE(A17,","), "-", ""), " ", "") -> Baron | H17: =_xlfn.LET( _xlpm.authors,_xlfn.TEXTBEFORE(A17," ("&I17&")"), _xlpm.hasAmp,ISNUMBER(SEARCH("&",_xlpm.authors)), _xlpm.commasBeforeAmp,IF(_xlpm.hasAmp,LEN(_xlfn.TEXTBEFORE(_xlpm.authors,"&"))-LEN(SUBSTITUTE(_xlfn.TEXTBEFORE(_xlpm.authors,"&"),",","")),0), IF(NOT(_xlpm.hasAmp),"",IF(_xlpm.commasBeforeAmp>2,"etal",TRIM(_xlfn.TEXTBEFORE(_xlfn.TEXTAFTER(_xlpm.authors,"& "),",")))) ) -> etal | I17: =_xlfn.TEXTBEFORE(_xlfn.TEXTAFTER(A17, "("), ")") -> 1988 | J17: =_xlfn.LET( _xlpm.doi,IF(C17<>"",C17,_xlfn.TEXTAFTER(A17,"https://doi.org/")), SUBSTITUTE( SUBSTITUTE( SUBSTITUTE( SUBSTITUTE( _xlpm.doi, "/","%2F"), ":","%3A"), "<","%3C"), ">","%3E") ) -> PMID%3A3216099 | K17: =TRIM(_xlfn.TEXTJOIN("_",FALSE(),F17,(SUBSTITUTE(SUBSTITUTE(D17," ",""), "_", "")))) -> Baron_etal_1988_Table1 | L17: =J17 & "_" & SUBSTITUTE(SUBSTITUTE(SUBSTITUTE(D17,CHAR(160),"")," ",""),"_","") -> PMID%3A3216099_Table1 | M17: {=IFERROR(INDEX(FileList!$A$1:$A$100,MATCH(TRUE(),EXACT(L17,_xlfn.TEXTBEFORE(FileList!$A$1:$A$100,".tsv")),0)),"notfound")} -> notfound | N17: Table 1. Volumes and indices of the vestibular complex (VC) and its main components (VM, V1, VL, VS) in Insectivora and Scadentia | P17: FINISHED | Y17: Stephan | Z17: Stephan | AF17: histological sections | AG17: Stephan | AI17: vestibular nuclear complex volume | AJ17: Insectivora, Scandentia & Primates | AL17: primary | AM17: volume
A18: Baron, G., Frahm, H. D., Bhatnagar, K. P., & Stephan, H. (1983). Comparison of brain structure volumes in Insectivora and Primates. III. Main olfactory bulb (MOB). J Hirnforsch, 24(5), 551-568. https://www.ncbi.nlm.nih.gov/pubmed/6663055 | C18: PMID:6663055 | D18: Table 1 | E18: =RIGHT(A18,1) -> 5 | F18: =G18 & IF(H18<>"", "_" & H18, "_") & IF(I18<>"", "_" & I18, "_") & IF(B18<>"", "_" & B18, "") -> Baron_etal_1983 | G18: =SUBSTITUTE(SUBSTITUTE(_xlfn.TEXTBEFORE(A18,","), "-", ""), " ", "") -> Baron | H18: =_xlfn.LET( _xlpm.authors,_xlfn.TEXTBEFORE(A18," ("&I18&")"), _xlpm.hasAmp,ISNUMBER(SEARCH("&",_xlpm.authors)), _xlpm.commasBeforeAmp,IF(_xlpm.hasAmp,LEN(_xlfn.TEXTBEFORE(_xlpm.authors,"&"))-LEN(SUBSTITUTE(_xlfn.TEXTBEFORE(_xlpm.authors,"&"),",","")),0), IF(NOT(_xlpm.hasAmp),"",IF(_xlpm.commasBeforeAmp>2,"etal",TRIM(_xlfn.TEXTBEFORE(_xlfn.TEXTAFTER(_xlpm.authors,"& "),",")))) ) -> etal | I18: =_xlfn.TEXTBEFORE(_xlfn.TEXTAFTER(A18, "("), ")") -> 1983 | J18: =_xlfn.LET( _xlpm.doi,IF(C18<>"",C18,_xlfn.TEXTAFTER(A18,"https://doi.org/")), SUBSTITUTE( SUBSTITUTE( SUBSTITUTE( SUBSTITUTE( _xlpm.doi, "/","%2F"), ":","%3A"), "<","%3C"), ">","%3E") ) -> PMID%3A6663055 | K18: =TRIM(_xlfn.TEXTJOIN("_",FALSE(),F18,(SUBSTITUTE(SUBSTITUTE(D18," ",""), "_", "")))) -> Baron_etal_1983_Table1 | L18: =J18 & "_" & SUBSTITUTE(SUBSTITUTE(SUBSTITUTE(D18,CHAR(160),"")," ",""),"_","") -> PMID%3A6663055_Table1 | M18: {=IFERROR(INDEX(FileList!$A$1:$A$100,MATCH(TRUE(),EXACT(L18,_xlfn.TEXTBEFORE(FileList!$A$1:$A$100,".tsv")),0)),"notfound")} -> notfound | P18: FINISHED | V18: table | W18: NO - not digitized | Y18: Stephan | Z18: Stephan | AF18: histological sections | AG18: Stephan | AI18: main olfactory bulb (MOB) volume | AJ18: Insectivora, Scandentia & Primates | AK18: primary | AL18: primary | AM18: volume
A19: Baron, G., Stephan, H., & Frahm, H. D. (1987). Comparison of brain structure volumes in Insectivora and Primates. VI. Paleocortical components. J Hirnforsch, 28(4), 463-477. http://www.ncbi.nlm.nih.gov/pubmed/3116076 | C19: PMID:3116076 | D19: Table 1 | E19: =RIGHT(A19,1) -> 6 | F19: =G19 & IF(H19<>"", "_" & H19, "_") & IF(I19<>"", "_" & I19, "_") & IF(B19<>"", "_" & B19, "") -> Baron_etal_1987 | G19: =SUBSTITUTE(SUBSTITUTE(_xlfn.TEXTBEFORE(A19,","), "-", ""), " ", "") -> Baron | H19: =_xlfn.LET( _xlpm.authors,_xlfn.TEXTBEFORE(A19," ("&I19&")"), _xlpm.hasAmp,ISNUMBER(SEARCH("&",_xlpm.authors)), _xlpm.commasBeforeAmp,IF(_xlpm.hasAmp,LEN(_xlfn.TEXTBEFORE(_xlpm.authors,"&"))-LEN(SUBSTITUTE(_xlfn.TEXTBEFORE(_xlpm.authors,"&"),",","")),0), IF(NOT(_xlpm.hasAmp),"",IF(_xlpm.commasBeforeAmp>2,"etal",TRIM(_xlfn.TEXTBEFORE(_xlfn.TEXTAFTER(_xlpm.authors,"& "),",")))) ) -> etal | I19: =_xlfn.TEXTBEFORE(_xlfn.TEXTAFTER(A19, "("), ")") -> 1987 | J19: =_xlfn.LET( _xlpm.doi,IF(C19<>"",C19,_xlfn.TEXTAFTER(A19,"https://doi.org/")), SUBSTITUTE( SUBSTITUTE( SUBSTITUTE( SUBSTITUTE( _xlpm.doi, "/","%2F"), ":","%3A"), "<","%3C"), ">","%3E") ) -> PMID%3A3116076 | K19: =TRIM(_xlfn.TEXTJOIN("_",FALSE(),F19,(SUBSTITUTE(SUBSTITUTE(D19," ",""), "_", "")))) -> Baron_etal_1987_Table1 | L19: =J19 & "_" & SUBSTITUTE(SUBSTITUTE(SUBSTITUTE(D19,CHAR(160),"")," ",""),"_","") -> PMID%3A3116076_Table1 | M19: {=IFERROR(INDEX(FileList!$A$1:$A$100,MATCH(TRUE(),EXACT(L19,_xlfn.TEXTBEFORE(FileList!$A$1:$A$100,".tsv")),0)),"notfound")} -> notfound | P19: FINISHED | V19: table | W19: NO - not digitized | Y19: Stephan | Z19: Stephan | AF19: histological sections | AG19: Stephan | AI19: brain-structure volume (Comparison series, Part) | AJ19: Insectivora, Scandentia & Primates | AK19: primary | AL19: primary | AM19: volume
A20: Baron, G., Stephan, H., & Frahm, H. D. (1990). Comparison of brain structure volumes in Insectivora and primates. IX. Trigeminal complex. J Hirnforsch, 31(2), 193-200. https://www.ncbi.nlm.nih.gov/pubmed/2358663 | C20: PMID:2358663 | D20: Table 1 | E20: =RIGHT(A20,1) -> 3 | F20: =G20 & IF(H20<>"", "_" & H20, "_") & IF(I20<>"", "_" & I20, "_") & IF(B20<>"", "_" & B20, "") -> Baron_etal_1990 | G20: =SUBSTITUTE(SUBSTITUTE(_xlfn.TEXTBEFORE(A20,","), "-", ""), " ", "") -> Baron | H20: =_xlfn.LET( _xlpm.authors,_xlfn.TEXTBEFORE(A20," ("&I20&")"), _xlpm.hasAmp,ISNUMBER(SEARCH("&",_xlpm.authors)), _xlpm.commasBeforeAmp,IF(_xlpm.hasAmp,LEN(_xlfn.TEXTBEFORE(_xlpm.authors,"&"))-LEN(SUBSTITUTE(_xlfn.TEXTBEFORE(_xlpm.authors,"&"),",","")),0), IF(NOT(_xlpm.hasAmp),"",IF(_xlpm.commasBeforeAmp>2,"etal",TRIM(_xlfn.TEXTBEFORE(_xlfn.TEXTAFTER(_xlpm.authors,"& "),",")))) ) -> etal | I20: =_xlfn.TEXTBEFORE(_xlfn.TEXTAFTER(A20, "("), ")") -> 1990 | J20: =_xlfn.LET( _xlpm.doi,IF(C20<>"",C20,_xlfn.TEXTAFTER(A20,"https://doi.org/")), SUBSTITUTE( SUBSTITUTE( SUBSTITUTE( SUBSTITUTE( _xlpm.doi, "/","%2F"), ":","%3A"), "<","%3C"), ">","%3E") ) -> PMID%3A2358663 | K20: =TRIM(_xlfn.TEXTJOIN("_",FALSE(),F20,(SUBSTITUTE(SUBSTITUTE(D20," ",""), "_", "")))) -> Baron_etal_1990_Table1 | L20: =J20 & "_" & SUBSTITUTE(SUBSTITUTE(SUBSTITUTE(D20,CHAR(160),"")," ",""),"_","") -> PMID%3A2358663_Table1 | M20: {=IFERROR(INDEX(FileList!$A$1:$A$100,MATCH(TRUE(),EXACT(L20,_xlfn.TEXTBEFORE(FileList!$A$1:$A$100,".tsv")),0)),"notfound")} -> notfound | N20: Table 1 .IX. Trigeminal complex | P20: FINISHED | V20: table | W20: NO - not digitized | Y20: Stephan | Z20: Stephan | AF20: histological sections | AG20: volumetry | AI20: trigeminal complex volume | AJ20: Insectivora, Scandentia & Primates | AK20: primary | AL20: primary | AM20: volume
A21: Bauernfeind, A. L., de Sousa, A. A., Avasthi, T., Dobson, S. D., Raghanti, M. A., Lewandowski, A. H., Zilles, K., Semendeferi, K., Allman, J. M., Craig, A. D., Hof, P. R., & Sherwood, C. C. (2013). A volumetric comparison of the insular cortex and its subregions in primates. J Hum Evol, 64(4), 263-279. https://doi.org/10.1016/j.jhevol.2012.12.003 | D21: Table 1 | E21: =RIGHT(A21,1) -> 3 | F21: =G21 & IF(H21<>"", "_" & H21, "_") & IF(I21<>"", "_" & I21, "_") & IF(B21<>"", "_" & B21, "") -> Bauernfeind_etal_2013 | G21: =SUBSTITUTE(SUBSTITUTE(_xlfn.TEXTBEFORE(A21,","), "-", ""), " ", "") -> Bauernfeind | H21: =_xlfn.LET( _xlpm.authors,_xlfn.TEXTBEFORE(A21," ("&I21&")"), _xlpm.hasAmp,ISNUMBER(SEARCH("&",_xlpm.authors)), _xlpm.commasBeforeAmp,IF(_xlpm.hasAmp,LEN(_xlfn.TEXTBEFORE(_xlpm.authors,"&"))-LEN(SUBSTITUTE(_xlfn.TEXTBEFORE(_xlpm.authors,"&"),",","")),0), IF(NOT(_xlpm.hasAmp),"",IF(_xlpm.commasBeforeAmp>2,"etal",TRIM(_xlfn.TEXTBEFORE(_xlfn.TEXTAFTER(_xlpm.authors,"& "),",")))) ) -> etal | I21: =_xlfn.TEXTBEFORE(_xlfn.TEXTAFTER(A21, "("), ")") -> 2013 | J21: =_xlfn.LET( _xlpm.doi,IF(C21<>"",C21,_xlfn.TEXTAFTER(A21,"https://doi.org/")), SUBSTITUTE( SUBSTITUTE( SUBSTITUTE( SUBSTITUTE( _xlpm.doi, "/","%2F"), ":","%3A"), "<","%3C"), ">","%3E") ) -> 10.1016%2Fj.jhevol.2012.12.003 | K21: =TRIM(_xlfn.TEXTJOIN("_",FALSE(),F21,(SUBSTITUTE(SUBSTITUTE(D21," ",""), "_", "")))) -> Bauernfeind_etal_2013_Table1 | L21: =J21 & "_" & SUBSTITUTE(SUBSTITUTE(SUBSTITUTE(D21,CHAR(160),"")," ",""),"_","") -> 10.1016%2Fj.jhevol.2012.12.003_Table1 | M21: {=IFERROR(INDEX(FileList!$A$1:$A$100,MATCH(TRUE(),EXACT(L21,_xlfn.TEXTBEFORE(FileList!$A$1:$A$100,".tsv")),0)),"notfound")} -> 10.1016%2Fj.jhevol.2012.12.003_Table1.tsv | N21: Volumetric comparison of the insular cortex (Table 1) | P21: FINISHED | V21: table | Y21: Stephan, Sherwood | AF21: histological sections | AG21: volumetry | AI21: insular cortex volumes | AJ21: Primates | AK21: primary | AL21: primary | AM21: volume
A22: Bauernfeind, A. L., de Sousa, A. A., Avasthi, T., Dobson, S. D., Raghanti, M. A., Lewandowski, A. H., Zilles, K., Semendeferi, K., Allman, J. M., Craig, A. D., Hof, P. R., & Sherwood, C. C. (2013). A volumetric comparison of the insular cortex and its subregions in primates. J Hum Evol, 64(4), 263-279. https://doi.org/10.1016/j.jhevol.2012.12.003 | D22: Table 2 | E22: =RIGHT(A22,1) -> 3 | F22: =G22 & IF(H22<>"", "_" & H22, "_") & IF(I22<>"", "_" & I22, "_") & IF(B22<>"", "_" & B22, "") -> Bauernfeind_etal_2013 | G22: =SUBSTITUTE(SUBSTITUTE(_xlfn.TEXTBEFORE(A22,","), "-", ""), " ", "") -> Bauernfeind | H22: =_xlfn.LET( _xlpm.authors,_xlfn.TEXTBEFORE(A22," ("&I22&")"), _xlpm.hasAmp,ISNUMBER(SEARCH("&",_xlpm.authors)), _xlpm.commasBeforeAmp,IF(_xlpm.hasAmp,LEN(_xlfn.TEXTBEFORE(_xlpm.authors,"&"))-LEN(SUBSTITUTE(_xlfn.TEXTBEFORE(_xlpm.authors,"&"),",","")),0), IF(NOT(_xlpm.hasAmp),"",IF(_xlpm.commasBeforeAmp>2,"etal",TRIM(_xlfn.TEXTBEFORE(_xlfn.TEXTAFTER(_xlpm.authors,"& "),",")))) ) -> etal | I22: =_xlfn.TEXTBEFORE(_xlfn.TEXTAFTER(A22, "("), ")") -> 2013 | J22: =_xlfn.LET( _xlpm.doi,IF(C22<>"",C22,_xlfn.TEXTAFTER(A22,"https://doi.org/")), SUBSTITUTE( SUBSTITUTE( SUBSTITUTE( SUBSTITUTE( _xlpm.doi, "/","%2F"), ":","%3A"), "<","%3C"), ">","%3E") ) -> 10.1016%2Fj.jhevol.2012.12.003 | K22: =TRIM(_xlfn.TEXTJOIN("_",FALSE(),F22,(SUBSTITUTE(SUBSTITUTE(D22," ",""), "_", "")))) -> Bauernfeind_etal_2013_Table2 | L22: =J22 & "_" & SUBSTITUTE(SUBSTITUTE(SUBSTITUTE(D22,CHAR(160),"")," ",""),"_","") -> 10.1016%2Fj.jhevol.2012.12.003_Table2 | M22: {=IFERROR(INDEX(FileList!$A$1:$A$100,MATCH(TRUE(),EXACT(L22,_xlfn.TEXTBEFORE(FileList!$A$1:$A$100,".tsv")),0)),"notfound")} -> 10.1016%2Fj.jhevol.2012.12.003_Table2.tsv | P22: FINISHED | V22: table | Y22: Stephan, Sherwood | AF22: histological sections | AG22: volumetry | AI22: insular cortex volumes | AJ22: Primates | AK22: primary | AL22: primary | AM22: volume
A23: Bauernfeind, A. L., de Sousa, A. A., Avasthi, T., Dobson, S. D., Raghanti, M. A., Lewandowski, A. H., Zilles, K., Semendeferi, K., Allman, J. M., Craig, A. D., Hof, P. R., & Sherwood, C. C. (2013). A volumetric comparison of the insular cortex and its subregions in primates. J Hum Evol, 64(4), 263-279. https://doi.org/10.1016/j.jhevol.2012.12.003 | D23: Table 3 | E23: =RIGHT(A23,1) -> 3 | F23: =G23 & IF(H23<>"", "_" & H23, "_") & IF(I23<>"", "_" & I23, "_") & IF(B23<>"", "_" & B23, "") -> Bauernfeind_etal_2013 | G23: =SUBSTITUTE(SUBSTITUTE(_xlfn.TEXTBEFORE(A23,","), "-", ""), " ", "") -> Bauernfeind | H23: =_xlfn.LET( _xlpm.authors,_xlfn.TEXTBEFORE(A23," ("&I23&")"), _xlpm.hasAmp,ISNUMBER(SEARCH("&",_xlpm.authors)), _xlpm.commasBeforeAmp,IF(_xlpm.hasAmp,LEN(_xlfn.TEXTBEFORE(_xlpm.authors,"&"))-LEN(SUBSTITUTE(_xlfn.TEXTBEFORE(_xlpm.authors,"&"),",","")),0), IF(NOT(_xlpm.hasAmp),"",IF(_xlpm.commasBeforeAmp>2,"etal",TRIM(_xlfn.TEXTBEFORE(_xlfn.TEXTAFTER(_xlpm.authors,"& "),",")))) ) -> etal | I23: =_xlfn.TEXTBEFORE(_xlfn.TEXTAFTER(A23, "("), ")") -> 2013 | J23: =_xlfn.LET( _xlpm.doi,IF(C23<>"",C23,_xlfn.TEXTAFTER(A23,"https://doi.org/")), SUBSTITUTE( SUBSTITUTE( SUBSTITUTE( SUBSTITUTE( _xlpm.doi, "/","%2F"), ":","%3A"), "<","%3C"), ">","%3E") ) -> 10.1016%2Fj.jhevol.2012.12.003 | K23: =TRIM(_xlfn.TEXTJOIN("_",FALSE(),F23,(SUBSTITUTE(SUBSTITUTE(D23," ",""), "_", "")))) -> Bauernfeind_etal_2013_Table3 | L23: =J23 & "_" & SUBSTITUTE(SUBSTITUTE(SUBSTITUTE(D23,CHAR(160),"")," ",""),"_","") -> 10.1016%2Fj.jhevol.2012.12.003_Table3 | M23: {=IFERROR(INDEX(FileList!$A$1:$A$100,MATCH(TRUE(),EXACT(L23,_xlfn.TEXTBEFORE(FileList!$A$1:$A$100,".tsv")),0)),"notfound")} -> notfound | V23: table | Y23: Stephan, Sherwood | AF23: histological sections | AG23: volumetry | AI23: insular cortex volumes | AJ23: Primates | AK23: primary | AL23: primary | AM23: volume
A24: Boyer, D. M., & Harrington, A. R. (2018). Scaling of bony canals for encephalic vessels in euarchontans: Implications for the role of the vertebral artery and brain metabolism. J Hum Evol, 114, 85-101. https://doi.org/10.1016/j.jhevol.2017.09.003 | D24: Table 1 | E24: =RIGHT(A24,1) -> 3 | F24: =G24 & IF(H24<>"", "_" & H24, "_") & IF(I24<>"", "_" & I24, "_") & IF(B24<>"", "_" & B24, "") -> Boyer_Harrington_2018 | G24: =SUBSTITUTE(SUBSTITUTE(_xlfn.TEXTBEFORE(A24,","), "-", ""), " ", "") -> Boyer | H24: =_xlfn.LET( _xlpm.authors,_xlfn.TEXTBEFORE(A24," ("&I24&")"), _xlpm.hasAmp,ISNUMBER(SEARCH("&",_xlpm.authors)), _xlpm.commasBeforeAmp,IF(_xlpm.hasAmp,LEN(_xlfn.TEXTBEFORE(_xlpm.authors,"&"))-LEN(SUBSTITUTE(_xlfn.TEXTBEFORE(_xlpm.authors,"&"),",","")),0), IF(NOT(_xlpm.hasAmp),"",IF(_xlpm.commasBeforeAmp>2,"etal",TRIM(_xlfn.TEXTBEFORE(_xlfn.TEXTAFTER(_xlpm.authors,"& "),",")))) ) -> Harrington | I24: =_xlfn.TEXTBEFORE(_xlfn.TEXTAFTER(A24, "("), ")") -> 2018 | J24: =_xlfn.LET( _xlpm.doi,IF(C24<>"",C24,_xlfn.TEXTAFTER(A24,"https://doi.org/")), SUBSTITUTE( SUBSTITUTE( SUBSTITUTE( SUBSTITUTE( _xlpm.doi, "/","%2F"), ":","%3A"), "<","%3C"), ">","%3E") ) -> 10.1016%2Fj.jhevol.2017.09.003 | K24: =TRIM(_xlfn.TEXTJOIN("_",FALSE(),F24,(SUBSTITUTE(SUBSTITUTE(D24," ",""), "_", "")))) -> Boyer_Harrington_2018_Table1 | L24: =J24 & "_" & SUBSTITUTE(SUBSTITUTE(SUBSTITUTE(D24,CHAR(160),"")," ",""),"_","") -> 10.1016%2Fj.jhevol.2017.09.003_Table1 | M24: {=IFERROR(INDEX(FileList!$A$1:$A$100,MATCH(TRUE(),EXACT(L24,_xlfn.TEXTBEFORE(FileList!$A$1:$A$100,".tsv")),0)),"notfound")} -> notfound | N24: Table 1 Taxon list and species mean values.
A25: Boyer, D. M., & Harrington, A. R. (2019). New estimates of blood flow rates in the vertebral artery of euarchontans and their implications for encephalic blood flow scaling: A response to Seymour and Snelling (2018). J Hum Evol, 128, 93-98. https://doi.org/10.1016/j.jhevol.2018.10.002 | D25: SOM Table S6 | E25: =RIGHT(A25,1) -> 2 | F25: =G25 & IF(H25<>"", "_" & H25, "_") & IF(I25<>"", "_" & I25, "_") & IF(B25<>"", "_" & B25, "") -> Boyer_Harrington_2019 | G25: =SUBSTITUTE(SUBSTITUTE(_xlfn.TEXTBEFORE(A25,","), "-", ""), " ", "") -> Boyer | H25: =_xlfn.LET( _xlpm.authors,_xlfn.TEXTBEFORE(A25," ("&I25&")"), _xlpm.hasAmp,ISNUMBER(SEARCH("&",_xlpm.authors)), _xlpm.commasBeforeAmp,IF(_xlpm.hasAmp,LEN(_xlfn.TEXTBEFORE(_xlpm.authors,"&"))-LEN(SUBSTITUTE(_xlfn.TEXTBEFORE(_xlpm.authors,"&"),",","")),0), IF(NOT(_xlpm.hasAmp),"",IF(_xlpm.commasBeforeAmp>2,"etal",TRIM(_xlfn.TEXTBEFORE(_xlfn.TEXTAFTER(_xlpm.authors,"& "),",")))) ) -> Harrington | I25: =_xlfn.TEXTBEFORE(_xlfn.TEXTAFTER(A25, "("), ")") -> 2019 | J25: =_xlfn.LET( _xlpm.doi,IF(C25<>"",C25,_xlfn.TEXTAFTER(A25,"https://doi.org/")), SUBSTITUTE( SUBSTITUTE( SUBSTITUTE( SUBSTITUTE( _xlpm.doi, "/","%2F"), ":","%3A"), "<","%3C"), ">","%3E") ) -> 10.1016%2Fj.jhevol.2018.10.002 | K25: =TRIM(_xlfn.TEXTJOIN("_",FALSE(),F25,(SUBSTITUTE(SUBSTITUTE(D25," ",""), "_", "")))) -> Boyer_Harrington_2019_SOMTableS6 | L25: =J25 & "_" & SUBSTITUTE(SUBSTITUTE(SUBSTITUTE(D25,CHAR(160),"")," ",""),"_","") -> 10.1016%2Fj.jhevol.2018.10.002_SOMTableS6 | M25: {=IFERROR(INDEX(FileList!$A$1:$A$100,MATCH(TRUE(),EXACT(L25,_xlfn.TEXTBEFORE(FileList!$A$1:$A$100,".tsv")),0)),"notfound")} -> notfound
A26: Brodmann, K. (1913). Neue Forschungsergebnisse der Großhirnrindenanatomie mit besonderer Berücksichtigung anthropologischer Fragen. Verhandlungen der Gesellschaft Deutscher Naturforscher und Ärzte, 85(1), 200-240 | C26: 10.0000/placeholder | D26: Tabelle 1 | E26: =RIGHT(A26,1) -> 0 | F26: =G26 & IF(H26<>"", "_" & H26, "_") & IF(I26<>"", "_" & I26, "_") & IF(B26<>"", "_" & B26, "") -> Brodmann__1913 | G26: =SUBSTITUTE(SUBSTITUTE(_xlfn.TEXTBEFORE(A26,","), "-", ""), " ", "") -> Brodmann | H26: =_xlfn.LET( _xlpm.authors,_xlfn.TEXTBEFORE(A26," ("&I26&")"), _xlpm.hasAmp,ISNUMBER(SEARCH("&",_xlpm.authors)), _xlpm.commasBeforeAmp,IF(_xlpm.hasAmp,LEN(_xlfn.TEXTBEFORE(_xlpm.authors,"&"))-LEN(SUBSTITUTE(_xlfn.TEXTBEFORE(_xlpm.authors,"&"),",","")),0), IF(NOT(_xlpm.hasAmp),"",IF(_xlpm.commasBeforeAmp>2,"etal",TRIM(_xlfn.TEXTBEFORE(_xlfn.TEXTAFTER(_xlpm.authors,"& "),",")))) ) | I26: =_xlfn.TEXTBEFORE(_xlfn.TEXTAFTER(A26, "("), ")") -> 1913 | J26: =_xlfn.LET( _xlpm.doi,IF(C26<>"",C26,_xlfn.TEXTAFTER(A26,"https://doi.org/")), SUBSTITUTE( SUBSTITUTE( SUBSTITUTE( SUBSTITUTE( _xlpm.doi, "/","%2F"), ":","%3A"), "<","%3C"), ">","%3E") ) -> 10.0000%2Fplaceholder | K26: =TRIM(_xlfn.TEXTJOIN("_",FALSE(),F26,(SUBSTITUTE(SUBSTITUTE(D26," ",""), "_", "")))) -> Brodmann__1913_Tabelle1 | L26: =J26 & "_" & SUBSTITUTE(SUBSTITUTE(SUBSTITUTE(D26,CHAR(160),"")," ",""),"_","") -> 10.0000%2Fplaceholder_Tabelle1 | M26: {=IFERROR(INDEX(FileList!$A$1:$A$100,MATCH(TRUE(),EXACT(L26,_xlfn.TEXTBEFORE(FileList!$A$1:$A$100,".tsv")),0)),"notfound")} -> notfound | AI26: cortical surface area | AJ26: Mammals (various) | AL26: primary | AM26: cortical surface area
A27: Burger, J. R., George, M. A., Leadbetter, C., & Shaikh, F. (2019). The allometry of brain size in mammals. J Mammal, 100(2), 276-283. https://doi.org/10.1093/jmammal/gyz043 | D27: Supplementary Data SD1 | E27: =RIGHT(A27,1) -> 3 | F27: =G27 & IF(H27<>"", "_" & H27, "_") & IF(I27<>"", "_" & I27, "_") & IF(B27<>"", "_" & B27, "") -> Burger_etal_2019 | G27: =SUBSTITUTE(SUBSTITUTE(_xlfn.TEXTBEFORE(A27,","), "-", ""), " ", "") -> Burger | H27: =_xlfn.LET( _xlpm.authors,_xlfn.TEXTBEFORE(A27," ("&I27&")"), _xlpm.hasAmp,ISNUMBER(SEARCH("&",_xlpm.authors)), _xlpm.commasBeforeAmp,IF(_xlpm.hasAmp,LEN(_xlfn.TEXTBEFORE(_xlpm.authors,"&"))-LEN(SUBSTITUTE(_xlfn.TEXTBEFORE(_xlpm.authors,"&"),",","")),0), IF(NOT(_xlpm.hasAmp),"",IF(_xlpm.commasBeforeAmp>2,"etal",TRIM(_xlfn.TEXTBEFORE(_xlfn.TEXTAFTER(_xlpm.authors,"& "),",")))) ) -> etal | I27: =_xlfn.TEXTBEFORE(_xlfn.TEXTAFTER(A27, "("), ")") -> 2019 | J27: =_xlfn.LET( _xlpm.doi,IF(C27<>"",C27,_xlfn.TEXTAFTER(A27,"https://doi.org/")), SUBSTITUTE( SUBSTITUTE( SUBSTITUTE( SUBSTITUTE( _xlpm.doi, "/","%2F"), ":","%3A"), "<","%3C"), ">","%3E") ) -> 10.1093%2Fjmammal%2Fgyz043 | K27: =TRIM(_xlfn.TEXTJOIN("_",FALSE(),F27,(SUBSTITUTE(SUBSTITUTE(D27," ",""), "_", "")))) -> Burger_etal_2019_SupplementaryDataSD1 | L27: =J27 & "_" & SUBSTITUTE(SUBSTITUTE(SUBSTITUTE(D27,CHAR(160),"")," ",""),"_","") -> 10.1093%2Fjmammal%2Fgyz043_SupplementaryDataSD1 | M27: {=IFERROR(INDEX(FileList!$A$1:$A$100,MATCH(TRUE(),EXACT(L27,_xlfn.TEXTBEFORE(FileList!$A$1:$A$100,".tsv")),0)),"notfound")} -> 10.1093%2Fjmammal%2Fgyz043_SupplementaryDataSD1.tsv | O27: Supplementary Data SD2 | P27: FINISHED | Q27: already there | R27: gyz043_suppl_Supplement_Data.csv | S27: N | T27: =IF(S27="N", R27, "write file name") -> gyz043_suppl_Supplement_Data.csv | U27: zipped csv | V27: table | W27: NO - the article link did not work in R, and goes to a zip | AB27: derived relative brain size data are problematic | AH27: mammals | AI27: Brain and body size | AJ27: Mammals | AK27: secondary | AL27: secondary | AM27: brain & body mass
A28: Burish, M. J., Peebles, J. K., Baldwin, M. K., Tavares, L., Kaas, J. H., & Herculano-Houzel, S. (2010). Cellular scaling rules for primate spinal cords. Brain Behav Evol, 76(1), 45-59. https://doi.org/10.1159/000319019 | D28: Supplementary Table 1 | E28: =RIGHT(A28,1) -> 9 | F28: =G28 & IF(H28<>"", "_" & H28, "_") & IF(I28<>"", "_" & I28, "_") & IF(B28<>"", "_" & B28, "") -> Burish_etal_2010 | G28: =SUBSTITUTE(SUBSTITUTE(_xlfn.TEXTBEFORE(A28,","), "-", ""), " ", "") -> Burish | H28: =_xlfn.LET( _xlpm.authors,_xlfn.TEXTBEFORE(A28," ("&I28&")"), _xlpm.hasAmp,ISNUMBER(SEARCH("&",_xlpm.authors)), _xlpm.commasBeforeAmp,IF(_xlpm.hasAmp,LEN(_xlfn.TEXTBEFORE(_xlpm.authors,"&"))-LEN(SUBSTITUTE(_xlfn.TEXTBEFORE(_xlpm.authors,"&"),",","")),0), IF(NOT(_xlpm.hasAmp),"",IF(_xlpm.commasBeforeAmp>2,"etal",TRIM(_xlfn.TEXTBEFORE(_xlfn.TEXTAFTER(_xlpm.authors,"& "),",")))) ) -> etal | I28: =_xlfn.TEXTBEFORE(_xlfn.TEXTAFTER(A28, "("), ")") -> 2010 | J28: =_xlfn.LET( _xlpm.doi,IF(C28<>"",C28,_xlfn.TEXTAFTER(A28,"https://doi.org/")), SUBSTITUTE( SUBSTITUTE( SUBSTITUTE( SUBSTITUTE( _xlpm.doi, "/","%2F"), ":","%3A"), "<","%3C"), ">","%3E") ) -> 10.1159%2F000319019 | K28: =TRIM(_xlfn.TEXTJOIN("_",FALSE(),F28,(SUBSTITUTE(SUBSTITUTE(D28," ",""), "_", "")))) -> Burish_etal_2010_SupplementaryTable1 | L28: =J28 & "_" & SUBSTITUTE(SUBSTITUTE(SUBSTITUTE(D28,CHAR(160),"")," ",""),"_","") -> 10.1159%2F000319019_SupplementaryTable1 | M28: {=IFERROR(INDEX(FileList!$A$1:$A$100,MATCH(TRUE(),EXACT(L28,_xlfn.TEXTBEFORE(FileList!$A$1:$A$100,".tsv")),0)),"notfound")} -> 10.1159%2F000319019_SupplementaryTable1.tsv | N28: Supplementary Table 1: Dataset of individual spinal cord measurements | P28: Species - binomials need to be added | R28: Burish_etal_2010_SupplementaryTable1_snapshot.csv | Y28: HH | Z28: HH | AA28: number spinal cord neurons | AG28: isotropic fractionator | AH28: primates and tree shrew | AJ28: Primates (+ other mammals) | AK28: primary (individual) | AL28: review | AM28: review
A29: Burish, M. J., Peebles, J. K., Baldwin, M. K., Tavares, L., Kaas, J. H., & Herculano-Houzel, S. (2010). Cellular scaling rules for primate spinal cords. Brain Behav Evol, 76(1), 45-59. https://doi.org/10.1159/000319019 | D29: Table 1 | E29: =RIGHT(A29,1) -> 9 | F29: =G29 & IF(H29<>"", "_" & H29, "_") & IF(I29<>"", "_" & I29, "_") & IF(B29<>"", "_" & B29, "") -> Burish_etal_2010 | G29: =SUBSTITUTE(SUBSTITUTE(_xlfn.TEXTBEFORE(A29,","), "-", ""), " ", "") -> Burish | H29: =_xlfn.LET( _xlpm.authors,_xlfn.TEXTBEFORE(A29," ("&I29&")"), _xlpm.hasAmp,ISNUMBER(SEARCH("&",_xlpm.authors)), _xlpm.commasBeforeAmp,IF(_xlpm.hasAmp,LEN(_xlfn.TEXTBEFORE(_xlpm.authors,"&"))-LEN(SUBSTITUTE(_xlfn.TEXTBEFORE(_xlpm.authors,"&"),",","")),0), IF(NOT(_xlpm.hasAmp),"",IF(_xlpm.commasBeforeAmp>2,"etal",TRIM(_xlfn.TEXTBEFORE(_xlfn.TEXTAFTER(_xlpm.authors,"& "),",")))) ) -> etal | I29: =_xlfn.TEXTBEFORE(_xlfn.TEXTAFTER(A29, "("), ")") -> 2010 | J29: =_xlfn.LET( _xlpm.doi,IF(C29<>"",C29,_xlfn.TEXTAFTER(A29,"https://doi.org/")), SUBSTITUTE( SUBSTITUTE( SUBSTITUTE( SUBSTITUTE( _xlpm.doi, "/","%2F"), ":","%3A"), "<","%3C"), ">","%3E") ) -> 10.1159%2F000319019 | K29: =TRIM(_xlfn.TEXTJOIN("_",FALSE(),F29,(SUBSTITUTE(SUBSTITUTE(D29," ",""), "_", "")))) -> Burish_etal_2010_Table1 | L29: =J29 & "_" & SUBSTITUTE(SUBSTITUTE(SUBSTITUTE(D29,CHAR(160),"")," ",""),"_","") -> 10.1159%2F000319019_Table1 | M29: {=IFERROR(INDEX(FileList!$A$1:$A$100,MATCH(TRUE(),EXACT(L29,_xlfn.TEXTBEFORE(FileList!$A$1:$A$100,".tsv")),0)),"notfound")} -> 10.1159%2F000319019_Table1.tsv | N29: Table 1. Cellular composition of the spinal cord | P29: FINISHED | Q29: added | R29: Burish_etal_2010_Table1_snapshot.csv | T29: Burish_etal_2010_Table1.csv | U29: pdf | V29: table | X29: https://doi.org/10.1159/000319019 | Y29: HH | Z29: HH | AA29: number spinal cord neurons | AC29: species-name-error: species-name typo corrected from paper text (in .R script). | AG29: isotropic fractionator | AH29: primates and tree shrew | AJ29: Primates (+ other mammals) | AK29: primary (averages) | AL29: review | AM29: review
A30: Bush, E. C., & Allman, J. M. (2003). The scaling of white matter to gray matter in cerebellum and neocortex. Brain Behav Evol, 61(1), 1-5. https://doi.org/10.1159/000068880 | D30: Table 1 | E30: =RIGHT(A30,1) -> 0 | F30: =G30 & IF(H30<>"", "_" & H30, "_") & IF(I30<>"", "_" & I30, "_") & IF(B30<>"", "_" & B30, "") -> Bush_Allman_2003 | G30: =SUBSTITUTE(SUBSTITUTE(_xlfn.TEXTBEFORE(A30,","), "-", ""), " ", "") -> Bush | H30: =_xlfn.LET( _xlpm.authors,_xlfn.TEXTBEFORE(A30," ("&I30&")"), _xlpm.hasAmp,ISNUMBER(SEARCH("&",_xlpm.authors)), _xlpm.commasBeforeAmp,IF(_xlpm.hasAmp,LEN(_xlfn.TEXTBEFORE(_xlpm.authors,"&"))-LEN(SUBSTITUTE(_xlfn.TEXTBEFORE(_xlpm.authors,"&"),",","")),0), IF(NOT(_xlpm.hasAmp),"",IF(_xlpm.commasBeforeAmp>2,"etal",TRIM(_xlfn.TEXTBEFORE(_xlfn.TEXTAFTER(_xlpm.authors,"& "),",")))) ) -> Allman | I30: =_xlfn.TEXTBEFORE(_xlfn.TEXTAFTER(A30, "("), ")") -> 2003 | J30: =_xlfn.LET( _xlpm.doi,IF(C30<>"",C30,_xlfn.TEXTAFTER(A30,"https://doi.org/")), SUBSTITUTE( SUBSTITUTE( SUBSTITUTE( SUBSTITUTE( _xlpm.doi, "/","%2F"), ":","%3A"), "<","%3C"), ">","%3E") ) -> 10.1159%2F000068880 | K30: =TRIM(_xlfn.TEXTJOIN("_",FALSE(),F30,(SUBSTITUTE(SUBSTITUTE(D30," ",""), "_", "")))) -> Bush_Allman_2003_Table1 | L30: =J30 & "_" & SUBSTITUTE(SUBSTITUTE(SUBSTITUTE(D30,CHAR(160),"")," ",""),"_","") -> 10.1159%2F000068880_Table1 | M30: {=IFERROR(INDEX(FileList!$A$1:$A$100,MATCH(TRUE(),EXACT(L30,_xlfn.TEXTBEFORE(FileList!$A$1:$A$100,".tsv")),0)),"notfound")} -> 10.1159%2F000068880_Table1.tsv | N30: Table 2. Major axis regression slopes and 95% confidence intervals | P30: not extracted (regression statistics, not species trait data) | Y30: Allman | Z30: AFIP
A31: Bush, E. C., & Allman, J. M. (2004). The scaling of frontal cortex in primates and carnivores. Proc Natl Acad Sci U S A, 101(11), 3962-3966. https://doi.org/10.1073/pnas.0305760101 | B31: a | D31: Table 2 | E31: =RIGHT(A31,1) -> 1 | F31: =G31 & IF(H31<>"", "_" & H31, "_") & IF(I31<>"", "_" & I31, "_") & IF(B31<>"", "_" & B31, "") -> Bush_Allman_2004_a | G31: =SUBSTITUTE(SUBSTITUTE(_xlfn.TEXTBEFORE(A31,","), "-", ""), " ", "") -> Bush | H31: =_xlfn.LET( _xlpm.authors,_xlfn.TEXTBEFORE(A31," ("&I31&")"), _xlpm.hasAmp,ISNUMBER(SEARCH("&",_xlpm.authors)), _xlpm.commasBeforeAmp,IF(_xlpm.hasAmp,LEN(_xlfn.TEXTBEFORE(_xlpm.authors,"&"))-LEN(SUBSTITUTE(_xlfn.TEXTBEFORE(_xlpm.authors,"&"),",","")),0), IF(NOT(_xlpm.hasAmp),"",IF(_xlpm.commasBeforeAmp>2,"etal",TRIM(_xlfn.TEXTBEFORE(_xlfn.TEXTAFTER(_xlpm.authors,"& "),",")))) ) -> Allman | I31: =_xlfn.TEXTBEFORE(_xlfn.TEXTAFTER(A31, "("), ")") -> 2004 | J31: =_xlfn.LET( _xlpm.doi,IF(C31<>"",C31,_xlfn.TEXTAFTER(A31,"https://doi.org/")), SUBSTITUTE( SUBSTITUTE( SUBSTITUTE( SUBSTITUTE( _xlpm.doi, "/","%2F"), ":","%3A"), "<","%3C"), ">","%3E") ) -> 10.1073%2Fpnas.0305760101 | K31: =TRIM(_xlfn.TEXTJOIN("_",FALSE(),F31,(SUBSTITUTE(SUBSTITUTE(D31," ",""), "_", "")))) -> Bush_Allman_2004_a_Table2 | L31: =J31 & "_" & SUBSTITUTE(SUBSTITUTE(SUBSTITUTE(D31,CHAR(160),"")," ",""),"_","") -> 10.1073%2Fpnas.0305760101_Table2 | M31: {=IFERROR(INDEX(FileList!$A$1:$A$100,MATCH(TRUE(),EXACT(L31,_xlfn.TEXTBEFORE(FileList!$A$1:$A$100,".tsv")),0)),"notfound")} -> 10.1073%2Fpnas.0305760101_Table2.tsv | N31: Table 1. White matter and gray matter volumes (cm3) for neocortex and cerebellum for 45 mammals | P31: Data readable | R31: Bush_Allman_2003_Table1_snapshot.csv | S31: Y | T31: Bush_Allman_2003_Table1.csv | U31: pdf | V31: table | Y31: Allman | Z31: AFIP | AF31: histological sections | AG31: volumetry | AH31: mammals (incl. primates) | AI31: neocortex & cerebellum grey/white volumes | AK31: primary
A32: Bush, E. C., & Allman, J. M. (2004). Three-dimensional structure and evolution of primate primary visual cortex. Anat Rec (Hoboken), 281(1), 1088-1094. https://doi.org/10.1002/ar.a.20114 | B32: b | D32: TABLE 1 | E32: =RIGHT(A32,1) -> 4 | F32: =G32 & IF(H32<>"", "_" & H32, "_") & IF(I32<>"", "_" & I32, "_") & IF(B32<>"", "_" & B32, "") -> Bush_Allman_2004_b | G32: =SUBSTITUTE(SUBSTITUTE(_xlfn.TEXTBEFORE(A32,","), "-", ""), " ", "") -> Bush | H32: =_xlfn.LET( _xlpm.authors,_xlfn.TEXTBEFORE(A32," ("&I32&")"), _xlpm.hasAmp,ISNUMBER(SEARCH("&",_xlpm.authors)), _xlpm.commasBeforeAmp,IF(_xlpm.hasAmp,LEN(_xlfn.TEXTBEFORE(_xlpm.authors,"&"))-LEN(SUBSTITUTE(_xlfn.TEXTBEFORE(_xlpm.authors,"&"),",","")),0), IF(NOT(_xlpm.hasAmp),"",IF(_xlpm.commasBeforeAmp>2,"etal",TRIM(_xlfn.TEXTBEFORE(_xlfn.TEXTAFTER(_xlpm.authors,"& "),",")))) ) -> Allman | I32: =_xlfn.TEXTBEFORE(_xlfn.TEXTAFTER(A32, "("), ")") -> 2004 | J32: =_xlfn.LET( _xlpm.doi,IF(C32<>"",C32,_xlfn.TEXTAFTER(A32,"https://doi.org/")), SUBSTITUTE( SUBSTITUTE( SUBSTITUTE( SUBSTITUTE( _xlpm.doi, "/","%2F"), ":","%3A"), "<","%3C"), ">","%3E") ) -> 10.1002%2Far.a.20114 | K32: =TRIM(_xlfn.TEXTJOIN("_",FALSE(),F32,(SUBSTITUTE(SUBSTITUTE(D32," ",""), "_", "")))) -> Bush_Allman_2004_b_TABLE1 | L32: =J32 & "_" & SUBSTITUTE(SUBSTITUTE(SUBSTITUTE(D32,CHAR(160),"")," ",""),"_","") -> 10.1002%2Far.a.20114_TABLE1 | M32: {=IFERROR(INDEX(FileList!$A$1:$A$100,MATCH(TRUE(),EXACT(L32,_xlfn.TEXTBEFORE(FileList!$A$1:$A$100,".tsv")),0)),"notfound")} -> 10.1002%2Far.a.20114_TABLE1.tsv | N32: Table 1. Measurements in V1 and the rest of the brain for a sample of primates | P32: Data readable | R32: Bush_Allman_2004_Table1_snapshot.csv | S32: Y | T32: Bush_Allman_2004_Table1.csv | U32: pdf | V32: table | Y32: Allman | Z32: AFIP | AF32: histological sections | AG32: volumetry/stereology | AH32: primates | AI32: V1 grey, LGN, V1 surface, neocortex GM/WM | AK32: primary
A33: Caspar, K. R., Pallasdies, F., Mader, L., Sartorelli, H., & Begall, S. (2022). The evolution and biological correlates of hand preferences in anthropoid primates. Elife, 11, e77875. https://doi.org/10.7554/eLife.77875 | D33: Supplementary file 3 | E33: =RIGHT(A33,1) -> 5 | F33: =G33 & IF(H33<>"", "_" & H33, "_") & IF(I33<>"", "_" & I33, "_") & IF(B33<>"", "_" & B33, "") -> Caspar_etal_2022 | G33: =SUBSTITUTE(SUBSTITUTE(_xlfn.TEXTBEFORE(A33,","), "-", ""), " ", "") -> Caspar | H33: =_xlfn.LET( _xlpm.authors,_xlfn.TEXTBEFORE(A33," ("&I33&")"), _xlpm.hasAmp,ISNUMBER(SEARCH("&",_xlpm.authors)), _xlpm.commasBeforeAmp,IF(_xlpm.hasAmp,LEN(_xlfn.TEXTBEFORE(_xlpm.authors,"&"))-LEN(SUBSTITUTE(_xlfn.TEXTBEFORE(_xlpm.authors,"&"),",","")),0), IF(NOT(_xlpm.hasAmp),"",IF(_xlpm.commasBeforeAmp>2,"etal",TRIM(_xlfn.TEXTBEFORE(_xlfn.TEXTAFTER(_xlpm.authors,"& "),",")))) ) -> etal | I33: =_xlfn.TEXTBEFORE(_xlfn.TEXTAFTER(A33, "("), ")") -> 2022 | J33: =_xlfn.LET( _xlpm.doi,IF(C33<>"",C33,_xlfn.TEXTAFTER(A33,"https://doi.org/")), SUBSTITUTE( SUBSTITUTE( SUBSTITUTE( SUBSTITUTE( _xlpm.doi, "/","%2F"), ":","%3A"), "<","%3C"), ">","%3E") ) -> 10.7554%2FeLife.77875 | K33: =TRIM(_xlfn.TEXTJOIN("_",FALSE(),F33,(SUBSTITUTE(SUBSTITUTE(D33," ",""), "_", "")))) -> Caspar_etal_2022_Supplementaryfile3 | L33: =J33 & "_" & SUBSTITUTE(SUBSTITUTE(SUBSTITUTE(D33,CHAR(160),"")," ",""),"_","") -> 10.7554%2FeLife.77875_Supplementaryfile3 | M33: {=IFERROR(INDEX(FileList!$A$1:$A$100,MATCH(TRUE(),EXACT(L33,_xlfn.TEXTBEFORE(FileList!$A$1:$A$100,".tsv")),0)),"notfound")} -> notfound | N33: part 2: ecological table | P33: FINISHED | Q33: added | R33: elife-77875-supp3-v1.xlsx | S33: N | T33: =IF(S33="N", R33, "write file name") -> elife-77875-supp3-v1.xlsx | U33: xlsx | V33: table | W33: YES - download link | X33: https://cdn.elifesciences.org/articles/77875/elife-77875-supp3-v1.xlsx | AH33: primates | AI33: Habitual Tool Use, Ecology, Female brain size | AJ33: Primates | AK33: secondary | AL33: secondary | AM33: behavioural (handedness, tool use, ecology)
