Workbook

Sheet Sheet1
A1: Citation (APA 7th-Annotated) | B1: sequence | C1: DOI if different from article or doi Alt | D1: Item number | E1: end | F1: Publication name | G1: 1st Author | H1: other author(s) | I1: year | J1: DOI (or Alt) | K1: Item name | L1: Item encoded | M1: Item in directory FileList | N1: Item full original title | O1: Note: related Item(s) included in folder | P1: Progress stage | Q1: Online Database | R1: Snapshot | S1: Adjustment made | T1: Data readable file, can use this | U1: Source Type | V1: Source format | W1: Source URL direct access | X1: Source URL link | Y1: Main Trait(s) | Z1: Source type | AA1: Team | AB1: Method | AC1: Possible Traits | AD1: Note | AE1: Subcategory | AF1: Flags pre-addressed | AG1: Flags possible | AH1: Flags active (skips)
A2: Andelin, A. K., Olavarria, J. F., Fine, I., Taber, E. N., Schwartz, D., Kroenke, C. D., & Stevens, A. A. (2019). The Effect of Onset Age of Visual Deprivation on Visual Cortex Surface Area Across-Species. Cereb Cortex, 29(10), 4321-4333. https://doi.org/10.1093/cercor/bhy315 | D2: Table 4 | E2: =RIGHT(A2,1) -> 5 | F2: =G2 & IF(H2<>"", "_" & H2, "_") & IF(I2<>"", "_" & I2, "_") & IF(B2<>"", "_" & B2, "") -> Andelin_etal_2019 | G2: =SUBSTITUTE(SUBSTITUTE(_xlfn.TEXTBEFORE(A2,","), "-", ""), " ", "") -> Andelin | H2: =IF(ISNUMBER(FIND("&", A2)), IF(LEN(A2)-LEN(SUBSTITUTE(A2, ",", ""))>=6, "etal", MID(A2, SEARCH("& ", A2)+2, SEARCH(",", A2, SEARCH("& ", A2)+2) - SEARCH("& ", A2)-2)), "" ) -> etal | I2: =_xlfn.TEXTBEFORE(_xlfn.TEXTAFTER(A2, "("), ")") -> 2019 | J2: =IF(C2<>"", C2, IF(C2="", _xlfn.TEXTAFTER(A2,"https://doi.org/"), C2)) -> 10.1093/cercor/bhy315 | K2: =TRIM(_xlfn.TEXTJOIN("_",FALSE,F2,(SUBSTITUTE(SUBSTITUTE(D2," ",""), "_", "")))) -> Andelin_etal_2019_Table4 | L2: =IF(ISBLANK(C2),TRIM(SUBSTITUTE(SUBSTITUTE(SUBSTITUTE(_xlfn.TEXTJOIN("_", FALSE, J2, SUBSTITUTE(D2,"_", "")), "/", "%2F"), ":", "%3A"), " ", "")),TRIM(SUBSTITUTE(SUBSTITUTE(SUBSTITUTE(_xlfn.TEXTJOIN("_", FALSE, C2, SUBSTITUTE(D2,"_", "")), "/", "%2F"), ":", "%3A"), " ", ""))) -> 10.1093%2Fcercor%2Fbhy315_Table4 | M2: {=IFERROR(INDEX(FileList!$A$1:$A$100, MATCH(L2, _xlfn.TEXTBEFORE(FileList!$A$1:$A$100, ".tsv"), 0)), "notfound")} -> 10.1093%2Fcercor%2Fbhy315_Table4.tsv | V2: table
A3: Avelino-de-Souza, K., Patzke, N., Karlsson, K. A. E., Manger, P. R., & Herculano-Houzel, S. (2025). Cellular Composition of the Brain of a Northern Minke Whale. J Comp Neurol, 533(9), e70089. https://doi.org/10.1002/cne.70089 | D3: TABLE 1 | E3: =RIGHT(A3,1) -> 9 | F3: =G3 & IF(H3<>"", "_" & H3, "_") & IF(I3<>"", "_" & I3, "_") & IF(B3<>"", "_" & B3, "") -> AvelinodeSouza_etal_2025 | G3: =SUBSTITUTE(SUBSTITUTE(_xlfn.TEXTBEFORE(A3,","), "-", ""), " ", "") -> AvelinodeSouza | H3: =IF(ISNUMBER(FIND("&", A3)), IF(LEN(A3)-LEN(SUBSTITUTE(A3, ",", ""))>=6, "etal", MID(A3, SEARCH("& ", A3)+2, SEARCH(",", A3, SEARCH("& ", A3)+2) - SEARCH("& ", A3)-2)), "" ) -> etal | I3: =_xlfn.TEXTBEFORE(_xlfn.TEXTAFTER(A3, "("), ")") -> 2025 | J3: =IF(C3<>"", C3, IF(C3="", _xlfn.TEXTAFTER(A3,"https://doi.org/"), C3)) -> 10.1002/cne.70089 | K3: =TRIM(_xlfn.TEXTJOIN("_",FALSE,F3,(SUBSTITUTE(SUBSTITUTE(D3," ",""), "_", "")))) -> AvelinodeSouza_etal_2025_TABLE1 | L3: =IF(ISBLANK(C3),TRIM(SUBSTITUTE(SUBSTITUTE(SUBSTITUTE(_xlfn.TEXTJOIN("_", FALSE, J3, SUBSTITUTE(D3,"_", "")), "/", "%2F"), ":", "%3A"), " ", "")),TRIM(SUBSTITUTE(SUBSTITUTE(SUBSTITUTE(_xlfn.TEXTJOIN("_", FALSE, C3, SUBSTITUTE(D3,"_", "")), "/", "%2F"), ":", "%3A"), " ", ""))) -> 10.1002%2Fcne.70089_TABLE1 | M3: {=IFERROR(INDEX(FileList!$A$1:$A$100, MATCH(L3, _xlfn.TEXTBEFORE(FileList!$A$1:$A$100, ".tsv"), 0)), "notfound")} -> 10.1002%2Fcne.70089_TABLE1.tsv | N3: Table 1. Cellular composition of the brain of a Northern minke whale (Balaenoptera acutorostrata) | P3: FINISHED | Q3: added | R3: AvelinodeSouza_etal_2025_TABLE1_snapshot.csv | S3: Y | T3: AvelinodeSouza_etal_2025_TABLE1.csv | U3: pdf | V3: table | W3: https://onlinelibrary.wiley.com/doi/10.1002/cne.70089 | X3: https://doi.org/10.1002/cne.70089 | Y3: neuron number | Z3: primary | AA3: HH | AB3: HH | AE3: placental mammals
A4: Barbeito-Andres, J., Castro-Fonseca, E., Qiu, L. R., Bernal, V., Lent, R., Henkelman, M., Lukowiak, K., Gleiser, P. M., Hallgrimsson, B., & Gonzalez, P. N. (2019). Region-specific changes in Mus musculus brain size and cell composition under chronic nutrient restriction. J Exp Biol, 222(Pt 17). https://doi.org/10.1242/jeb.204651 | D4: data_figshare.xlsx | E4: =RIGHT(A4,1) -> 1 | F4: =G4 & IF(H4<>"", "_" & H4, "_") & IF(I4<>"", "_" & I4, "_") & IF(B4<>"", "_" & B4, "") -> BarbeitoAndres_etal_2019 | G4: =SUBSTITUTE(SUBSTITUTE(_xlfn.TEXTBEFORE(A4,","), "-", ""), " ", "") -> BarbeitoAndres | H4: =IF(ISNUMBER(FIND("&", A4)), IF(LEN(A4)-LEN(SUBSTITUTE(A4, ",", ""))>=6, "etal", MID(A4, SEARCH("& ", A4)+2, SEARCH(",", A4, SEARCH("& ", A4)+2) - SEARCH("& ", A4)-2)), "" ) -> etal | I4: =_xlfn.TEXTBEFORE(_xlfn.TEXTAFTER(A4, "("), ")") -> 2019 | J4: =IF(C4<>"", C4, IF(C4="", _xlfn.TEXTAFTER(A4,"https://doi.org/"), C4)) -> 10.1242/jeb.204651 | K4: =TRIM(_xlfn.TEXTJOIN("_",FALSE,F4,(SUBSTITUTE(SUBSTITUTE(D4," ",""), "_", "")))) -> BarbeitoAndres_etal_2019_datafigshare.xlsx | L4: =IF(ISBLANK(C4),TRIM(SUBSTITUTE(SUBSTITUTE(SUBSTITUTE(_xlfn.TEXTJOIN("_", FALSE, J4, SUBSTITUTE(D4,"_", "")), "/", "%2F"), ":", "%3A"), " ", "")),TRIM(SUBSTITUTE(SUBSTITUTE(SUBSTITUTE(_xlfn.TEXTJOIN("_", FALSE, C4, SUBSTITUTE(D4,"_", "")), "/", "%2F"), ":", "%3A"), " ", ""))) -> 10.1242%2Fjeb.204651_datafigshare.xlsx | M4: {=IFERROR(INDEX(FileList!$A$1:$A$100, MATCH(L4, _xlfn.TEXTBEFORE(FileList!$A$1:$A$100, ".tsv"), 0)), "notfound")} -> notfound
A5: Baron, G., Frahm, H. D., & Stephan, H. (1988). Comparison of brain structure volumes in Insectivora and Primates. VIII. Vestibular complex. J Hirnforsch, 29(5), 509-523. http://www.ncbi.nlm.nih.gov/pubmed/3216099 | C5: PMID:3216099 | D5: Table1 | E5: =RIGHT(A5,1) -> 9 | F5: =G5 & IF(H5<>"", "_" & H5, "_") & IF(I5<>"", "_" & I5, "_") & IF(B5<>"", "_" & B5, "") -> Baron_etal_1988 | G5: =SUBSTITUTE(SUBSTITUTE(_xlfn.TEXTBEFORE(A5,","), "-", ""), " ", "") -> Baron | H5: =IF(ISNUMBER(FIND("&", A5)), IF(LEN(A5)-LEN(SUBSTITUTE(A5, ",", ""))>=6, "etal", MID(A5, SEARCH("& ", A5)+2, SEARCH(",", A5, SEARCH("& ", A5)+2) - SEARCH("& ", A5)-2)), "" ) -> etal | I5: =_xlfn.TEXTBEFORE(_xlfn.TEXTAFTER(A5, "("), ")") -> 1988 | J5: =IF(C5<>"", C5, IF(C5="", _xlfn.TEXTAFTER(A5,"https://doi.org/"), C5)) -> PMID:3216099 | K5: =TRIM(_xlfn.TEXTJOIN("_",FALSE,F5,(SUBSTITUTE(SUBSTITUTE(D5," ",""), "_", "")))) -> Baron_etal_1988_Table1 | L5: =IF(ISBLANK(C5),TRIM(SUBSTITUTE(SUBSTITUTE(SUBSTITUTE(_xlfn.TEXTJOIN("_", FALSE, J5, SUBSTITUTE(D5,"_", "")), "/", "%2F"), ":", "%3A"), " ", "")),TRIM(SUBSTITUTE(SUBSTITUTE(SUBSTITUTE(_xlfn.TEXTJOIN("_", FALSE, C5, SUBSTITUTE(D5,"_", "")), "/", "%2F"), ":", "%3A"), " ", ""))) -> PMID%3A3216099_Table1 | M5: {=IFERROR(INDEX(FileList!$A$1:$A$100, MATCH(L5, _xlfn.TEXTBEFORE(FileList!$A$1:$A$100, ".tsv"), 0)), "notfound")} -> notfound | N5: Table 1. Volumes and indices of the vestibular complex (VC) and its main components (VM, V1, VL, VS) in Insectivora and Scadentia | AA5: Stephan
A6: Baron, G., Frahm, H. D., Bhatnagar, K. P., & Stephan, H. (1983). Comparison of brain structure volumes in Insectivora and Primates. III. Main olfactory bulb (MOB). J Hirnforsch, 24(5), 551-568. https://www.ncbi.nlm.nih.gov/pubmed/6663055 | C6: PMID:6663055 | D6: Table1 | E6: =RIGHT(A6,1) -> 5 | F6: =G6 & IF(H6<>"", "_" & H6, "_") & IF(I6<>"", "_" & I6, "_") & IF(B6<>"", "_" & B6, "") -> Baron_etal_1983 | G6: =SUBSTITUTE(SUBSTITUTE(_xlfn.TEXTBEFORE(A6,","), "-", ""), " ", "") -> Baron | H6: =IF(ISNUMBER(FIND("&", A6)), IF(LEN(A6)-LEN(SUBSTITUTE(A6, ",", ""))>=6, "etal", MID(A6, SEARCH("& ", A6)+2, SEARCH(",", A6, SEARCH("& ", A6)+2) - SEARCH("& ", A6)-2)), "" ) -> etal | I6: =_xlfn.TEXTBEFORE(_xlfn.TEXTAFTER(A6, "("), ")") -> 1983 | J6: =IF(C6<>"", C6, IF(C6="", _xlfn.TEXTAFTER(A6,"https://doi.org/"), C6)) -> PMID:6663055 | K6: =TRIM(_xlfn.TEXTJOIN("_",FALSE,F6,(SUBSTITUTE(SUBSTITUTE(D6," ",""), "_", "")))) -> Baron_etal_1983_Table1 | L6: PMID%3A6663055_Table1 | M6: {=IFERROR(INDEX(FileList!$A$1:$A$100, MATCH(L6, _xlfn.TEXTBEFORE(FileList!$A$1:$A$100, ".tsv"), 0)), "notfound")} -> notfound | V6: table | W6: NO - not digitized | Z6: primary | AB6: Stephan
A7: Baron, G., Stephan, H., & Frahm, H. D. (1987). Comparison of brain structure volumes in Insectivora and Primates. VI. Paleocortical components. J Hirnforsch, 28(4), 463-477. http://www.ncbi.nlm.nih.gov/pubmed/3116076 | C7: PMID:3116076 | D7: Table1 | E7: =RIGHT(A7,1) -> 6 | F7: =G7 & IF(H7<>"", "_" & H7, "_") & IF(I7<>"", "_" & I7, "_") & IF(B7<>"", "_" & B7, "") -> Baron_etal_1987 | G7: =SUBSTITUTE(SUBSTITUTE(_xlfn.TEXTBEFORE(A7,","), "-", ""), " ", "") -> Baron | H7: =IF(ISNUMBER(FIND("&", A7)), IF(LEN(A7)-LEN(SUBSTITUTE(A7, ",", ""))>=6, "etal", MID(A7, SEARCH("& ", A7)+2, SEARCH(",", A7, SEARCH("& ", A7)+2) - SEARCH("& ", A7)-2)), "" ) -> etal | I7: =_xlfn.TEXTBEFORE(_xlfn.TEXTAFTER(A7, "("), ")") -> 1987 | J7: =IF(C7<>"", C7, IF(C7="", _xlfn.TEXTAFTER(A7,"https://doi.org/"), C7)) -> PMID:3116076 | K7: =TRIM(_xlfn.TEXTJOIN("_",FALSE,F7,(SUBSTITUTE(SUBSTITUTE(D7," ",""), "_", "")))) -> Baron_etal_1987_Table1 | L7: PMID%3A3116076_Table1 | M7: {=IFERROR(INDEX(FileList!$A$1:$A$100, MATCH(L7, _xlfn.TEXTBEFORE(FileList!$A$1:$A$100, ".tsv"), 0)), "notfound")} -> notfound | V7: table | W7: NO - not digitized | Z7: primary | AB7: Stephan
A8: Baron, G., Stephan, H., & Frahm, H. D. (1990). Comparison of brain structure volumes in Insectivora and primates. IX. Trigeminal complex. J Hirnforsch, 31(2), 193-200. https://www.ncbi.nlm.nih.gov/pubmed/2358663 | C8: PMID:2358663 | D8: Table1 | E8: =RIGHT(A8,1) -> 3 | F8: =G8 & IF(H8<>"", "_" & H8, "_") & IF(I8<>"", "_" & I8, "_") & IF(B8<>"", "_" & B8, "") -> Baron_etal_1990 | G8: =SUBSTITUTE(SUBSTITUTE(_xlfn.TEXTBEFORE(A8,","), "-", ""), " ", "") -> Baron | H8: =IF(ISNUMBER(FIND("&", A8)), IF(LEN(A8)-LEN(SUBSTITUTE(A8, ",", ""))>=6, "etal", MID(A8, SEARCH("& ", A8)+2, SEARCH(",", A8, SEARCH("& ", A8)+2) - SEARCH("& ", A8)-2)), "" ) -> etal | I8: =_xlfn.TEXTBEFORE(_xlfn.TEXTAFTER(A8, "("), ")") -> 1990 | J8: =IF(C8<>"", C8, IF(C8="", _xlfn.TEXTAFTER(A8,"https://doi.org/"), C8)) -> PMID:2358663 | K8: =TRIM(_xlfn.TEXTJOIN("_",FALSE,F8,(SUBSTITUTE(SUBSTITUTE(D8," ",""), "_", "")))) -> Baron_etal_1990_Table1 | L8: =IF(ISBLANK(C8),TRIM(SUBSTITUTE(SUBSTITUTE(SUBSTITUTE(_xlfn.TEXTJOIN("_", FALSE, J8, SUBSTITUTE(D8,"_", "")), "/", "%2F"), ":", "%3A"), " ", "")),TRIM(SUBSTITUTE(SUBSTITUTE(SUBSTITUTE(_xlfn.TEXTJOIN("_", FALSE, C8, SUBSTITUTE(D8,"_", "")), "/", "%2F"), ":", "%3A"), " ", ""))) -> PMID%3A2358663_Table1 | M8: {=IFERROR(INDEX(FileList!$A$1:$A$100, MATCH(L8, _xlfn.TEXTBEFORE(FileList!$A$1:$A$100, ".tsv"), 0)), "notfound")} -> notfound | N8: ...IX. Trigeminal complex (Table 1) | V8: table | W8: NO - not digitized | Y8: trigeminal complex volume | Z8: primary | AA8: Stephan | AB8: volumetry
A9: Bauernfeind, A. L., de Sousa, A. A., Avasthi, T., Dobson, S. D., Raghanti, M. A., Lewandowski, A. H., Zilles, K., Semendeferi, K., Allman, J. M., Craig, A. D., Hof, P. R., & Sherwood, C. C. (2013). A volumetric comparison of the insular cortex and its subregions in primates. J Hum Evol, 64(4), 263-279. https://doi.org/10.1016/j.jhevol.2012.12.003 | D9: Table1 | E9: =RIGHT(A9,1) -> 3 | F9: =G9 & IF(H9<>"", "_" & H9, "_") & IF(I9<>"", "_" & I9, "_") & IF(B9<>"", "_" & B9, "") -> Bauernfeind_etal_2013 | G9: =SUBSTITUTE(SUBSTITUTE(_xlfn.TEXTBEFORE(A9,","), "-", ""), " ", "") -> Bauernfeind | H9: =IF(ISNUMBER(FIND("&", A9)), IF(LEN(A9)-LEN(SUBSTITUTE(A9, ",", ""))>=6, "etal", MID(A9, SEARCH("& ", A9)+2, SEARCH(",", A9, SEARCH("& ", A9)+2) - SEARCH("& ", A9)-2)), "" ) -> etal | I9: =_xlfn.TEXTBEFORE(_xlfn.TEXTAFTER(A9, "("), ")") -> 2013 | J9: =IF(C9<>"", C9, IF(C9="", _xlfn.TEXTAFTER(A9,"https://doi.org/"), C9)) -> 10.1016/j.jhevol.2012.12.003 | K9: =TRIM(_xlfn.TEXTJOIN("_",FALSE,F9,(SUBSTITUTE(SUBSTITUTE(D9," ",""), "_", "")))) -> Bauernfeind_etal_2013_Table1 | L9: =IF(ISBLANK(C9),TRIM(SUBSTITUTE(SUBSTITUTE(SUBSTITUTE(_xlfn.TEXTJOIN("_", FALSE, J9, SUBSTITUTE(D9,"_", "")), "/", "%2F"), ":", "%3A"), " ", "")),TRIM(SUBSTITUTE(SUBSTITUTE(SUBSTITUTE(_xlfn.TEXTJOIN("_", FALSE, C9, SUBSTITUTE(D9,"_", "")), "/", "%2F"), ":", "%3A"), " ", ""))) -> 10.1016%2Fj.jhevol.2012.12.003_Table1 | M9: {=IFERROR(INDEX(FileList!$A$1:$A$100, MATCH(L9, _xlfn.TEXTBEFORE(FileList!$A$1:$A$100, ".tsv"), 0)), "notfound")} -> notfound | N9: Volumetric comparison of the insular cortex (Table 1) | V9: table | Y9: insular cortex volumes | Z9: primary | AA9: Stephan | AB9: volumetry
A10: Brodmann, K. (1913). Neue Forschungsergebnisse der Großhirnrindenanatomie mit besonderer Berücksichtigung anthropologischer Fragen. Verhandlungen der Gesellschaft Deutscher Naturforscher und Ärzte, 85(1), 200-240 | C10: 10.0000/placeholder | D10: Tabelle 1 | E10: =RIGHT(A10,1) -> 0 | F10: =G10 & IF(H10<>"", "_" & H10, "_") & IF(I10<>"", "_" & I10, "_") & IF(B10<>"", "_" & B10, "") -> Brodmann__1913 | G10: =SUBSTITUTE(SUBSTITUTE(_xlfn.TEXTBEFORE(A10,","), "-", ""), " ", "") -> Brodmann | H10: =IF(ISNUMBER(FIND("&", A10)), IF(LEN(A10)-LEN(SUBSTITUTE(A10, ",", ""))>=6, "etal", MID(A10, SEARCH("& ", A10)+2, SEARCH(",", A10, SEARCH("& ", A10)+2) - SEARCH("& ", A10)-2)), "" ) | I10: =_xlfn.TEXTBEFORE(_xlfn.TEXTAFTER(A10, "("), ")") -> 1913 | J10: =IF(C10<>"", C10, IF(C10="", _xlfn.TEXTAFTER(A10,"https://doi.org/"), C10)) -> 10.0000/placeholder | K10: =TRIM(_xlfn.TEXTJOIN("_",FALSE,F10,(SUBSTITUTE(SUBSTITUTE(D10," ",""), "_", "")))) -> Brodmann__1913_Tabelle1 | L10: =IF(ISBLANK(C10),TRIM(SUBSTITUTE(SUBSTITUTE(SUBSTITUTE(_xlfn.TEXTJOIN("_", FALSE, J10, SUBSTITUTE(D10,"_", "")), "/", "%2F"), ":", "%3A"), " ", "")),TRIM(SUBSTITUTE(SUBSTITUTE(SUBSTITUTE(_xlfn.TEXTJOIN("_", FALSE, C10, SUBSTITUTE(D10,"_", "")), "/", "%2F"), ":", "%3A"), " ", ""))) -> 10.0000%2Fplaceholder_Tabelle1 | M10: {=IFERROR(INDEX(FileList!$A$1:$A$100, MATCH(L10, _xlfn.TEXTBEFORE(FileList!$A$1:$A$100, ".tsv"), 0)), "notfound")} -> notfound
A11: Burger, J. R., George, M. A., Leadbetter, C., & Shaikh, F. (2019). The allometry of brain size in mammals. J Mammal, 100(2), 276-283. https://doi.org/10.1093/jmammal/gyz043 | D11: Supplementary Data SD1 | E11: =RIGHT(A11,1) -> 3 | F11: =G11 & IF(H11<>"", "_" & H11, "_") & IF(I11<>"", "_" & I11, "_") & IF(B11<>"", "_" & B11, "") -> Burger_etal_2019 | G11: =SUBSTITUTE(SUBSTITUTE(_xlfn.TEXTBEFORE(A11,","), "-", ""), " ", "") -> Burger | H11: =IF(ISNUMBER(FIND("&", A11)), IF(LEN(A11)-LEN(SUBSTITUTE(A11, ",", ""))>=6, "etal", MID(A11, SEARCH("& ", A11)+2, SEARCH(",", A11, SEARCH("& ", A11)+2) - SEARCH("& ", A11)-2)), "" ) -> etal | I11: =_xlfn.TEXTBEFORE(_xlfn.TEXTAFTER(A11, "("), ")") -> 2019 | J11: =IF(C11<>"", C11, IF(C11="", _xlfn.TEXTAFTER(A11,"https://doi.org/"), C11)) -> 10.1093/jmammal/gyz043 | K11: =TRIM(_xlfn.TEXTJOIN("_",FALSE,F11,(SUBSTITUTE(SUBSTITUTE(D11," ",""), "_", "")))) -> Burger_etal_2019_SupplementaryDataSD1 | L11: =IF(ISBLANK(C11),TRIM(SUBSTITUTE(SUBSTITUTE(SUBSTITUTE(_xlfn.TEXTJOIN("_", FALSE, J11, SUBSTITUTE(D11,"_", "")), "/", "%2F"), ":", "%3A"), " ", "")),TRIM(SUBSTITUTE(SUBSTITUTE(SUBSTITUTE(_xlfn.TEXTJOIN("_", FALSE, C11, SUBSTITUTE(D11,"_", "")), "/", "%2F"), ":", "%3A"), " ", ""))) -> 10.1093%2Fjmammal%2Fgyz043_SupplementaryDataSD1 | M11: {=IFERROR(INDEX(FileList!$A$1:$A$100, MATCH(L11, _xlfn.TEXTBEFORE(FileList!$A$1:$A$100, ".tsv"), 0)), "notfound")} -> 10.1093%2Fjmammal%2Fgyz043_SupplementaryDataSD1.tsv | O11: Supplementary Data SD2 | P11: FINISHED | Q11: already there | R11: gyz043_suppl_Supplement_Data.csv | S11: N | T11: =IF(S11="N", R11, "write file name") -> gyz043_suppl_Supplement_Data.csv | U11: zipped csv | V11: table | W11: NO - the article link did not work in R, and goes to a zip | Y11: Brain and body size | Z11: secondary | AD11: derived relative brain size data are problematic | AE11: mammals
A12: Burish, M. J., Peebles, J. K., Baldwin, M. K., Tavares, L., Kaas, J. H., & Herculano-Houzel, S. (2010). Cellular scaling rules for primate spinal cords. Brain Behav Evol, 76(1), 45-59. https://doi.org/10.1159/000319019 | D12: Supplementary Table 1 | E12: =RIGHT(A12,1) -> 9 | F12: =G12 & IF(H12<>"", "_" & H12, "_") & IF(I12<>"", "_" & I12, "_") & IF(B12<>"", "_" & B12, "") -> Burish_etal_2010 | G12: =SUBSTITUTE(SUBSTITUTE(_xlfn.TEXTBEFORE(A12,","), "-", ""), " ", "") -> Burish | H12: =IF(ISNUMBER(FIND("&", A12)), IF(LEN(A12)-LEN(SUBSTITUTE(A12, ",", ""))>=6, "etal", MID(A12, SEARCH("& ", A12)+2, SEARCH(",", A12, SEARCH("& ", A12)+2) - SEARCH("& ", A12)-2)), "" ) -> etal | I12: =_xlfn.TEXTBEFORE(_xlfn.TEXTAFTER(A12, "("), ")") -> 2010 | J12: =IF(C12<>"", C12, IF(C12="", _xlfn.TEXTAFTER(A12,"https://doi.org/"), C12)) -> 10.1159/000319019 | K12: =TRIM(_xlfn.TEXTJOIN("_",FALSE,F12,(SUBSTITUTE(SUBSTITUTE(D12," ",""), "_", "")))) -> Burish_etal_2010_SupplementaryTable1 | L12: =IF(ISBLANK(C12),TRIM(SUBSTITUTE(SUBSTITUTE(SUBSTITUTE(_xlfn.TEXTJOIN("_", FALSE, J12, SUBSTITUTE(D12,"_", "")), "/", "%2F"), ":", "%3A"), " ", "")),TRIM(SUBSTITUTE(SUBSTITUTE(SUBSTITUTE(_xlfn.TEXTJOIN("_", FALSE, C12, SUBSTITUTE(D12,"_", "")), "/", "%2F"), ":", "%3A"), " ", ""))) -> 10.1159%2F000319019_SupplementaryTable1 | M12: {=IFERROR(INDEX(FileList!$A$1:$A$100, MATCH(L12, _xlfn.TEXTBEFORE(FileList!$A$1:$A$100, ".tsv"), 0)), "notfound")} -> 10.1159%2F000319019_SupplementaryTable1.tsv | N12: Supplementary Table 1: Dataset of individual spinal cord measurements | P12: Species - binomials need to be added | R12: Burish_etal_2010_SupplementaryTable1_snapshot.csv | Z12: primary (individual) | AC12: number spinal cord neurons | AE12: primates and tree shrew
A13: Burish, M. J., Peebles, J. K., Baldwin, M. K., Tavares, L., Kaas, J. H., & Herculano-Houzel, S. (2010). Cellular scaling rules for primate spinal cords. Brain Behav Evol, 76(1), 45-59. https://doi.org/10.1159/000319019 | D13: Table 1 | E13: =RIGHT(A13,1) -> 9 | F13: =G13 & IF(H13<>"", "_" & H13, "_") & IF(I13<>"", "_" & I13, "_") & IF(B13<>"", "_" & B13, "") -> Burish_etal_2010 | G13: =SUBSTITUTE(SUBSTITUTE(_xlfn.TEXTBEFORE(A13,","), "-", ""), " ", "") -> Burish | H13: =IF(ISNUMBER(FIND("&", A13)), IF(LEN(A13)-LEN(SUBSTITUTE(A13, ",", ""))>=6, "etal", MID(A13, SEARCH("& ", A13)+2, SEARCH(",", A13, SEARCH("& ", A13)+2) - SEARCH("& ", A13)-2)), "" ) -> etal | I13: =_xlfn.TEXTBEFORE(_xlfn.TEXTAFTER(A13, "("), ")") -> 2010 | J13: =IF(C13<>"", C13, IF(C13="", _xlfn.TEXTAFTER(A13,"https://doi.org/"), C13)) -> 10.1159/000319019 | K13: =TRIM(_xlfn.TEXTJOIN("_",FALSE,F13,(SUBSTITUTE(SUBSTITUTE(D13," ",""), "_", "")))) -> Burish_etal_2010_Table1 | L13: =IF(ISBLANK(C13),TRIM(SUBSTITUTE(SUBSTITUTE(SUBSTITUTE(_xlfn.TEXTJOIN("_", FALSE, J13, SUBSTITUTE(D13,"_", "")), "/", "%2F"), ":", "%3A"), " ", "")),TRIM(SUBSTITUTE(SUBSTITUTE(SUBSTITUTE(_xlfn.TEXTJOIN("_", FALSE, C13, SUBSTITUTE(D13,"_", "")), "/", "%2F"), ":", "%3A"), " ", ""))) -> 10.1159%2F000319019_Table1 | M13: {=IFERROR(INDEX(FileList!$A$1:$A$100, MATCH(L13, _xlfn.TEXTBEFORE(FileList!$A$1:$A$100, ".tsv"), 0)), "notfound")} -> 10.1159%2F000319019_Table1.tsv | N13: Table 1. Cellular composition of the spinal cord | P13: FINISHED | Q13: added | R13: Burish_etal_2010_Table1_snapshot.csv | T13: Burish_etal_2010_Table1.csv | U13: pdf | V13: table | X13: https://doi.org/10.1159/000319019 | Z13: primary (averages) | AC13: number spinal cord neurons | AE13: primates and tree shrew
A14: Caspar, K. R., Pallasdies, F., Mader, L., Sartorelli, H., & Begall, S. (2022). The evolution and biological correlates of hand preferences in anthropoid primates. Elife, 11, e77875. https://doi.org/10.7554/eLife.77875 | D14: Supplementary file 3 | E14: =RIGHT(A14,1) -> 5 | F14: =G14 & IF(H14<>"", "_" & H14, "_") & IF(I14<>"", "_" & I14, "_") & IF(B14<>"", "_" & B14, "") -> Caspar_etal_2022 | G14: =SUBSTITUTE(SUBSTITUTE(_xlfn.TEXTBEFORE(A14,","), "-", ""), " ", "") -> Caspar | H14: =IF(ISNUMBER(FIND("&", A14)), IF(LEN(A14)-LEN(SUBSTITUTE(A14, ",", ""))>=6, "etal", MID(A14, SEARCH("& ", A14)+2, SEARCH(",", A14, SEARCH("& ", A14)+2) - SEARCH("& ", A14)-2)), "" ) -> etal | I14: =_xlfn.TEXTBEFORE(_xlfn.TEXTAFTER(A14, "("), ")") -> 2022 | J14: =IF(C14<>"", C14, IF(C14="", _xlfn.TEXTAFTER(A14,"https://doi.org/"), C14)) -> 10.7554/eLife.77875 | K14: =TRIM(_xlfn.TEXTJOIN("_",FALSE,F14,(SUBSTITUTE(SUBSTITUTE(D14," ",""), "_", "")))) -> Caspar_etal_2022_Supplementaryfile3 | L14: =IF(ISBLANK(C14),TRIM(SUBSTITUTE(SUBSTITUTE(SUBSTITUTE(_xlfn.TEXTJOIN("_", FALSE, J14, SUBSTITUTE(D14,"_", "")), "/", "%2F"), ":", "%3A"), " ", "")),TRIM(SUBSTITUTE(SUBSTITUTE(SUBSTITUTE(_xlfn.TEXTJOIN("_", FALSE, C14, SUBSTITUTE(D14,"_", "")), "/", "%2F"), ":", "%3A"), " ", ""))) -> 10.7554%2FeLife.77875_Supplementaryfile3 | M14: {=IFERROR(INDEX(FileList!$A$1:$A$100, MATCH(L14, _xlfn.TEXTBEFORE(FileList!$A$1:$A$100, ".tsv"), 0)), "notfound")} -> 10.7554%2FeLife.77875_Supplementaryfile3.tsv | N14: part 2: ecological table | P14: FINISHED | Q14: added | R14: elife-77875-supp3-v1.xlsx | S14: N | T14: =IF(S14="N", R14, "write file name") -> elife-77875-supp3-v1.xlsx | U14: xlsx | V14: table | W14: YES - download link | X14: https://cdn.elifesciences.org/articles/77875/elife-77875-supp3-v1.xlsx | Y14: Habitual Tool Use, Ecology, Female brain size | Z14: secondary | AE14: primates
A15: Caspar, K. R., Pallasdies, F., Mader, L., Sartorelli, H., & Begall, S. (2022). The evolution and biological correlates of hand preferences in anthropoid primates. Elife, 11, e77875. https://doi.org/10.7554/eLife.77875 | D15: Table 1 | E15: =RIGHT(A15,1) -> 5 | F15: =G15 & IF(H15<>"", "_" & H15, "_") & IF(I15<>"", "_" & I15, "_") & IF(B15<>"", "_" & B15, "") -> Caspar_etal_2022 | G15: =SUBSTITUTE(SUBSTITUTE(_xlfn.TEXTBEFORE(A15,","), "-", ""), " ", "") -> Caspar | H15: =IF(ISNUMBER(FIND("&", A15)), IF(LEN(A15)-LEN(SUBSTITUTE(A15, ",", ""))>=6, "etal", MID(A15, SEARCH("& ", A15)+2, SEARCH(",", A15, SEARCH("& ", A15)+2) - SEARCH("& ", A15)-2)), "" ) -> etal | I15: =_xlfn.TEXTBEFORE(_xlfn.TEXTAFTER(A15, "("), ")") -> 2022 | J15: =IF(C15<>"", C15, IF(C15="", _xlfn.TEXTAFTER(A15,"https://doi.org/"), C15)) -> 10.7554/eLife.77875 | K15: =TRIM(_xlfn.TEXTJOIN("_",FALSE,F15,(SUBSTITUTE(SUBSTITUTE(D15," ",""), "_", "")))) -> Caspar_etal_2022_Table1 | L15: =IF(ISBLANK(C15),TRIM(SUBSTITUTE(SUBSTITUTE(SUBSTITUTE(_xlfn.TEXTJOIN("_", FALSE, J15, SUBSTITUTE(D15,"_", "")), "/", "%2F"), ":", "%3A"), " ", "")),TRIM(SUBSTITUTE(SUBSTITUTE(SUBSTITUTE(_xlfn.TEXTJOIN("_", FALSE, C15, SUBSTITUTE(D15,"_", "")), "/", "%2F"), ":", "%3A"), " ", ""))) -> 10.7554%2FeLife.77875_Table1 | M15: {=IFERROR(INDEX(FileList!$A$1:$A$100, MATCH(L15, _xlfn.TEXTBEFORE(FileList!$A$1:$A$100, ".tsv"), 0)), "notfound")} -> 10.7554%2FeLife.77875_Table1.tsv | N15: part 1: handedness summary table | P15: FINISHED | Q15: added | R15: Caspar_etal_2022_Table1_snapshot.xlsx | S15: Y | T15: Caspar_etal_2022_Table1.csv | U15: pdf | V15: table | W15: YES - but formatting issues | X15: https://elifesciences.org/download/aHR0cHM6Ly9jZG4uZWxpZmVzY2llbmNlcy5vcmcvYXJ0aWNsZXMvNzc4NzUvZWxpZmUtNzc4NzUtdjEucGRmP2Nhbm9uaWNhbFVyaT1odHRwczovL2VsaWZlc2NpZW5jZXMub3JnL2FydGljbGVzLzc3ODc1/elife-77875-v1.pdf?_hash=NStjcL9fTlmy3AQDwSiM0YgMVB3UYjO8nDg0UbwN5gM%3D | Y15: Handedness derived data | Z15: derived from primary | AD15: perhaps useful to get raw data as well? | AE15: primates
A16: Changizi, M. A. (2001). Principles underlying mammalian neocortical scaling. Biol Cybern, 84(3), 207-215. https://doi.org/10.1007/s004220000205 | D16: Figure 3 | E16: =RIGHT(A16,1) -> 5 | F16: =G16 & IF(H16<>"", "_" & H16, "_") & IF(I16<>"", "_" & I16, "_") & IF(B16<>"", "_" & B16, "") -> Changizi__2001 | G16: =SUBSTITUTE(SUBSTITUTE(_xlfn.TEXTBEFORE(A16,","), "-", ""), " ", "") -> Changizi | H16: =IF(ISNUMBER(FIND("&", A16)), IF(LEN(A16)-LEN(SUBSTITUTE(A16, ",", ""))>=6, "etal", MID(A16, SEARCH("& ", A16)+2, SEARCH(",", A16, SEARCH("& ", A16)+2) - SEARCH("& ", A16)-2)), "" ) | I16: =_xlfn.TEXTBEFORE(_xlfn.TEXTAFTER(A16, "("), ")") -> 2001 | J16: =IF(C16<>"", C16, IF(C16="", _xlfn.TEXTAFTER(A16,"https://doi.org/"), C16)) -> 10.1007/s004220000205 | K16: =TRIM(_xlfn.TEXTJOIN("_",FALSE,F16,(SUBSTITUTE(SUBSTITUTE(D16," ",""), "_", "")))) -> Changizi__2001_Figure3 | L16: =IF(ISBLANK(C16),TRIM(SUBSTITUTE(SUBSTITUTE(SUBSTITUTE(_xlfn.TEXTJOIN("_", FALSE, J16, SUBSTITUTE(D16,"_", "")), "/", "%2F"), ":", "%3A"), " ", "")),TRIM(SUBSTITUTE(SUBSTITUTE(SUBSTITUTE(_xlfn.TEXTJOIN("_", FALSE, C16, SUBSTITUTE(D16,"_", "")), "/", "%2F"), ":", "%3A"), " ", ""))) -> 10.1007%2Fs004220000205_Figure3 | M16: {=IFERROR(INDEX(FileList!$A$1:$A$100, MATCH(L16, _xlfn.TEXTBEFORE(FileList!$A$1:$A$100, ".tsv"), 0)), "notfound")} -> 10.1007%2Fs004220000205_Figure3.tsv | P16: Species -- wait for Project Kaskan | Q16: NA | R16: Changizi__2001_Figure3_snapshot.csv | S16: Y | T16: Changizi__2001_Figure3.csv | U16: pdf | V16: figure and caption | W16: NO - paywall | Y16: number of cortical areas | Z16: primary (derived from published materials) | AD16: summary to check more precise areas from ProjectKaskan
A17: Chen, Z., & Wiens, J. J. (2020). The origins of acoustic communication in vertebrates. Nature Communications, 11(1), 369. https://doi.org/10.1038/s41467-020-14356-3 | D17: Supplementary Data 3 | E17: =RIGHT(A17,1) -> 3 | F17: =G17 & IF(H17<>"", "_" & H17, "_") & IF(I17<>"", "_" & I17, "_") & IF(B17<>"", "_" & B17, "") -> Chen_Wiens_2020 | G17: =SUBSTITUTE(SUBSTITUTE(_xlfn.TEXTBEFORE(A17,","), "-", ""), " ", "") -> Chen | H17: =IF(ISNUMBER(FIND("&", A17)), IF(LEN(A17)-LEN(SUBSTITUTE(A17, ",", ""))>=6, "etal", MID(A17, SEARCH("& ", A17)+2, SEARCH(",", A17, SEARCH("& ", A17)+2) - SEARCH("& ", A17)-2)), "" ) -> Wiens | I17: =_xlfn.TEXTBEFORE(_xlfn.TEXTAFTER(A17, "("), ")") -> 2020 | J17: =IF(C17<>"", C17, IF(C17="", _xlfn.TEXTAFTER(A17,"https://doi.org/"), C17)) -> 10.1038/s41467-020-14356-3 | K17: =TRIM(_xlfn.TEXTJOIN("_",FALSE,F17,(SUBSTITUTE(SUBSTITUTE(D17," ",""), "_", "")))) -> Chen_Wiens_2020_SupplementaryData3 | L17: =IF(ISBLANK(C17),TRIM(SUBSTITUTE(SUBSTITUTE(SUBSTITUTE(_xlfn.TEXTJOIN("_", FALSE, J17, SUBSTITUTE(D17,"_", "")), "/", "%2F"), ":", "%3A"), " ", "")),TRIM(SUBSTITUTE(SUBSTITUTE(SUBSTITUTE(_xlfn.TEXTJOIN("_", FALSE, C17, SUBSTITUTE(D17,"_", "")), "/", "%2F"), ":", "%3A"), " ", ""))) -> 10.1038%2Fs41467-020-14356-3_SupplementaryData3 | M17: {=IFERROR(INDEX(FileList!$A$1:$A$100, MATCH(L17, _xlfn.TEXTBEFORE(FileList!$A$1:$A$100, ".tsv"), 0)), "notfound")} -> 10.1038%2Fs41467-020-14356-3_SupplementaryData3.tsv | P17: FINISHED | Q17: added | R17: 41467_2020_14356_MOESM6_ESM.xlsx | S17: N | T17: =IF(S17="N", R17, "write file name") -> 41467_2020_14356_MOESM6_ESM.xlsx | U17: xlsx | V17: table | W17: YES - download link | X17: https://static-content.springer.com/esm/art%3A10.1038%2Fs41467-020-14356-3/MediaObjects/41467_2020_14356_MOESM6_ESM.xlsx | Y17: acoustic communication | Z17: secondary | AC17: dial activity (Supp 4) | AD17: maybe delete: not relevent in current dataset, unless for imputations? | AE17: vertebrates
A18: Collins, C. E., Airey, D. C., Young, N. A., Leitch, D. B., & Kaas, J. H. (2010). Neuron densities vary across and within cortical areas in primates. Proc Natl Acad Sci U S A, 107(36), 15927-15932. https://doi.org/10.1073/pnas.1010356107 | D18: Dataset S1 | E18: =RIGHT(A18,1) -> 7 | F18: =G18 & IF(H18<>"", "_" & H18, "_") & IF(I18<>"", "_" & I18, "_") & IF(B18<>"", "_" & B18, "") -> Collins_etal_2010 | G18: =SUBSTITUTE(SUBSTITUTE(_xlfn.TEXTBEFORE(A18,","), "-", ""), " ", "") -> Collins | H18: =IF(ISNUMBER(FIND("&", A18)), IF(LEN(A18)-LEN(SUBSTITUTE(A18, ",", ""))>=6, "etal", MID(A18, SEARCH("& ", A18)+2, SEARCH(",", A18, SEARCH("& ", A18)+2) - SEARCH("& ", A18)-2)), "" ) -> etal | I18: =_xlfn.TEXTBEFORE(_xlfn.TEXTAFTER(A18, "("), ")") -> 2010 | J18: =IF(C18<>"", C18, IF(C18="", _xlfn.TEXTAFTER(A18,"https://doi.org/"), C18)) -> 10.1073/pnas.1010356107 | K18: =TRIM(_xlfn.TEXTJOIN("_",FALSE,F18,(SUBSTITUTE(SUBSTITUTE(D18," ",""), "_", "")))) -> Collins_etal_2010_DatasetS1 | L18: =IF(ISBLANK(C18),TRIM(SUBSTITUTE(SUBSTITUTE(SUBSTITUTE(_xlfn.TEXTJOIN("_", FALSE, J18, SUBSTITUTE(D18,"_", "")), "/", "%2F"), ":", "%3A"), " ", "")),TRIM(SUBSTITUTE(SUBSTITUTE(SUBSTITUTE(_xlfn.TEXTJOIN("_", FALSE, C18, SUBSTITUTE(D18,"_", "")), "/", "%2F"), ":", "%3A"), " ", ""))) -> 10.1073%2Fpnas.1010356107_DatasetS1 | M18: {=IFERROR(INDEX(FileList!$A$1:$A$100, MATCH(L18, _xlfn.TEXTBEFORE(FileList!$A$1:$A$100, ".tsv"), 0)), "notfound")} -> notfound | Y18: cortical area surface area, neuron density | Z18: primary
A19: Collins, C. E., Turner, E. C., Sawyer, E. K., Reed, J. L., Young, N. A., Flaherty, D. K., & Kaas, J. H. (2016). Cortical cell and neuron density estimates in one chimpanzee hemisphere. Proc Natl Acad Sci U S A, 113(3), 740-745. https://doi.org/10.1073/pnas.1524208113 | D19: Table1 | E19: =RIGHT(A19,1) -> 3 | F19: =G19 & IF(H19<>"", "_" & H19, "_") & IF(I19<>"", "_" & I19, "_") & IF(B19<>"", "_" & B19, "") -> Collins_etal_2016 | G19: =SUBSTITUTE(SUBSTITUTE(_xlfn.TEXTBEFORE(A19,","), "-", ""), " ", "") -> Collins | H19: =IF(ISNUMBER(FIND("&", A19)), IF(LEN(A19)-LEN(SUBSTITUTE(A19, ",", ""))>=6, "etal", MID(A19, SEARCH("& ", A19)+2, SEARCH(",", A19, SEARCH("& ", A19)+2) - SEARCH("& ", A19)-2)), "" ) -> etal | I19: =_xlfn.TEXTBEFORE(_xlfn.TEXTAFTER(A19, "("), ")") -> 2016 | J19: =IF(C19<>"", C19, IF(C19="", _xlfn.TEXTAFTER(A19,"https://doi.org/"), C19)) -> 10.1073/pnas.1524208113 | K19: =TRIM(_xlfn.TEXTJOIN("_",FALSE,F19,(SUBSTITUTE(SUBSTITUTE(D19," ",""), "_", "")))) -> Collins_etal_2016_Table1 | L19: =IF(ISBLANK(C19),TRIM(SUBSTITUTE(SUBSTITUTE(SUBSTITUTE(_xlfn.TEXTJOIN("_", FALSE, J19, SUBSTITUTE(D19,"_", "")), "/", "%2F"), ":", "%3A"), " ", "")),TRIM(SUBSTITUTE(SUBSTITUTE(SUBSTITUTE(_xlfn.TEXTJOIN("_", FALSE, C19, SUBSTITUTE(D19,"_", "")), "/", "%2F"), ":", "%3A"), " ", ""))) -> 10.1073%2Fpnas.1524208113_Table1 | M19: {=IFERROR(INDEX(FileList!$A$1:$A$100, MATCH(L19, _xlfn.TEXTBEFORE(FileList!$A$1:$A$100, ".tsv"), 0)), "notfound")} -> notfound | N19: Cortical cell and neuron density in one chimpanzee hemisphere (Table 1) | V19: table | Y19: cortical neuron/cell density | Z19: primary | AA19: Kaas | AB19: isotropic fractionator
A20: de Sousa, A. A., Sherwood, C. C., Hof, P. R., & Zilles, K. (2013). Lamination of the lateral geniculate nucleus of catarrhine primates. Brain Behav Evol, 81(2), 93-108. https://doi.org/10.1159/000346495 | D20: Table1 | E20: =RIGHT(A20,1) -> 5 | F20: =G20 & IF(H20<>"", "_" & H20, "_") & IF(I20<>"", "_" & I20, "_") & IF(B20<>"", "_" & B20, "") -> deSousa_etal_2013 | G20: =SUBSTITUTE(SUBSTITUTE(_xlfn.TEXTBEFORE(A20,","), "-", ""), " ", "") -> deSousa | H20: =IF(ISNUMBER(FIND("&", A20)), IF(LEN(A20)-LEN(SUBSTITUTE(A20, ",", ""))>=6, "etal", MID(A20, SEARCH("& ", A20)+2, SEARCH(",", A20, SEARCH("& ", A20)+2) - SEARCH("& ", A20)-2)), "" ) -> etal | I20: =_xlfn.TEXTBEFORE(_xlfn.TEXTAFTER(A20, "("), ")") -> 2013 | J20: =IF(C20<>"", C20, IF(C20="", _xlfn.TEXTAFTER(A20,"https://doi.org/"), C20)) -> 10.1159/000346495 | K20: =TRIM(_xlfn.TEXTJOIN("_",FALSE,F20,(SUBSTITUTE(SUBSTITUTE(D20," ",""), "_", "")))) -> deSousa_etal_2013_Table1 | L20: =IF(ISBLANK(C20),TRIM(SUBSTITUTE(SUBSTITUTE(SUBSTITUTE(_xlfn.TEXTJOIN("_", FALSE, J20, SUBSTITUTE(D20,"_", "")), "/", "%2F"), ":", "%3A"), " ", "")),TRIM(SUBSTITUTE(SUBSTITUTE(SUBSTITUTE(_xlfn.TEXTJOIN("_", FALSE, C20, SUBSTITUTE(D20,"_", "")), "/", "%2F"), ":", "%3A"), " ", ""))) -> 10.1159%2F000346495_Table1 | M20: {=IFERROR(INDEX(FileList!$A$1:$A$100, MATCH(L20, _xlfn.TEXTBEFORE(FileList!$A$1:$A$100, ".tsv"), 0)), "notfound")} -> notfound | N20: Lamination of the LGN of catarrhine primates (Table 1) | V20: table | Y20: LGN lamination volumes | Z20: primary | AA20: Stephan | AB20: volumetry
A21: de Sousa, A. A., Sherwood, C. C., Mohlberg, H., Amunts, K., Schleicher, A., MacLeod, C. E., Hof, P. R., Frahm, H., & Zilles, K. (2010). Hominoid visual brain structure volumes and the position of the lunate sulcus. J Hum Evol, 58(4), 281-292. https://doi.org/10.1016/j.jhevol.2009.11.011 | D21: Table1 | E21: =RIGHT(A21,1) -> 1 | F21: =G21 & IF(H21<>"", "_" & H21, "_") & IF(I21<>"", "_" & I21, "_") & IF(B21<>"", "_" & B21, "") -> deSousa_etal_2010 | G21: =SUBSTITUTE(SUBSTITUTE(_xlfn.TEXTBEFORE(A21,","), "-", ""), " ", "") -> deSousa | H21: =IF(ISNUMBER(FIND("&", A21)), IF(LEN(A21)-LEN(SUBSTITUTE(A21, ",", ""))>=6, "etal", MID(A21, SEARCH("& ", A21)+2, SEARCH(",", A21, SEARCH("& ", A21)+2) - SEARCH("& ", A21)-2)), "" ) -> etal | I21: =_xlfn.TEXTBEFORE(_xlfn.TEXTAFTER(A21, "("), ")") -> 2010 | J21: =IF(C21<>"", C21, IF(C21="", _xlfn.TEXTAFTER(A21,"https://doi.org/"), C21)) -> 10.1016/j.jhevol.2009.11.011 | K21: =TRIM(_xlfn.TEXTJOIN("_",FALSE,F21,(SUBSTITUTE(SUBSTITUTE(D21," ",""), "_", "")))) -> deSousa_etal_2010_Table1 | L21: =IF(ISBLANK(C21),TRIM(SUBSTITUTE(SUBSTITUTE(SUBSTITUTE(_xlfn.TEXTJOIN("_", FALSE, J21, SUBSTITUTE(D21,"_", "")), "/", "%2F"), ":", "%3A"), " ", "")),TRIM(SUBSTITUTE(SUBSTITUTE(SUBSTITUTE(_xlfn.TEXTJOIN("_", FALSE, C21, SUBSTITUTE(D21,"_", "")), "/", "%2F"), ":", "%3A"), " ", ""))) -> 10.1016%2Fj.jhevol.2009.11.011_Table1 | M21: {=IFERROR(INDEX(FileList!$A$1:$A$100, MATCH(L21, _xlfn.TEXTBEFORE(FileList!$A$1:$A$100, ".tsv"), 0)), "notfound")} -> notfound | N21: Hominoid visual brain structure volumes (Table 1) | V21: table | Y21: visual brain structure volumes | Z21: primary | AA21: Stephan | AB21: volumetry
A22: DeCasien, A. R., & Higham, J. P. (2019). Primate mosaic brain evolution reflects selection on sensory and cognitive specialization. Nat Ecol Evol, 3(10), 1483-1493. https://doi.org/10.1038/s41559-019-0969-0 | D22: Supplementary Data 1-Brain Region | E22: =RIGHT(A22,1) -> 0 | F22: =G22 & IF(H22<>"", "_" & H22, "_") & IF(I22<>"", "_" & I22, "_") & IF(B22<>"", "_" & B22, "") -> DeCasien_Higham_2019 | G22: =SUBSTITUTE(SUBSTITUTE(_xlfn.TEXTBEFORE(A22,","), "-", ""), " ", "") -> DeCasien | H22: =IF(ISNUMBER(FIND("&", A22)), IF(LEN(A22)-LEN(SUBSTITUTE(A22, ",", ""))>=6, "etal", MID(A22, SEARCH("& ", A22)+2, SEARCH(",", A22, SEARCH("& ", A22)+2) - SEARCH("& ", A22)-2)), "" ) -> Higham | I22: =_xlfn.TEXTBEFORE(_xlfn.TEXTAFTER(A22, "("), ")") -> 2019 | J22: =IF(C22<>"", C22, IF(C22="", _xlfn.TEXTAFTER(A22,"https://doi.org/"), C22)) -> 10.1038/s41559-019-0969-0 | K22: =TRIM(_xlfn.TEXTJOIN("_",FALSE,F22,(SUBSTITUTE(SUBSTITUTE(D22," ",""), "_", "")))) -> DeCasien_Higham_2019_SupplementaryData1-BrainRegion | L22: =IF(ISBLANK(C22),TRIM(SUBSTITUTE(SUBSTITUTE(SUBSTITUTE(_xlfn.TEXTJOIN("_", FALSE, J22, SUBSTITUTE(D22,"_", "")), "/", "%2F"), ":", "%3A"), " ", "")),TRIM(SUBSTITUTE(SUBSTITUTE(SUBSTITUTE(_xlfn.TEXTJOIN("_", FALSE, C22, SUBSTITUTE(D22,"_", "")), "/", "%2F"), ":", "%3A"), " ", ""))) -> 10.1038%2Fs41559-019-0969-0_SupplementaryData1-BrainRegion | M22: {=IFERROR(INDEX(FileList!$A$1:$A$100, MATCH(L22, _xlfn.TEXTBEFORE(FileList!$A$1:$A$100, ".tsv"), 0)), "notfound")} -> notfound | N22: Supplementary Data 1 Brain Region Data (mm3) | U22: xlsx | V22: table Sheet 1 | W22: YES - download link | X22: https://www.nature.com/articles/s41559-019-0969-0#Sec13 | Y22: Brain Regions Volumes | Z22: secondary | AD22: mostly Stephan and other Ddorf studies | AE22: primates
A23: DeCasien, A. R., & Higham, J. P. (2019). Primate mosaic brain evolution reflects selection on sensory and cognitive specialization. Nat Ecol Evol, 3(10), 1483-1493. https://doi.org/10.1038/s41559-019-0969-0 | D23: Supplementary Data 1-Activity Period | E23: =RIGHT(A23,1) -> 0 | F23: =G23 & IF(H23<>"", "_" & H23, "_") & IF(I23<>"", "_" & I23, "_") & IF(B23<>"", "_" & B23, "") -> DeCasien_Higham_2019 | G23: =SUBSTITUTE(SUBSTITUTE(_xlfn.TEXTBEFORE(A23,","), "-", ""), " ", "") -> DeCasien | H23: =IF(ISNUMBER(FIND("&", A23)), IF(LEN(A23)-LEN(SUBSTITUTE(A23, ",", ""))>=6, "etal", MID(A23, SEARCH("& ", A23)+2, SEARCH(",", A23, SEARCH("& ", A23)+2) - SEARCH("& ", A23)-2)), "" ) -> Higham | I23: =_xlfn.TEXTBEFORE(_xlfn.TEXTAFTER(A23, "("), ")") -> 2019 | J23: =IF(C23<>"", C23, IF(C23="", _xlfn.TEXTAFTER(A23,"https://doi.org/"), C23)) -> 10.1038/s41559-019-0969-0 | K23: =TRIM(_xlfn.TEXTJOIN("_",FALSE,F23,(SUBSTITUTE(SUBSTITUTE(D24," ",""), "_", "")))) -> DeCasien_Higham_2019_SupplementaryData1-Diet | L23: =IF(ISBLANK(C23),TRIM(SUBSTITUTE(SUBSTITUTE(SUBSTITUTE(_xlfn.TEXTJOIN("_", FALSE, J23, SUBSTITUTE(D24,"_", "")), "/", "%2F"), ":", "%3A"), " ", "")),TRIM(SUBSTITUTE(SUBSTITUTE(SUBSTITUTE(_xlfn.TEXTJOIN("_", FALSE, C23, SUBSTITUTE(D24,"_", "")), "/", "%2F"), ":", "%3A"), " ", ""))) -> 10.1038%2Fs41559-019-0969-0_SupplementaryData1-Diet | M23: {=IFERROR(INDEX(FileList!$A$1:$A$100, MATCH(L23, _xlfn.TEXTBEFORE(FileList!$A$1:$A$100, ".tsv"), 0)), "notfound")} -> notfound | N23: Supplementary Data 1 Brain Region Data (mm3) | U23: xlsx | V23: table Sheet 1 | W23: YES - download link | X23: https://www.nature.com/articles/s41559-019-0969-0#Sec13 | Y23: Activity Period | Z23: secondary | AE23: primates
A24: DeCasien, A. R., & Higham, J. P. (2019). Primate mosaic brain evolution reflects selection on sensory and cognitive specialization. Nat Ecol Evol, 3(10), 1483-1493. https://doi.org/10.1038/s41559-019-0969-0 | D24: Supplementary Data 1-Diet | E24: =RIGHT(A24,1) -> 0 | F24: =G24 & IF(H24<>"", "_" & H24, "_") & IF(I24<>"", "_" & I24, "_") & IF(B24<>"", "_" & B24, "") -> DeCasien_Higham_2019 | G24: =SUBSTITUTE(SUBSTITUTE(_xlfn.TEXTBEFORE(A24,","), "-", ""), " ", "") -> DeCasien | H24: =IF(ISNUMBER(FIND("&", A24)), IF(LEN(A24)-LEN(SUBSTITUTE(A24, ",", ""))>=6, "etal", MID(A24, SEARCH("& ", A24)+2, SEARCH(",", A24, SEARCH("& ", A24)+2) - SEARCH("& ", A24)-2)), "" ) -> Higham | I24: =_xlfn.TEXTBEFORE(_xlfn.TEXTAFTER(A24, "("), ")") -> 2019 | J24: =IF(C24<>"", C24, IF(C24="", _xlfn.TEXTAFTER(A24,"https://doi.org/"), C24)) -> 10.1038/s41559-019-0969-0 | K24: =TRIM(_xlfn.TEXTJOIN("_",FALSE,F24,(SUBSTITUTE(SUBSTITUTE(D25," ",""), "_", "")))) -> DeCasien_Higham_2019_SupplementaryData1-SocialSystem | L24: =IF(ISBLANK(C24),TRIM(SUBSTITUTE(SUBSTITUTE(SUBSTITUTE(_xlfn.TEXTJOIN("_", FALSE, J24, SUBSTITUTE(D25,"_", "")), "/", "%2F"), ":", "%3A"), " ", "")),TRIM(SUBSTITUTE(SUBSTITUTE(SUBSTITUTE(_xlfn.TEXTJOIN("_", FALSE, C24, SUBSTITUTE(D25,"_", "")), "/", "%2F"), ":", "%3A"), " ", ""))) -> 10.1038%2Fs41559-019-0969-0_SupplementaryData1-SocialSystem | M24: {=IFERROR(INDEX(FileList!$A$1:$A$100, MATCH(L24, _xlfn.TEXTBEFORE(FileList!$A$1:$A$100, ".tsv"), 0)), "notfound")} -> notfound | N24: Supplementary Data 1 Brain Region Data (mm3) | U24: xlsx | V24: table Sheet 1 | W24: YES - download link | X24: https://www.nature.com/articles/s41559-019-0969-0#Sec13 | Y24: Diet | Z24: secondary | AE24: primates
A25: DeCasien, A. R., & Higham, J. P. (2019). Primate mosaic brain evolution reflects selection on sensory and cognitive specialization. Nat Ecol Evol, 3(10), 1483-1493. https://doi.org/10.1038/s41559-019-0969-0 | D25: Supplementary Data 1-Social System | E25: =RIGHT(A25,1) -> 0 | F25: =G25 & IF(H25<>"", "_" & H25, "_") & IF(I25<>"", "_" & I25, "_") & IF(B25<>"", "_" & B25, "") -> DeCasien_Higham_2019 | G25: =SUBSTITUTE(SUBSTITUTE(_xlfn.TEXTBEFORE(A25,","), "-", ""), " ", "") -> DeCasien | H25: =IF(ISNUMBER(FIND("&", A25)), IF(LEN(A25)-LEN(SUBSTITUTE(A25, ",", ""))>=6, "etal", MID(A25, SEARCH("& ", A25)+2, SEARCH(",", A25, SEARCH("& ", A25)+2) - SEARCH("& ", A25)-2)), "" ) -> Higham | I25: =_xlfn.TEXTBEFORE(_xlfn.TEXTAFTER(A25, "("), ")") -> 2019 | J25: =IF(C25<>"", C25, IF(C25="", _xlfn.TEXTAFTER(A25,"https://doi.org/"), C25)) -> 10.1038/s41559-019-0969-0 | K25: =TRIM(_xlfn.TEXTJOIN("_",FALSE,F25,(SUBSTITUTE(SUBSTITUTE(D25," ",""), "_", "")))) -> DeCasien_Higham_2019_SupplementaryData1-SocialSystem | L25: =IF(ISBLANK(C25),TRIM(SUBSTITUTE(SUBSTITUTE(SUBSTITUTE(_xlfn.TEXTJOIN("_", FALSE, J25, SUBSTITUTE(D25,"_", "")), "/", "%2F"), ":", "%3A"), " ", "")),TRIM(SUBSTITUTE(SUBSTITUTE(SUBSTITUTE(_xlfn.TEXTJOIN("_", FALSE, C25, SUBSTITUTE(D25,"_", "")), "/", "%2F"), ":", "%3A"), " ", ""))) -> 10.1038%2Fs41559-019-0969-0_SupplementaryData1-SocialSystem | M25: {=IFERROR(INDEX(FileList!$A$1:$A$100, MATCH(L25, _xlfn.TEXTBEFORE(FileList!$A$1:$A$100, ".tsv"), 0)), "notfound")} -> notfound | N25: Supplementary Data 1 Brain Region Data (mm3) | U25: xlsx | V25: table Sheet 1 | W25: YES - download link | X25: https://www.nature.com/articles/s41559-019-0969-0#Sec13 | Y25: Social System | Z25: secondary | AE25: primates
A26: Dos Santos, S. E., Medeiros, M., Porfirio, J., Tavares, W., Pessoa, L., Grinberg, L., Leite, R. E. P., Ferretti-Rebustini, R. E. L., Suemoto, C. K., Filho, W. J., Noctor, S. C., Sherwood, C. C., Kaas, J. H., Manger, P. R., & Herculano-Houzel, S. (2020). Similar Microglial Cell Densities across Brain Structures and Mammalian Species: Implications for Brain Tissue Function. J Neurosci, 40(24), 4622-4643. https://doi.org/10.1523/JNEUROSCI.2339-19.2020 | D26: Table 1 | E26: =RIGHT(A26,1) -> 0 | F26: =G26 & IF(H26<>"", "_" & H26, "_") & IF(I26<>"", "_" & I26, "_") & IF(B26<>"", "_" & B26, "") -> DosSantos_etal_2020 | G26: =SUBSTITUTE(SUBSTITUTE(_xlfn.TEXTBEFORE(A26,","), "-", ""), " ", "") -> DosSantos | H26: =IF(ISNUMBER(FIND("&", A26)), IF(LEN(A26)-LEN(SUBSTITUTE(A26, ",", ""))>=6, "etal", MID(A26, SEARCH("& ", A26)+2, SEARCH(",", A26, SEARCH("& ", A26)+2) - SEARCH("& ", A26)-2)), "" ) -> etal | I26: =_xlfn.TEXTBEFORE(_xlfn.TEXTAFTER(A26, "("), ")") -> 2020 | J26: =IF(C26<>"", C26, IF(C26="", _xlfn.TEXTAFTER(A26,"https://doi.org/"), C26)) -> 10.1523/JNEUROSCI.2339-19.2020 | K26: =TRIM(_xlfn.TEXTJOIN("_",FALSE,F26,(SUBSTITUTE(SUBSTITUTE(D26," ",""), "_", "")))) -> DosSantos_etal_2020_Table1 | L26: =IF(ISBLANK(C26),TRIM(SUBSTITUTE(SUBSTITUTE(SUBSTITUTE(_xlfn.TEXTJOIN("_", FALSE, J26, SUBSTITUTE(D26,"_", "")), "/", "%2F"), ":", "%3A"), " ", "")),TRIM(SUBSTITUTE(SUBSTITUTE(SUBSTITUTE(_xlfn.TEXTJOIN("_", FALSE, C26, SUBSTITUTE(D26,"_", "")), "/", "%2F"), ":", "%3A"), " ", ""))) -> 10.1523%2FJNEUROSCI.2339-19.2020_Table1 | M26: {=IFERROR(INDEX(FileList!$A$1:$A$100, MATCH(L26, _xlfn.TEXTBEFORE(FileList!$A$1:$A$100, ".tsv"), 0)), "notfound")} -> 10.1523%2FJNEUROSCI.2339-19.2020_Table1.tsv | P26: FINISHED | Q26: added | R26: DosSantos_etal_2020_Table1_snapshot.csv | S26: Y | T26: DosSantos_etal_2020_Table1.csv | U26: pdf online | V26: table | Y26: Cell numbers, region size | Z26: primary; secondary (compiled team data) | AA26: HH | AB26: HH | AE26: microglia
A27: Dos Santos, S. E., Medeiros, M., Porfirio, J., Tavares, W., Pessoa, L., Grinberg, L., Leite, R. E. P., Ferretti-Rebustini, R. E. L., Suemoto, C. K., Filho, W. J., Noctor, S. C., Sherwood, C. C., Kaas, J. H., Manger, P. R., & Herculano-Houzel, S. (2020). Similar Microglial Cell Densities across Brain Structures and Mammalian Species: Implications for Brain Tissue Function. J Neurosci, 40(24), 4622-4643. https://doi.org/10.1523/JNEUROSCI.2339-19.2020 | D27: unpublished | E27: =RIGHT(A27,1) -> 0 | F27: =G27 & IF(H27<>"", "_" & H27, "_") & IF(I27<>"", "_" & I27, "_") & IF(B27<>"", "_" & B27, "") -> DosSantos_etal_2020 | G27: =SUBSTITUTE(SUBSTITUTE(_xlfn.TEXTBEFORE(A27,","), "-", ""), " ", "") -> DosSantos | H27: =IF(ISNUMBER(FIND("&", A27)), IF(LEN(A27)-LEN(SUBSTITUTE(A27, ",", ""))>=6, "etal", MID(A27, SEARCH("& ", A27)+2, SEARCH(",", A27, SEARCH("& ", A27)+2) - SEARCH("& ", A27)-2)), "" ) -> etal | I27: =_xlfn.TEXTBEFORE(_xlfn.TEXTAFTER(A27, "("), ")") -> 2020 | J27: =IF(C27<>"", C27, IF(C27="", _xlfn.TEXTAFTER(A27,"https://doi.org/"), C27)) -> 10.1523/JNEUROSCI.2339-19.2020 | K27: =TRIM(_xlfn.TEXTJOIN("_",FALSE,F27,(SUBSTITUTE(SUBSTITUTE(D27," ",""), "_", "")))) -> DosSantos_etal_2020_unpublished | L27: =IF(ISBLANK(C27),TRIM(SUBSTITUTE(SUBSTITUTE(SUBSTITUTE(_xlfn.TEXTJOIN("_", FALSE, J27, SUBSTITUTE(D27,"_", "")), "/", "%2F"), ":", "%3A"), " ", "")),TRIM(SUBSTITUTE(SUBSTITUTE(SUBSTITUTE(_xlfn.TEXTJOIN("_", FALSE, C27, SUBSTITUTE(D27,"_", "")), "/", "%2F"), ":", "%3A"), " ", ""))) -> 10.1523%2FJNEUROSCI.2339-19.2020_unpublished | M27: {=IFERROR(INDEX(FileList!$A$1:$A$100, MATCH(L27, _xlfn.TEXTBEFORE(FileList!$A$1:$A$100, ".tsv"), 0)), "notfound")} -> 10.1523%2FJNEUROSCI.2339-19.2020_unpublished.tsv | P27: FINISHED | Q27: added | R27: DosSantos_etal_2020_Table1_snapshot.csv | S27: Y | T27: DosSantos_etal_2020_Table1.csv | U27: pdf online | V27: table | X27: https://doi.org/10.1523/JNEUROSCI.2339-19.2020 | Y27: Cell numbers, region size | Z27: primary; secondary (compiled team data) | AA27: HH | AB27: HH | AE27: microglia
A28: Dos Santos, S. E., Porfirio, J., da Cunha, F. B., Manger, P. R., Tavares, W., Pessoa, L., Raghanti, M. A., Sherwood, C. C., & Herculano-Houzel, S. (2017). Cellular Scaling Rules for the Brains of Marsupials: Not as "Primitive" as Expected. Brain Behav Evol. https://doi.org/10.1159/000452856 | D28: Table S1 | E28: =RIGHT(A28,1) -> 6 | F28: =G28 & IF(H28<>"", "_" & H28, "_") & IF(I28<>"", "_" & I28, "_") & IF(B28<>"", "_" & B28, "") -> DosSantos_etal_2017 | G28: =SUBSTITUTE(SUBSTITUTE(_xlfn.TEXTBEFORE(A28,","), "-", ""), " ", "") -> DosSantos | H28: =IF(ISNUMBER(FIND("&", A28)), IF(LEN(A28)-LEN(SUBSTITUTE(A28, ",", ""))>=6, "etal", MID(A28, SEARCH("& ", A28)+2, SEARCH(",", A28, SEARCH("& ", A28)+2) - SEARCH("& ", A28)-2)), "" ) -> etal | I28: =_xlfn.TEXTBEFORE(_xlfn.TEXTAFTER(A28, "("), ")") -> 2017 | J28: =IF(C28<>"", C28, IF(C28="", _xlfn.TEXTAFTER(A28,"https://doi.org/"), C28)) -> 10.1159/000452856 | K28: =TRIM(_xlfn.TEXTJOIN("_",FALSE,F28,(SUBSTITUTE(SUBSTITUTE(D28," ",""), "_", "")))) -> DosSantos_etal_2017_TableS1 | L28: =IF(ISBLANK(C28),TRIM(SUBSTITUTE(SUBSTITUTE(SUBSTITUTE(_xlfn.TEXTJOIN("_", FALSE, J28, SUBSTITUTE(D28,"_", "")), "/", "%2F"), ":", "%3A"), " ", "")),TRIM(SUBSTITUTE(SUBSTITUTE(SUBSTITUTE(_xlfn.TEXTJOIN("_", FALSE, C28, SUBSTITUTE(D28,"_", "")), "/", "%2F"), ":", "%3A"), " ", ""))) -> 10.1159%2F000452856_TableS1 | M28: {=IFERROR(INDEX(FileList!$A$1:$A$100, MATCH(L28, _xlfn.TEXTBEFORE(FileList!$A$1:$A$100, ".tsv"), 0)), "notfound")} -> 10.1159%2F000452856_TableS1.tsv | O28: ERRATUM ! | P28: FINISHED | Q28: added | R28: DosSantos_etal_2017_TableS1_snapshot.csv | S28: Y | T28: DosSantos_etal_2017_TableS1.csv | U28: doc, erratum (on pdf) | V28: table, erratum | W28: YES - download link | X28: https://ndownloader.figstatic.com/files/7428211 | Y28: Cell numbers, region size | Z28: primary | AA28: HH | AB28: HH | AE28: marsupials | AF28: erratum
A29: Eagleman, D. M., & Vaughn, D. A. (2021). The Defensive Activation Theory: REM Sleep as a Mechanism to Prevent Takeover of the Visual Cortex [Hypothesis and Theory]. Front Neurosci, 15(598), 632853. https://doi.org/10.3389/fnins.2021.632853 | D29: TABLE 1 | E29: =RIGHT(A29,1) -> 3 | F29: =G29 & IF(H29<>"", "_" & H29, "_") & IF(I29<>"", "_" & I29, "_") & IF(B29<>"", "_" & B29, "") -> Eagleman_Vaughn_2021 | G29: =SUBSTITUTE(SUBSTITUTE(_xlfn.TEXTBEFORE(A29,","), "-", ""), " ", "") -> Eagleman | H29: =IF(ISNUMBER(FIND("&", A29)), IF(LEN(A29)-LEN(SUBSTITUTE(A29, ",", ""))>=6, "etal", MID(A29, SEARCH("& ", A29)+2, SEARCH(",", A29, SEARCH("& ", A29)+2) - SEARCH("& ", A29)-2)), "" ) -> Vaughn | I29: =_xlfn.TEXTBEFORE(_xlfn.TEXTAFTER(A29, "("), ")") -> 2021 | J29: =IF(C29<>"", C29, IF(C29="", _xlfn.TEXTAFTER(A29,"https://doi.org/"), C29)) -> 10.3389/fnins.2021.632853 | K29: =TRIM(_xlfn.TEXTJOIN("_",FALSE,F29,(SUBSTITUTE(SUBSTITUTE(D29," ",""), "_", "")))) -> Eagleman_Vaughn_2021_TABLE1 | L29: =IF(ISBLANK(C29),TRIM(SUBSTITUTE(SUBSTITUTE(SUBSTITUTE(_xlfn.TEXTJOIN("_", FALSE, J29, SUBSTITUTE(D29,"_", "")), "/", "%2F"), ":", "%3A"), " ", "")),TRIM(SUBSTITUTE(SUBSTITUTE(SUBSTITUTE(_xlfn.TEXTJOIN("_", FALSE, C29, SUBSTITUTE(D29,"_", "")), "/", "%2F"), ":", "%3A"), " ", ""))) -> 10.3389%2Ffnins.2021.632853_TABLE1 | M29: {=IFERROR(INDEX(FileList!$A$1:$A$100, MATCH(L29, _xlfn.TEXTBEFORE(FileList!$A$1:$A$100, ".tsv"), 0)), "notfound")} -> 10.3389%2Ffnins.2021.632853_TABLE1.tsv | N29: TABLE 1 | Three behavioral correlates of plasticity and the proportion of REM (versus non-REM) sleep in 25 primate species. | U29: pdf | Y29: proportion REM and developmental milestones | Z29: secondary
A30: Falcone, C., Wolf-Ochoa, M., Amina, S., Hong, T., Vakilzadeh, G., Hopkins, W. D., Hof, P. R., Sherwood, C. C., Manger, P. R., Noctor, S. C., & Martinez-Cerdeno, V. (2019). Cortical interlaminar astrocytes across the therian mammal radiation. J Comp Neurol, 527(10), 1654-1674. https://doi.org/10.1002/cne.24605 | D30: TABLE 1 | E30: =RIGHT(A30,1) -> 5 | F30: =G30 & IF(H30<>"", "_" & H30, "_") & IF(I30<>"", "_" & I30, "_") & IF(B30<>"", "_" & B30, "") -> Falcone_etal_2019 | G30: =SUBSTITUTE(SUBSTITUTE(_xlfn.TEXTBEFORE(A30,","), "-", ""), " ", "") -> Falcone | H30: =IF(ISNUMBER(FIND("&", A30)), IF(LEN(A30)-LEN(SUBSTITUTE(A30, ",", ""))>=6, "etal", MID(A30, SEARCH("& ", A30)+2, SEARCH(",", A30, SEARCH("& ", A30)+2) - SEARCH("& ", A30)-2)), "" ) -> etal | I30: =_xlfn.TEXTBEFORE(_xlfn.TEXTAFTER(A30, "("), ")") -> 2019 | J30: =IF(C30<>"", C30, IF(C30="", _xlfn.TEXTAFTER(A30,"https://doi.org/"), C30)) -> 10.1002/cne.24605 | K30: =TRIM(_xlfn.TEXTJOIN("_",FALSE,F30,(SUBSTITUTE(SUBSTITUTE(D30," ",""), "_", "")))) -> Falcone_etal_2019_TABLE1 | L30: =IF(ISBLANK(C30),TRIM(SUBSTITUTE(SUBSTITUTE(SUBSTITUTE(_xlfn.TEXTJOIN("_", FALSE, J30, SUBSTITUTE(D30,"_", "")), "/", "%2F"), ":", "%3A"), " ", "")),TRIM(SUBSTITUTE(SUBSTITUTE(SUBSTITUTE(_xlfn.TEXTJOIN("_", FALSE, C30, SUBSTITUTE(D30,"_", "")), "/", "%2F"), ":", "%3A"), " ", ""))) -> 10.1002%2Fcne.24605_TABLE1 | M30: {=IFERROR(INDEX(FileList!$A$1:$A$100, MATCH(L30, _xlfn.TEXTBEFORE(FileList!$A$1:$A$100, ".tsv"), 0)), "notfound")} -> 10.1002%2Fcne.24605_TABLE1.tsv | N30: TABLE 1 Pial and subpial ILA presence in mammalian species analyzed. Highlighted in red are the species where proper subpial ILA are present | U30: pdf | Z30: primary
A31: Falcone, C., Wolf-Ochoa, M., Amina, S., Hong, T., Vakilzadeh, G., Hopkins, W. D., Hof, P. R., Sherwood, C. C., Manger, P. R., Noctor, S. C., & Martinez-Cerdeno, V. (2019). Cortical interlaminar astrocytes across the therian mammal radiation. J Comp Neurol, 527(10), 1654-1674. https://doi.org/10.1002/cne.24605 | D31: TABLE 2 | E31: =RIGHT(A31,1) -> 5 | F31: =G31 & IF(H31<>"", "_" & H31, "_") & IF(I31<>"", "_" & I31, "_") & IF(B31<>"", "_" & B31, "") -> Falcone_etal_2019 | G31: =SUBSTITUTE(SUBSTITUTE(_xlfn.TEXTBEFORE(A31,","), "-", ""), " ", "") -> Falcone | H31: =IF(ISNUMBER(FIND("&", A31)), IF(LEN(A31)-LEN(SUBSTITUTE(A31, ",", ""))>=6, "etal", MID(A31, SEARCH("& ", A31)+2, SEARCH(",", A31, SEARCH("& ", A31)+2) - SEARCH("& ", A31)-2)), "" ) -> etal | I31: =_xlfn.TEXTBEFORE(_xlfn.TEXTAFTER(A31, "("), ")") -> 2019 | J31: =IF(C31<>"", C31, IF(C31="", _xlfn.TEXTAFTER(A31,"https://doi.org/"), C31)) -> 10.1002/cne.24605 | K31: =TRIM(_xlfn.TEXTJOIN("_",FALSE,F31,(SUBSTITUTE(SUBSTITUTE(D31," ",""), "_", "")))) -> Falcone_etal_2019_TABLE2 | L31: =IF(ISBLANK(C31),TRIM(SUBSTITUTE(SUBSTITUTE(SUBSTITUTE(_xlfn.TEXTJOIN("_", FALSE, J31, SUBSTITUTE(D31,"_", "")), "/", "%2F"), ":", "%3A"), " ", "")),TRIM(SUBSTITUTE(SUBSTITUTE(SUBSTITUTE(_xlfn.TEXTJOIN("_", FALSE, C31, SUBSTITUTE(D31,"_", "")), "/", "%2F"), ":", "%3A"), " ", ""))) -> 10.1002%2Fcne.24605_TABLE2 | M31: {=IFERROR(INDEX(FileList!$A$1:$A$100, MATCH(L31, _xlfn.TEXTBEFORE(FileList!$A$1:$A$100, ".tsv"), 0)), "notfound")} -> 10.1002%2Fcne.24605_TABLE2.tsv | N31: TABLE 2 ILA linear density, number of primary processes, number of total processes, total length, and complexity, of mammalian species analyzed | U31: pdf | Z31: primary
A32: Finlay, B. L., Cheung, D. T.-M., & Darlington, R. B. (2006). Developmental constraints on or developmental structure in brain evolution? In Y. Munakata & M. H. Johnson (Eds.), Processes of Change in Brain and Cognitive Development (Vol. 8208, pp. 131-162). Oxford University Press. https://doi.org/10.1093/oso/9780198568742.003.0006 | D32: Table 6.1 | E32: =RIGHT(A32,1) -> 6 | F32: =G32 & IF(H32<>"", "_" & H32, "_") & IF(I32<>"", "_" & I32, "_") & IF(B32<>"", "_" & B32, "") -> Finlay_etal_2006 | G32: =SUBSTITUTE(SUBSTITUTE(_xlfn.TEXTBEFORE(A32,","), "-", ""), " ", "") -> Finlay | H32: =IF(ISNUMBER(FIND("&", A32)), IF(LEN(A32)-LEN(SUBSTITUTE(A32, ",", ""))>=6, "etal", MID(A32, SEARCH("& ", A32)+2, SEARCH(",", A32, SEARCH("& ", A32)+2) - SEARCH("& ", A32)-2)), "" ) -> etal | I32: =_xlfn.TEXTBEFORE(_xlfn.TEXTAFTER(A32, "("), ")") -> 2006 | J32: =IF(C32<>"", C32, IF(C32="", _xlfn.TEXTAFTER(A32,"https://doi.org/"), C32)) -> 10.1093/oso/9780198568742.003.0006 | K32: =TRIM(_xlfn.TEXTJOIN("_",FALSE,F32,(SUBSTITUTE(SUBSTITUTE(D32," ",""), "_", "")))) -> Finlay_etal_2006_Table6.1 | L32: =IF(ISBLANK(C32),TRIM(SUBSTITUTE(SUBSTITUTE(SUBSTITUTE(_xlfn.TEXTJOIN("_", FALSE, J32, SUBSTITUTE(D32,"_", "")), "/", "%2F"), ":", "%3A"), " ", "")),TRIM(SUBSTITUTE(SUBSTITUTE(SUBSTITUTE(_xlfn.TEXTJOIN("_", FALSE, C32, SUBSTITUTE(D32,"_", "")), "/", "%2F"), ":", "%3A"), " ", ""))) -> 10.1093%2Foso%2F9780198568742.003.0006_Table6.1 | M32: {=IFERROR(INDEX(FileList!$A$1:$A$100, MATCH(L32, _xlfn.TEXTBEFORE(FileList!$A$1:$A$100, ".tsv"), 0)), "notfound")} -> 10.1093%2Foso%2F9780198568742.003.0006_Table6.1.tsv | P32: Species -- wait for Project Kaskan | Q32: NA | R32: Finlay_etal_2006_Table6.1_snapshot.xlsx | S32: Y | T32: Finlay_etal_2006_Table6.1.csv | U32: pdf | V32: table | W32: YES - but formatting issues | X32: https://www.researchgate.net/publication/299027052_Developmental_constraints_on_or_developmental_structure_in_brain_evolution | Y32: cerebral cortex surface area and number of areas (broadly defined) | Z32: primary (derived from published materials) | AD32: summary to check more precise areas from ProjectKaskan | AE32: mammals
A33: Frahm, H. D., & Zilles, K. (1994). Volumetric comparison of hippocampal regions in 44 primate species. J Hirnforsch, 35(3), 343-354. https://www.ncbi.nlm.nih.gov/pubmed/7983368 | C33: PMID:7983368 | D33: Table1 | E33: =RIGHT(A33,1) -> 8 | F33: =G33 & IF(H33<>"", "_" & H33, "_") & IF(I33<>"", "_" & I33, "_") & IF(B33<>"", "_" & B33, "") -> Frahm_Zilles_1994 | G33: =SUBSTITUTE(SUBSTITUTE(_xlfn.TEXTBEFORE(A33,","), "-", ""), " ", "") -> Frahm | H33: =IF(ISNUMBER(FIND("&", A33)), IF(LEN(A33)-LEN(SUBSTITUTE(A33, ",", ""))>=6, "etal", MID(A33, SEARCH("& ", A33)+2, SEARCH(",", A33, SEARCH("& ", A33)+2) - SEARCH("& ", A33)-2)), "" ) -> Zilles | I33: =_xlfn.TEXTBEFORE(_xlfn.TEXTAFTER(A33, "("), ")") -> 1994 | J33: =IF(C33<>"", C33, IF(C33="", _xlfn.TEXTAFTER(A33,"https://doi.org/"), C33)) -> PMID:7983368 | K33: =TRIM(_xlfn.TEXTJOIN("_",FALSE,F33,(SUBSTITUTE(SUBSTITUTE(D33," ",""), "_", "")))) -> Frahm_Zilles_1994_Table1 | L33: =IF(ISBLANK(C33),TRIM(SUBSTITUTE(SUBSTITUTE(SUBSTITUTE(_xlfn.TEXTJOIN("_", FALSE, J33, SUBSTITUTE(D33,"_", "")), "/", "%2F"), ":", "%3A"), " ", "")),TRIM(SUBSTITUTE(SUBSTITUTE(SUBSTITUTE(_xlfn.TEXTJOIN("_", FALSE, C33, SUBSTITUTE(D33,"_", "")), "/", "%2F"), ":", "%3A"), " ", ""))) -> PMID%3A7983368_Table1 | M33: {=IFERROR(INDEX(FileList!$A$1:$A$100, MATCH(L33, _xlfn.TEXTBEFORE(FileList!$A$1:$A$100, ".tsv"), 0)), "notfound")} -> notfound | N33: Hippocampal regions in 44 primates (Table 1) | V33: table | W33: NO - not digitized | Y33: hippocampal region volumes | Z33: primary | AA33: Stephan | AB33: volumetry
A34: Frahm, H. D., Rehkamper, G., & Nevo, E. (1997). Brain structure volumes in the mole rat, Spalax ehrenbergi (Spalacidae, Rodentia) in comparison to the rat and subterrestrial insectivores. J Hirnforsch, 38(2), 209-222. https://www.ncbi.nlm.nih.gov/pubmed/9176733 | C34: PMID:9176733 | D34: Table1 | E34: =RIGHT(A34,1) -> 3 | F34: =G34 & IF(H34<>"", "_" & H34, "_") & IF(I34<>"", "_" & I34, "_") & IF(B34<>"", "_" & B34, "") -> Frahm_etal_1997 | G34: =SUBSTITUTE(SUBSTITUTE(_xlfn.TEXTBEFORE(A34,","), "-", ""), " ", "") -> Frahm | H34: =IF(ISNUMBER(FIND("&", A34)), IF(LEN(A34)-LEN(SUBSTITUTE(A34, ",", ""))>=6, "etal", MID(A34, SEARCH("& ", A34)+2, SEARCH(",", A34, SEARCH("& ", A34)+2) - SEARCH("& ", A34)-2)), "" ) -> etal | I34: =_xlfn.TEXTBEFORE(_xlfn.TEXTAFTER(A34, "("), ")") -> 1997 | J34: =IF(C34<>"", C34, IF(C34="", _xlfn.TEXTAFTER(A34,"https://doi.org/"), C34)) -> PMID:9176733 | K34: =TRIM(_xlfn.TEXTJOIN("_",FALSE,F34,(SUBSTITUTE(SUBSTITUTE(D34," ",""), "_", "")))) -> Frahm_etal_1997_Table1 | L34: =IF(ISBLANK(C34),TRIM(SUBSTITUTE(SUBSTITUTE(SUBSTITUTE(_xlfn.TEXTJOIN("_", FALSE, J34, SUBSTITUTE(D34,"_", "")), "/", "%2F"), ":", "%3A"), " ", "")),TRIM(SUBSTITUTE(SUBSTITUTE(SUBSTITUTE(_xlfn.TEXTJOIN("_", FALSE, C34, SUBSTITUTE(D34,"_", "")), "/", "%2F"), ":", "%3A"), " ", ""))) -> PMID%3A9176733_Table1 | M34: {=IFERROR(INDEX(FileList!$A$1:$A$100, MATCH(L34, _xlfn.TEXTBEFORE(FileList!$A$1:$A$100, ".tsv"), 0)), "notfound")} -> notfound | N34: Brain structure volumes in Spalax ehrenbergi (Table 1) | V34: table | W34: NO - not digitized | Y34: brain structure volumes (Spalax) | Z34: primary | AA34: Stephan | AB34: volumetry
A35: Frahm, H. D., Stephan, H., & Baron, G. (1984). Comparison of brain structure volumes in insectivora and primates. V. Area striata (AS). J Hirnforsch, 25(5), 537-557. https://www.ncbi.nlm.nih.gov/pubmed/6501869 | C35: PMID:6501869 | D35: Table 1 | E35: =RIGHT(A35,1) -> 9 | F35: =G35 & IF(H35<>"", "_" & H35, "_") & IF(I35<>"", "_" & I35, "_") & IF(B35<>"", "_" & B35, "") -> Frahm_etal_1984 | G35: =SUBSTITUTE(SUBSTITUTE(_xlfn.TEXTBEFORE(A35,","), "-", ""), " ", "") -> Frahm | H35: =IF(ISNUMBER(FIND("&", A35)), IF(LEN(A35)-LEN(SUBSTITUTE(A35, ",", ""))>=6, "etal", MID(A35, SEARCH("& ", A35)+2, SEARCH(",", A35, SEARCH("& ", A35)+2) - SEARCH("& ", A35)-2)), "" ) -> etal | I35: =_xlfn.TEXTBEFORE(_xlfn.TEXTAFTER(A35, "("), ")") -> 1984 | J35: =IF(C35<>"", C35, IF(C35="", _xlfn.TEXTAFTER(A35,"https://doi.org/"), C35)) -> PMID:6501869 | K35: =TRIM(_xlfn.TEXTJOIN("_",FALSE,F35,(SUBSTITUTE(SUBSTITUTE(D35," ",""), "_", "")))) -> Frahm_etal_1984_Table1 | L35: =IF(ISBLANK(C35),TRIM(SUBSTITUTE(SUBSTITUTE(SUBSTITUTE(_xlfn.TEXTJOIN("_", FALSE, J35, SUBSTITUTE(D35,"_", "")), "/", "%2F"), ":", "%3A"), " ", "")),TRIM(SUBSTITUTE(SUBSTITUTE(SUBSTITUTE(_xlfn.TEXTJOIN("_", FALSE, C35, SUBSTITUTE(D35,"_", "")), "/", "%2F"), ":", "%3A"), " ", ""))) -> PMID%3A6501869_Table1 | M35: {=IFERROR(INDEX(FileList!$A$1:$A$100, MATCH(L35, _xlfn.TEXTBEFORE(FileList!$A$1:$A$100, ".tsv"), 0)), "notfound")} -> notfound | N35: Table 1. Volumes of area striata and some of its laminar components (in mm3). | V35: table | W35: NO - not digitized | Y35: area striata volume | Z35: primary | AA35: Stephan | AB35: volumetry
