Workbook

Sheet publishedTable1cerebral cortex
A1: Table 1. Cerebral cortex
A2: Species | B2: Order | C2: Mass, g | E2: N, n | G2: O, n | I2: N/mg | K2: O/mg | M2: O/N | O2: Source
A3: Sorex fumeus | B3: Eulipotyphla | C3: 0.084 ± 0.009 | E3: 9,730,000 ± 352,000 | G3: 9,290,000 ± 1,112,000 | I3: 116,727 ± 9,387 | K3: 111,754 ± 18,566 | M3: 0.958 ± 0.135 | O3: Sarko et al., 2009
A4: Mus musculus | B4: Glires | C4: 0.173 ± 0.015 | E4: 13,688,162 ± 2,242,257 | G4: 12,061,838 ± 3,668,594 | I4: 78,672 ± 7,683 | K4: 68,643 ± 15,807 | M4: 0.870 ± 0.177 | O4: Herculano-Houzel et al., 2006
A5: Blarina brevicauda | B5: Eulipotyphla | C5: 0.197 ± 0.012 | E5: 11,876,000 ± 1,569,000 | G5: 15,820,000 ± 1,158,000 | I5: 60,214 ± 4,935 | K5: 80,729 ± 8,731 | M5: 1.357 ± 0.250 | O5: Sarko et al., 2009
A6: Heterocephalus glaber | B6: Glires | C6: 0.184 ± 0.026 | E6: 6,151,875 ± 1,065,587 | G6: 8,398,125 ± 1,197,056 | I6: 33,374 ± 2,063 | K6: 45,894 ± 11,497 | M6: 1.365 ± 0.125 | O6: Herculano-Houzel et al., 2011
A7: Condylura cristata | B7: Eulipotyphla | C7: 0.420± 0.024 | E7: 17,250,000± 3,105,000 | G7: 32,010,000± 8,822,000 | I7: 40,777 ± 5,145 | K7: 76,995 ± 25,019 | M7: 1.966 ± 0.924 | O7: Sarko et al., 2009
A8: Parascalops breweri | B8: Eulipotyphla | C8: 0.429± 0.019 | E8: 15,690,000± 2,611,000 | G8: 39,870,000± 4,884,000 | I8: 36,727 ± 7,359 | K8: 93,185 ± 14,583 | M8: 2.581 ± 0.109 | O8: Sarko et al., 2009
A9: Amblysomus hottentotus | B9: Afrotheria | C9: 0.439 ± 0.035 | E9: 21,516,000 ± 2,154,000 | G9: 21,370,000 ± 4,614,000 | I9: 48,932 ± 1,004 | K9: 48,146 ± 6,674 | M9: 0.982 ± 0.116 | O9: Neves et al., 2014
A10: Scalopus aquaticus | B10: Eulipotyphla | C10: 0.476± 0.032 | E10: 26,680,000± 5,113,000 | G10: 38,540,000 ± 5,567,000 | I10: 60,461± 12,249 | K10: 80,745± 6,407 | M10: 1.383± 0.368 | O10: Sarko et al., 2009
A11: Elephantulus myurus | B11: Afrotheria | C11: 0.471 ± 0.021 | E11: 25,865,000 ± 4,020,000 | G11: 26,229,000 ± 1,104,000 | I11: 54,644 ± 6,098 | K11: 55,693 ± 138 | M11: 1.032 ± 0.119 | O11: Neves et al., 2014
A12: Mesocricetus auratus | B12: Glires | C12: 0.446 ± 0.048 | E12: 17,140,000 ± 3,619,934 | G12: 41,870,000 ± 1,350,121 | I12: 39,099 ± 12,332 | K12: 94,271 ± 7,136 | M12: 2.507 ± 0.608 | O12: Herculano-Houzel et al., 2006
A13: Rattus norvegicus | B13: Glires | C13: 0.769 ± 0.113 | E13: 31,017,192 + 3,034,654 | G13: 45,687,808 ± 5,678,958 | I13: 41,092 ± 7,999 | K13: 60,426 ± 12,477 | M13: 1.497 ± 0.328 | O13: Herculano-Houzel et al., 2006
A14: Microcebus murinus | B14: Primata | C14: 0.908 | E14: 22310400 | G14: 70649600 | I14: 24571 | K14: 77808 | M14: 3.167 | O14: Gabi et al., 2010
A15: Proechimys cayennensis | B15: Glires | C15: 0.924 ± 0.050 | E15: 26,086,024 ± 2,155,723 | G15: 71,833,039 ± 6,712,722 | I15: 28,321 ± 3,870 | K15: 78,011 ± 11,497 | M15: 2.752 ± 0.030 | O15: Herculano-Houzel et al., 2011
A16: Petrodromus tetradactylus | B16: Afrotheria | C16: 1.239 ± 0.059 | E16: 33,947,000 ± 5,840,000 | G16: 40,486,000 ± 1,104,000 | I16: 27,236 ± 3,416 | K16: 32,550 ± 2,661 | M16: 1.202 ± 0.053 | O16: Neves et al., 2014
A17: Tupaia glis | B17: Scandentia | C17: 1.455 ± 0.174 | E17: 60,390,000 ± 26,510,000 | G17: 85,580,000 ± 8,400,000 | I17: 42,900 ± 23,350 | K17: 58,900 ± 1,270 | M17: 1.417 | O17: Herculano-Houzel et al., 2007
A18: Cavia porcellus | B18: Glires | C18: 1.938 ± 0.231 | E18: 43,510,525 ± 3,169,924 | G18: 108,614,475 ± 12,775,334 | I18: 22,508 ± 1,050 | K18: 56,036 ± 93 | M18: 2.492 ± 0.112 | O18: Herculano-Houzel et al., 2006
A19: Cynomys sp. | B19: Glires | C19: 2.586 ± 0.109 | E19: 53,768,353 ± 6,044,322 | G19: 183,451,647 ± 17,959,104 | I19: 20,866 ± 3,113 | K19: 71,202 ± 9,677 | M19: 3.432 ± 0.433 | O19: Herculano-Houzel et al., 2011
A20: Sciurus carolinensis | B20: Glires | C20: 2.730 ± 0.178 | E20: 77,334,617 ± 2,634,444 | G20: 209,654,717 ± 13,003,170 | I20: 28,384 ± 1,487 | K20: 76,877 ± 3,859 | M20: 2.709 ± 0.076 | O20: Herculano-Houzel et al., 2011
A21: Oryctolagus cuniculus | B21: Glires | C21: 4.448 | E21: 71448750 | G21: 254801250 | I21: 16063 | K21: 57284 | M21: 3.566 | O21: Herculano-Houzel et al., 2011
A22: Callithrix jacchus | B22: Primata | C22: 5.561 ± 0.443 | E22: 244,720,000 ± 81,180,000 | G22: 395,340,000 ± 58,790,000 | I22: 44,280 ± 15,900 | K22: 71,800 ± 14,880 | M22: 1.615 | O22: Herculano-Houzel et al., 2007
A23: Otolemur garnettii | B23: Primata | C23: 6.290 ± 0.863 | E23: 226,090,000 ± 87,570,000 | G23: 402,070,000 ± 74,790,000 | I23: 37,820 ± 20,500 | K23: 63,610 ± 3,400 | M23: 1.778 | O23: Herculano-Houzel et al., 2007
A24: Dendrohyrax dorsalis | B24: Afrotheria | C24: 7.56 | E24: 98960000 | G24: 183540000 | I24: 13098 | K24: 24291 | M24: 1.855 | O24: Neves et al., 2014
A25: Dasyprocta prymnolopha | B25: Glires | C25: 8.913 ± 1.214 | E25: 110,641,950 ± 2,576,768 | G25: 416,208,050 ± 950,422 | I25: 13,250 ± 1,633 | K25: 49,939 ± 7,422 | M25: 3.763 ± 0.096 | O25: Herculano-Houzel et al., 2006
A26: Procavia capensis | B26: Afrotheria | C26: 10.478 ± 0.646 | E26: 197,933,000 ± 29,082,000 | G26: 366,620,000 ± 13,520,000 | I26: 19,134 ± 3,955 | K26: 35,203 ± 3,461 | M26: 1.883 ± 0.208 | O26: Neves et al., 2014
A27: Aotus trivirgatus | B27: Primata | C27: 10.617 ± 0.610 | E27: 441,900,000 ± 111,310,000 | G27: 695,420,000 ± 130,000,000 | I27: 41,990 ± 12,900 | K27: 65,330 ± 5,950 | M27: 1.574 | O27: Herculano-Houzel et al., 2007
A28: Callimico goeldii | B28: Primata | C28: 12.984 | E28: 357129180 | G28: 715330820 | I28: 27505 | K28: 55093 | M28: 2.003 | O28: Gabi et al., 2010
A29: Saimiri sciureus | B29: Primata | C29: 20.652 ± 0.368 | E29: 1,340,000,000 ± 20,000,000 | G29: 1,610,000,000 ± 40,000,000 | I29: 64,930 ± 7,420 | K29: 77,840 ± 790 | M29: 1.201 | O29: Herculano-Houzel et al., 2007
A30: Macaca fascicularis | B30: Primata | C30: 36.226 | E30: 800955000 | G30: 2758845000 | I30: 22110 | K30: 76156 | M30: 3.444 | O30: Gabi et al., 2010
A31: Cebus apella | B31: Primata | C31: 39.178 | E31: 1140000000 | G31: 2550000000 | I31: 29180 | K31: 64980 | M31: 2.237 | O31: Herculano-Houzel et al., 2007
A32: Macaca radiata | B32: Primata | C32: 48.274 | E32: 1655707140 | G32: 3808672860 | I32: 34298 | K32: 78897 | M32: 2.3 | O32: Gabi et al., 2010
A33: Sus scrofa domesticus | B33: Artiodactyla | C33: 42.404 | E33: 307082404 | G33: 3250251354 | I33: 7276 | K33: 77016 | M33: 10.585 | O33: Kazu et al., 2014
A34: Hydrochoerus hydrochaeris | B34: Glires | C34: 48.175 ± 2.714 | E34: 306,501,565 ± 62,726,120 | G34: 1,847,818,435 ± 512,392,109 | I34: 6,336 ± 945 | K34: 38,117 ± 8,489 | M34: 5.983 ± 0.447 | O34: Herculano-Houzel et al., 2006
A35: Antidorcas marsupialis | B35: Artiodactyla | C35: 68.806 | E35: 396896159 | G35: 4126259275 | I35: 5768 | K35: 59969 | M35: 10.396 | O35: Kazu et al., 2014
A36: Macaca mulatta | B36: Primata | C36: 69.832 | E36: 1710000000 | G36: 5270000000 | I36: 24470 | K36: 75400 | M36: 3.082 | O36: Herculano-Houzel et al., 2007
A37: Damaliscus dorcas phillipsi | B37: Artiodactyla | C37: 111.31 | E37: 570673431 | G37: 6762256227 | I37: 5127 | K37: 60760 | M37: 11.851 | O37: Kazu et al., 2014
A38: Papio anubis cynocephalus | B38: Primata | C38: 120.214 | E38: 2875028372 | G38: 7569751628 | I38: 23916 | K38: 62969 | M38: 2.633 | O38: Gabi et al., 2010
A39: Tragelaphus strepsiceros | B39: Artiodactyla | C39: 213.37 | E39: 762567178 | G39: 12302304448 | I39: 3574 | K39: 57657 | M39: 16.133 | O39: Kazu et al., 2014
A40: Giraffa camelopardalis | B40: Artiodactyla | C40: 398.808 | E40: 1730513460 | G40: 27513706540 | I40: 4339 | K40: 68990 | M40: 15.9 | O40: Kazu et al., 2014
...

Sheet publishedTable2cerebellum
A1: Table 2. Cerebellum
A2: Species | B2: Order | C2: Mass, g | D2: +- | E2: N, n | F2: +- | G2: O, n | H2: +- | I2: N/mg | J2: +- | K2: O/mg | L2: +- | M2: O/N | N2: +- | O2: Source
A3: Sorex fumeus | B3: Eulipotyphla | C3: 0.020 ± 0.002 | E3: 20,870,000 ± 4,660,000 | G3: 5,290,000 ± 2,120,000 | I3: 1,038,666 ± 214,440 | K3: 258,073 ± 85,510 | M3: 0.253 | O3: Sarko et al., 2009
A4: Blarina brevicauda | B4: Eulipotyphla | C4: 0.037 ± 0.005 | E4: 33,430,000 ± 5,821,000 | G4: 4,410,000 ± 1,280,000 | I4: 919,942 ± 19,721 | K4: 118,736 ± 25,620 | M4: 0.132 | O4: Sarko et al., 2009
A5: Heterocephalus glaber | B5: Glires | C5: 0.048 ± 0.004 | E5: 15,742,270 ± 2,849,254 | G5: 5,482,730 ± 1,274,352 | I5: 327,280 ± 48,331 | K5: 115,748 ± 32,952 | M5: 0.356 ± 0.106 | O5: Herculano-Houzel et al., 2011
A6: Mus musculus | B6: Glires | C6: 0.056 ± 0.005 | E6: 42,219,708 ± 9,277,647 | G6: 6,947,791 ± 1,502,773 | I6: 746,691 ± 128,541 | K6: 123,493 ± 25,715 | M6: 0.165 ± 0.017 | O6: Herculano-Houzel et al., 2006
A7: Amblysomus hottentotus | B7: Afrotheria | C7: 0.084 | E7: 34,488,379 ± 3,207,000 | G7: 8,155,621 ± 813,000 | I7: 409,687 ± 18,667 | K7: 96,849 ± 5,069 | M7: 0.236 ± 0.002 | O7: Neves et al., 2014
A8: Parascalops breweri | B8: Eulipotyphla | C8: 0.102 ± 0.005 | E8: 100,780,000 ± 13,850,000 | G8: 7,010,000 ± 1,100,000 | I8: 997,370 ± 173,030 | K8: 68,795 ± 7,910 | M8: 0.07 | O8: Sarko et al., 2009
A9: Condylura cristata | B9: Eulipotyphla | C9: 0.138 ± 0.012 | E9: 105,920,000 ± 22,100,000 | G9: 19,480,000 ± 6,420,000 | I9: 776,460 ± 181,530 | K9: 139,912 ± 39,720 | M9: 0.184 | O9: Sarko et al., 2009
A10: Mesocricetus auratus | B10: Glires | C10: 0.145 ± 0.030 | E10: 61,210,000 ± 12,351,246 | G10: 7,430,000 ± 1,713,108 | I10: 424,002 ± 3,743 | K10: 51,332 ± 1,054 | M10: 0.121 ± 0.004 | O10: Herculano-Houzel et al., 2006
A11: Scalopus aquaticus | B11: Eulipotyphla | C11: 0.153 ± 0.008 | E11: 158,550,000 ± 13,630,000 | G11: 17,510,000 ± 3,160,000 | I11: 1,037,390 ± 63,570 | K11: 114,660 ± 20,790 | M11: 0.11 | O11: Sarko et al., 2009
A12: Elephantulus myurus | B12: Afrotheria | C12: 0.168 | E12: 89,312,372 ± 2,852,000 | G12: 23,368,628 ± 1,279,000 | I12: 531,494 ± 10,651 | K12: 139,028 ± 5,956 | M12: 0.261 ± 0.005 | O12: Neves et al., 2014
A13: Rattus norvegicus | B13: Glires | C13: 0.272 ± 0.038 | E13: 139,171,882 ± 11,185,675 | G13: 29,005,617 ± 6,282,204 | I13: 522,688 ± 108,847 | K13: 108,555 ± 29,355 | M13: 0.209 ± 0.047 | O13: Herculano-Houzel et al., 2006
A14: Petrodromus tetradactylus | B14: Afrotheria | C14: 0.304 | E14: 110,653,150 ±14,948,000 | G14: 34,657,851 ± 15,801,000 | I14: 362,537 ± 15,780 | K14: 110,153 ± 41,831 | M14: 0.299 ± 0.102 | O14: Neves et al., 2014
A15: Tupaia glis | B15: Scandentia | C15: 0.326 ± 0.018 | E15: 185,280,000 ± 16,980,000 | G15: 19,980,000 ± 1,510,000 | I15: 571,460 ± 83,200 | K15: 61,600 ± 7,990 | M15: 0.108 | O15: Herculano-Houzel et al., 2007
A16: Proechimys cayennensis | B16: Glires | C16: 0.330 ± 0.026 | E16: 162,512,050 ± 3,553,848 | G16: 36,372,950 ± 5,094,068 | I16: 494,338 ± 28,466 | K16: 110,122 ± 6,716 | M16: 0.224 ± 0.026 | O16: Herculano-Houzel et al., 2011
A17: Microcebus murinus | B17: Primata | C17: 0.391 | E17: 221386140 | G17: 17433860 | I17: 566205 | K17: 44588 | M17: 0.079 | O17: Gabi et al., 2010
A18: Cavia porcellus | B18: Glires | C18: 0.500 ± 0.077 | E18: 167,854,925 ± 2,175,973 | G18: 36,290,075 ± 4,506,186 | I18: 339,755 ± 48,069 | K18: 72,824 ± 2,216 | M18: 0.216 ± 0.024 | O18: Herculano-Houzel et al., 2006
A19: Callithrix jacchus | B19: Primata | C19: 0.730 ± 0.039 | E19: 361,370,000 ± 28,530,000 | G19: 49,490,000 ± 6,770,000 | I19: 494,970 ± 25,740 | K19: 68,170 ± 12,210 | M19: 0.137 | O19: Herculano-Houzel et al., 2007
A20: Cynomys sp. | B20: Glires | C20: 0.789 ± 0.093 | E20: 350,084,813 ± 72,177,851 | G20: 66,155,187 ± 39,268,821 | I20: 440,658 ± 39,554 | K20: 84,802 ± 54,286 | M20: 0.192 ± 0.123 | O20: Herculano-Houzel et al., 2011
A21: Sciurus carolinensis | B21: Glires | C21: 0.874 ± 0.069 | E21: 342,832,180 ± 71,181,798 | G21: 110,797,820 ± 9,070,639 | I21: 392,363 ± 74,294 | K21: 127,682 ± 19,212 | M21: 0.336 ± 0.090 | O21: Herculano-Houzel et al., 2011
A22: Otolemur garnettii | B22: Primata | C22: 1.196 ± 0.105 | E22: 743,500,000 ± 52,450,000 | G22: 65,960,000 ± 20,290,000 | I22: 623,080 ± 45,720 | K22: 54,460 ± 11,890 | M22: 0.089 | O22: Herculano-Houzel et al., 2007
A23: Oryctolagus cuniculus | B23: Glires | C23: 1.412 | E23: 396671250 | G23: 124578750 | I23: 280929 | K23: 88229 | M23: 1.222 | O23: Herculano-Houzel et al., 2011
A24: Aotus trivirgatus | B24: Primata | C24: 1.732 ± 0.218 | E24: 1,040,000,000 ± 20,000,000 | G24: 145,270,000 ± 45,030,000 | I24: 605,080 ± 90,570 | K24: 82,890 ± 15,580 | M24: 0.14 | O24: Herculano-Houzel et al., 2007
A25: Dendrohyrax dorsalis | B25: Afrotheria | C25: 1.918 | E25: 360929350 | G25: 77570650 | I25: 188180 | K25: 40444 | M25: 0.215 | O25: Neves et al., 2014
A26: Procavia capensis | B26: Afrotheria | C26: 2.058 | E26: 488,373,000 ± 42,322,000 | G26: 91,005,000 ± 30,180,000 | I26: 242,415 ± 46,950 | K26: 46,365 ± 19,711 | M26: 0.182 ± 0.046 | O26: Neves et al., 2014
A27: Dasyprocta prymnolopha | B27: Glires | C27: 2.742 | E27: 673,488,085 ± 48,145,960 | G27: 155,986,915 ± 32,978,520 | I27: 253,208 ± 39,447 | K27: 57,945 ± 7,405 | M27: 0.234 ± 0.066 | O27: Herculano-Houzel et al., 2006
A28: Saimiri sciureus | B28: Primata | C28: 4.3 | E28: 1820000000 | G28: 133020000 | I28: 424000 | K28: 30940 | M28: 0.073 | O28: Herculano-Houzel et al., 2007
A29: Cebus apella | B29: Primata | C29: 4.6 | E29: 2490000000 | G29: 245810000 | I29: 540310 | K29: 53440 | M29: 0.099 | O29: Herculano-Houzel et al., 2007
A30: Macaca fascicularis | B30: Primata | C30: 5.642 | E30: 2572600000 | G30: 135400000 | I30: 455973 | K30: 23999 | M30: 0.053 | O30: Gabi et al., 2010
A31: Macaca radiata | B31: Primata | C31: 5.748 | E31: 2038554160 | G31: 453565840 | I31: 354655 | K31: 78908 | M31: 0.222 | O31: Gabi et al., 2010
A32: Hydrochoerus hydrochaeris | B32: Glires | C32: 6.632 ± 1.312 | E32: 1,157,810,000 ± 5,515,433 | G32: 570,940,000 ± 81,105,148 | I32: 177,982 ± 34,889 | K32: 86,574 ± 4,902 | M32: 0.493 ± 0.068 | O32: Herculano-Houzel et al., 2006
A33: Macaca mulatta | B33: Primata | C33: 7.694 | E33: 4550000000 | G33: 931030000 | I33: 590800 | K33: 121010 | M33: 0.205 | O33: Herculano-Houzel et al., 2007
A34: Sus scrofa domesticus | B34: Artiodactyla | C34: 8.128 | E34: 1858320313 | G34: 348710938 | I34: 228632 | K34: 42902 | M34: 0.188 | O34: Kazu et al., 2014
A35: Antidorcas marsupialis | B35: Artiodactyla | C35: 11.458 | E35: 2257214074 | G35: 467244676 | I35: 196999 | K35: 40779 | M35: 0.207 | O35: Kazu et al., 2014
A36: Damaliscus dorcas phillipsi | B36: Artiodactyla | C36: 13.402 | E36: 2401712670 | G36: 443918456 | I36: 179206 | K36: 33123 | M36: 0.184 | O36: Kazu et al., 2014
A37: Papio anubis cynocephalus | B37: Primata | C37: 13.745 | E37: 7794907300 | G37: 525977700 | I37: 567109 | K37: 38267 | M37: 0.067 | O37: Gabi et al., 2010
A38: Tragelaphus strepsiceros | B38: Artiodactyla | C38: 31.776 | E38: 4042494141 | G38: 1266099609 | I38: 127218 | K38: 39845 | M38: 0.313 | O38: Kazu et al., 2014
A39: Pongo pygmaeus | B39: Primata | C39: 35.06 ± 4.34 | E39: 26,300,000,000 ± 2,470,000,000 | G39: 2200000000 | I39: 750143 | K39: 62750 | M39: 0.084 | O39: Herculano-Houzel and Kaas, 2011
A40: Gorilla gorilla | B40: Primata | C40: 37.56 | E40: 26400000000 | G40: 2900000000 | I40: 702875 | K40: 77210 | M40: 0.11 | O40: Herculano-Houzel and Kaas, 2011
...

Sheet publishedTable3RoB
A1: Table 3. RoB
A2: Species | B2: Order | C2: Mass, g | E2: N, n | G2: O, n | I2: N/mg | K2: O/mg | M2: O/N | O2: Source
A3: Sorex fumeus | B3: Eulipotyphla | C3: 0.072 ± 0.010 | E3: 5,560,000 ± 1,490,000 | G3: 8,280,000 ± 1,440,000 | I3: 75,941 ± 11,870 | K3: 114,880 ± 17,860 | M3: 1.489 ± 0.294 | O3: Sarko et al., 2009
A4: Blarina brevicauda | B4: Eulipotyphla | C4: 0.113 ± 0.009 | E4: 6,340,000 ± 636,200 | G4: 13,320,000 ± 1,120,000 | I4: 55,924 ± 2,130 | K4: 117,736 ± 5,840 | M4: 2.102 ± 0.096 | O4: Sarko et al., 2009
A5: Heterocephalus glaber | B5: Glires | C5: 0.160 ± 0.019 | E5: 4,981,317 ± 853,026 | G5: 10,310,350 ± 1,843,572 | I5: 31,674 ± 8,484 | K5: 64,145 ± 3,790 | M5: 2.125 | O5: Herculano-Houzel et al., 2011
A6: Mus musculus | B6: Glires | C6: 0.172 ± 0.019 | E6: 11,960,000 ± 1,577,022 | G6: 14,850,000 ± 3,590,591 | I6: 64,301 ± 6,623 | K6: 79,839 ± 11,249 | M6: 1.242 | O6: Herculano-Houzel et al., 2006
A7: Parascalops breweri | B7: Eulipotyphla | C7: 0.228 ± 0.009 | E7: 7,130,000 ± 920,000 | G7: 31,380,000 ± 1,500,000 | I7: 31,276 ± 3,180 | K7: 137,960 ± 7,180 | M7: 4.401 ± 0.375 | O7: Sarko et al., 2009
A8: Condylura cristata | B8: Eulipotyphla | C8: 0.244 ± 0.026 | E8: 8,160,000 ± 2,180,000 | G8: 31,550,000 ± 5,950,000 | I8: 33,475 ± 8,560 | K8: 128,990 ± 17,820 | M8: 3.866 ± 1.692 | O8: Sarko et al., 2009
A9: Amblysomus hottentotus | B9: Afrotheria | C9: 0.289 ± 0.013 | E9: 9,070,358 ± 1,069,000 | G9: 16,834,642 ± 3,276,000 | I9: 31,616 ± 5,124 | K9: 58,880 ± 13,983 | M9: 1.839 ± 0.144 | O9: Neves et al., 2014
A10: Scalopus aquaticus | B10: Eulipotyphla | C10: 0.370 ± 0.042 | E10: 16,560,000 ± 2,990,000 | G10: 45,690,000 ± 4,820,000 | I10: 44,620 ± 4,900 | K10: 123,600 ± 2,550 | M10: 2.759 ± 0.379 | O10: Sarko et al., 2009
A11: Mesocricetus auratus | B11: Glires | C11: 0.375 ± 0.057 | E11: 5,870,000 ± 1,162,059 | G11: 21,330,000 ± 8,878,857 | I11: 15,611 ± 715 | K11: 55,804 ± 15,174 | M11: 3.556 | O11: Herculano-Houzel et al., 2006
A12: Elephantulus myurus | B12: Afrotheria | C12: 0.401 ± 0.063 | E12: 14,012,533 ± 3,258,000 | G12: 28,997,467 ± 7,906,000 | I12: 34,520 ± 2,702 | K12: 70,967 ± 8,566 | M12: 2.048 ± 0.088 | O12: Neves et al., 2014
A13: Microcebus murinus | B13: Primata | C13: 0.5 | E13: 11014640 | G13: 50865360 | I13: 22029 | K13: 101731 | M13: 4.618 | O13: Gabi et al., 2010
A14: Rattus norvegicus | B14: Glires | C14: 0.683 ± 0.153 | E14: 18,678,758 ± 4,243,909 | G14: 47,221,243 ± 5,979,982 | I14: 27,813 ± 6,171 | K14: 71,760 ± 18,475 | M14: 2.587 | O14: Herculano-Houzel et al., 2006
A15: Proechimys cayennensis | B15: Glires | C15: 0.824 ± 0.006 | E15: 13,492,039 ± 1,533,120 | G15: 73,068,898 ± 2,691,449 | I15: 16,381 ± 1,973 | K15: 88,667 ± 2,658 | M15: 5.462 | O15: Herculano-Houzel et al., 2011
A16: Petrodromus tetradactylus | B16: Afrotheria | C16: 0.894 ± 0.022 | E16: 12,231,811 ± 188,000 | G16: 28,204,189 ± 5,408,000 | I16: 13,696 ± 547 | K16: 31,716 ± 6,830 | M16: 2.300 ± 0.407 | O16: Neves et al., 2014
A17: Tupaia glis | B17: Scandentia | C17: 0.919 ± 0.072 | E17: 22480000 | G17: 87080000 | I17: 25900 | K17: 100320 | M17: 3.874 | O17: Herculano-Houzel et al., 2007
A18: Cavia porcellus | B18: Glires | C18: 1.218 ± 0.178 | E18: 22,191,825 ± 9,431,638 | G18: 83,183,175 ± 8,139,966 | I18: 18,990 ± 10,522 | K18: 69,528 ± 16,855 | M18: 4.035 | O18: Herculano-Houzel et al., 2006
A19: Callithrix jacchus | B19: Primata | C19: 1.489 ± 0.317 | E19: 29,720,000 ± 9,350,000 | G19: 145,910,000 ± 27,830,000 | I19: 19,650 ± 2,840 | K19: 98370 | M19: 4.909 | O19: Herculano-Houzel et al., 2007
A20: Sciurus carolinensis | B20: Glires | C20: 1.943 ± 0.156 | E20: 33,493,401 ± 17,128,790 | G20: 210,023,933 ± 3,415,060 | I20: 17,616 ± 9,989 | K20: 108,482 ± 7,808 | M20: 7.246 | O20: Herculano-Houzel et al., 2011
A21: Cynomys sp. | B21: Glires | C21: 1.945 ± 0.146 | E21: 34,090,600 ± 589,361 | G21: 167,742,733 ± 5,025,290 | I21: 17,590 ± 1,335 | K21: 86,542 ± 6,793 | M21: 4.923 | O21: Herculano-Houzel et al., 2011
A22: Callimico goeldii | B22: Primata | C22: 2.086 | E22: 53911480 | G22: 194528520 | I22: 25844 | K22: 93254 | M22: 3.608 | O22: Gabi et al., 2010
A23: Otolemur garnettii | B23: Primata | C23: 2.131 ± 0.021 | E23: 20,800,000 ± 12,280,000 | G23: 147,440,000 ± 64,500,000 | I23: 9,730 ± 5,920 | K23: 69040 | M23: 7.088 | O23: Herculano-Houzel et al., 2007
A24: Aotus trivirgatus | B24: Primata | C24: 3.104 | E24: 49340000 | G24: 313460000 | I24: 15900 | K24: 100990 | M24: 6.353 | O24: Herculano-Houzel et al., 2007
A25: Oryctolagus cuniculus | B25: Glires | C25: 3.272 | E25: 26085000 | G25: 251415000 | I25: 7972 | K25: 76838 | O25: Herculano-Houzel et al., 2011
A26: Dendrohyrax dorsalis | B26: Afrotheria | C26: 3.328 | E26: 44671471 | G26: 152466529 | I26: 13423 | K26: 45813 | M26: 3.413 | O26: Neves et al., 2014
A27: Macaca fascicularis | B27: Primata | C27: 4.294 | E27: 65449620 | G27: 260170380 | I27: 15242 | K27: 60589 | M27: 3.975 | O27: Gabi et al., 2010
A28: Procavia capensis | B28: Afrotheria | C28: 4.317 ± 0.625 | E28: 69,358,240 ± 762,000 | G28: 162,984,760 ± 6,105,000 | I28: 16,436 ± 2,556 | K28: 38,353 ± 4,138 | M28: 2.351 ± 0.114 | O28: Neves et al., 2014
A29: Saimiri sciureus | B29: Primata | C29: 5.004 | E29: 65530000 | G29: 302590000 | I29: 13090 | K29: 60470 | M29: 4.618 | O29: Herculano-Houzel et al., 2007
A30: Dasyprocta prymnolopha | B30: Glires | C30: 5.972 ± 0.514 | E30: 43204320 | G30: 356835680 | I30: 6830 | K30: 56408 | O30: Herculano-Houzel et al., 2006
A31: Macaca radiata | B31: Primata | C31: 7.448 | E31: 61359000 | G31: 616641000 | I31: 8238 | K31: 82793 | M31: 10.05 | O31: Gabi et al., 2010
A32: Cebus apella | B32: Primata | C32: 8.43 | E32: 61850000 | G32: 506110000 | I32: 7340 | K32: 60040 | M32: 8.183 | O32: Herculano-Houzel et al., 2007
A33: Macaca mulatta | B33: Primata | C33: 9.204 ± 0.871 | E33: 121900000 | G33: 966520000 | I33: 12410 | K33: 98420 | M33: 7.929 | O33: Herculano-Houzel et al., 2007
A34: Sus scrofa domesticus | B34: Artiodactyla | C34: 13.85 | E34: 58709836 | G34: 1096821414 | I34: 4238 | K34: 79192 | M34: 18.682 | O34: Kazu et al., 2014
A35: Papio anubis cynocephalus | B35: Primata | C35: 17.235 | E35: 278150760 | G35: 1079809236 | I35: 16136 | K35: 62656 | M35: 3.882 | O35: Gabi et al., 2010
A36: Hydrochoerus hydrochaeris | B36: Glires | C36: 19.927 ± 0.270 | E36: 108,250,000 ± 4,400,000 | G36: 779,170,000 ± 381,900,000 | I36: 5434 | K36: 39234 | O36: Herculano-Houzel et al., 2006
A37: Antidorcas marsupialis | B37: Artiodactyla | C37: 25.81 | E37: 70485000 | G37: 1319280624 | I37: 2731 | K37: 51115 | M37: 18.71 | O37: Kazu et al., 2014
A38: Damaliscus dorcas phillipsi | B38: Artiodactyla | C38: 30.006 | E38: 86428126 | G38: 2136071876 | I38: 2880 | K38: 71188 | M38: 24.718 | O38: Kazu et al., 2014
A39: Tragelaphus strepsiceros | B39: Artiodactyla | C39: 61.716 | E39: 106590230 | G39: 3408779523 | I39: 1727 | K39: 55233 | M39: 31.98 | O39: Kazu et al., 2014
A40: Giraffa camelopardalis | B40: Artiodactyla | C40: 70.68 | E40: 142697625 | G40: 4878864876 | I40: 2019 | K40: 69028 | M40: 34.19 | O40: Kazu et al., 2014
...

Sheet publishedTable4olfactory bulb
A1: Table 4. Olfactory bulb
A2: Species | B2: Order | C2: n | D2: Mass, g | F2: N, n | H2: O, n | J2: N/mg | L2: O/mg | N2: O/N | P2: Source
A3: Callithrix jacchus | B3: Primata | C3: 5 | D3: 0.008 ± 0.014 | F3: 2,108,078 ± 983,420 | H3: 2,547,922 ± 960,104 | J3: 232,309 ± 137,605 | L3: 269,383 ± 105,563 | N3: 1.209 | P3: Ribeiro et al., 2014
A4: Sorex fumeus | B4: Eulipotyphla | C4: 3 | D4: 0.012 ± 0.002 | F4: 3,330,000 ± 1,050,000 | H4: 2,760,000 ± 130,000 | J4: 289,806 ± 124,350 | L4: 235,249 ± 44,620 | N4: 0.829 ± 214 | P4: Sarko et al., 2009
A5: Mus musculus | B5: Glires | C5: 4 | D5: 0.014 ± 0.004 | F5: 3,893,300 ± 1,246,396 | H5: 5,456,700 ± 1,154,502 | J5: 257,475 ± 34,036 | L5: 371,204 ± 75,573 | N5: 1.454 ± 0.260 | P5: Herculano-Houzel et al., 2006
A6: Heterocephalus glaber | B6: Glires | C6: 3 | D6: 0.021 ± 0.001 | F6: 2,303,030 ± 636,099 | H6: 3,571,970 ± 1,548,861 | J6: 108,895 ± 22,957 | L6: 167,991 ± 62,442 | N6: 1.516 ± 0.254 | P6: Herculano-Houzel et al., 2011
A7: Blarina brevicauda | B7: Eulipotyphla | C7: 5 | D7: 0.026 ± 0.003 | F7: 8,090,000 ± 935,900 | H7: 4,910,000 ± 730,000 | J7: 318,164 ± 34,950 | L7: 193,631 ± 31,450 | N7: 0.607 ± 0.125 | P7: Sarko et al., 2009
A8: Microcebus murinus | B8: Primata | C8: 2 | D8: 0.030 ± 0.008 | F8: 7,636,912 ± 119,088 | H8: 9,723,088 ± 842,576 | J8: 270,894 ± 61,946 | L8: 341,900 ± 54,311 | N8: 1.273 | P8: Ribeiro et al., 2014
A9: Condylura cristata | B9: Eulipotyphla | C9: 4 | D9: 0.040 ± 0.005 | F9: 10,550,000 ± 4,290,000 | H9: 7,470,000 ± 970,000 | J9: 254,720 ± 74,620 | L9: 185,124 ± 19,370 | N9: 0.708 ± 0.328 | P9: Sarko et al., 2009
A10: Parascalops breweri | B10: Eulipotyphla | C10: 3 | D10: 0.049 ± 0.008 | F10: 16,750,000 ± 6,370,000 | H10: 10,910,000 ± 3,400,000 | J10: 333,590 ± 81,590 | L10: 217,440 ± 41,370 | N10: 0.651 ± 0.168 | P10: Sarko et al., 2009
A11: Elephantulus myurus | B11: Afrotheria | C11: 2 | D11: 0.050 ± 0.010 | F11: 9,693,534 ± 1,745,000 | H11: 4919466 | J11: 194,678 ± 5,708 | L11: 97872 | N11: 0.507 | P11: Neves et al., 2014
A12: Aotus trivirgatus | B12: Primata | C12: 6 | D12: 0.050 ± 0.012 | F12: 7,925,468 ± 3,114,924 | H12: 8,360,532 ± 3,213,106 | J12: 155,879 ± 62,241 | L12: 162,922 ± 44,209 | N12: 1.055 | P12: Ribeiro et al., 2014
A13: Mesocricetus auratus | B13: Glires | C13: 2 | D13: 0.055 ± 0.011 | F13: 5,747,930 ± 347,203 | H13: 5,507,170 ± 2,277,605 | J13: 105,418 ± 27,498 | L13: 96,197 ± 21,237 | N13: 0.972 ± 0.455 | P13: Herculano-Houzel et al., 2006
A14: Rattus norvegicus | B14: Glires | C14: 5 | D14: 0.074 ± 0.022 | F14: 11,103,272 ± 3,202,766 | H14: 9,238,728 ± 2,250,728 | J14: 152,373 ± 26,913 | L14: 126,210 ± 8,033 | N14: 0.848 ± 0.145 | P14: Herculano-Houzel et al., 2006
A15: Scalopus aquaticus | B15: Eulipotyphla | C15: 3 | D15: 0.082 ± 0.005 | F15: 34,610,000 ± 5,960,000 | H15: 17,780,000 ± 2,060,000 | J15: 423,520 ± 94,950 | L15: 215,230 ± 14,600 | N15: 0.514 ± 0.154 | P15: Sarko et al., 2009
A16: Macaca mulatta | B16: Primata | C16: 1 | D16: 0.088 | F16: 8473800 | H16: 11006200 | J16: 96293 | L16: 125070 | N16: 1.299 | P16: Ribeiro et al., 2014
A17: Tupaia glis | B17: Scandentia | C17: 16 | D17: 0.100 ± 0.032 | F17: 12,700,000 ± 3,584,952 | H17: 20,068,000 ± 6,541,838 | J17: 130,173 ± 17,451 | L17: 205,876 ± 51,596 | N17: 1.58 | P17: Herculano-Houzel et al., 2007
A18: Cavia porcellus | B18: Glires | C18: 2 | D18: 0.103 ± 0.013 | F18: 6,065,700 ± 1,295,335 | H18: 10,154,300 ± 4,220,098 | J18: 58,560 ± 5,340 | L18: 96,793 ± 29,011 | N18: 1.637 ± 0.346 | P18: Herculano-Houzel et al., 2006
A19: Proechimys cayennensis | B19: Glires | C19: 1 | D19: 0.132 | F19: 9141540 | H19: 21128460 | J19: 69254 | L19: 160064 | N19: 2.311 | P19: Herculano-Houzel et al., 2011
A20: Oryctolagus cuniculus | B20: Glires | C20: 1 | D20: 0.156 | F20: 18765000 | H20: 22935000 | J20: 120288 | L20: 147019 | N20: 1.222 | P20: Herculano-Houzel et al., 2011
A21: Petrodromus tetradactylus | B21: Afrotheria | C21: 2 | D21: 0.159 ± 0.009 | F21: 12,828,365 ± 380,000 | H21: 14775635 | J21: 80,805 ± 3,084 | L21: 91369 | N21: 1.141 | P21: Neves et al., 2014
A22: Otolemur garnettii | B22: Primata | C22: 11 | D22: 0.200 ± 0.016 | F22: 30,237,060 ± 9,645,480 | H22: 34,244,000 ± 7,155,556 | J22: 149,219 ± 47,590 | L22: 170,505 ± 39,463 | N22: 1.133 | P22: Ribeiro et al., 2014
A23: Sciurus carolinensis | B23: Glires | C23: 9 | D23: 0.212 ± 0.022 | F23: 28,845,724 ± 7,903,412 | H23: 39,015,942 ± 12,812,316 | J23: 137,532 ± 38,236 | L23: 185,359 ± 58,050 | N23: 1.478 ± 0.776 | P23: Herculano-Houzel et al., 2011
A24: Procavia capensis | B24: Afrotheria | C24: 1 | D24: 0.286 | F24: 20909490 | H24: 14790510 | J24: 73110 | L24: 51715 | N24: 0.707 | P24: Neves et al., 2014
A25: Dasyprocta prymnolopha | B25: Glires | C25: 3 | D25: 0.737 ± 0.162 | F25: 58,124,085 ± 4,952,795 | H25: 72,595,915 ± 19,682,805 | J25: 88,008 ± 14,973 | L25: 107,301 ± 1,958 | N25: 1.239 ± 0.233 | P25: Herculano-Houzel et al., 2006
A26: Sus scrofa domesticus | B26: Artiodactyla | C26: 1 | D26: 0.822 | F26: 9195500 | H26: 77554500 | J26: 11187 | L26: 94348 | N26: 8.434 | P26: Kazu et al., 2014
A27: Antidorcas marsupialis | B27: Artiodactyla | C27: 1 | D27: 1.2 | F27: 15998400 | H27: 105201600 | J27: 13332 | L27: 87668 | N27: 6.576 | P27: Kazu et al., 2014
A28: Hydrochoerus hydrochaeris | B28: Glires | C28: 2 | D28: 1.302 ± 0.031 | F28: 28,560,310 ± 8,515,588 | H28: 67,389,690 ± 21,015,416 | J28: 21,864 ± 6,018 | L28: 51,544 ± 17,981 | N28: 2.333 ± 0.180 | P28: Herculano-Houzel et al., 2006
A29: Giraffa camelopardalis | B29: Artiodactyla | C29: 1 | D29: 2.052 | F29: 24678000 | H29: 232384500 | J29: 12026 | L29: 113248 | N29: 9.417 | P29: Kazu et al., 2014
A30: Tragelaphus strepsiceros | B30: Artiodactyla | C30: 1 | D30: 5.546 | F30: 38331562 | H30: 362731438 | J30: 6912 | L30: 58913 | N30: 8.523 | P30: Kazu et al., 2014
A31: Loxodonta africana | B31: Afrotheria | C31: 1 | D31: 41.886 | F31: 908371986 | H31: 2857878014 | J31: 21687 | L31: 68230 | N31: 3.146 | P31: Herculano-Houzel et al., 2014
A33: All values refer to both olfactory bulbs. N = Neurons; O = other cells.

Sheet publishedTable5whole brain
A1: Table 5. Whole brain
A2: Species | B2: Order | C2: n | D2: Body mass, g | F2: Brain mass, g | H2: Neurons | J2: Other cells | L2: % Neurons | N2: Source
A3: Sorex fumeus | B3: Eulipotyphla | C3: 3 | D3: 7.8 ± 0.1 | F3: 0.176 ± 0.007 | H3: 36,460,000 ± 4,567,000 | J3: 22,860,000 ± 3,956,000 | L3: 61.3 ± 1.4 | N3: Sarko et al., 2009
A4: Blarina brevicauda | B4: Eulipotyphla | C4: 5 | D4: 16.2 ± 1.6 | F4: 0.347±.0.018 | H4: 55,190,000 ± 6,126,000 | J4: 33,550,000 ± 1,222,000 | L4: 64.8 ± 2.3 | N4: Sarko et al., 2009
A5: Heterocephalus glaber | B5: Glires | C5: 3 | D5: 23.3 ± 5.9 | F5: 0.392 ± 0.045 | H5: 26,875,462 ± 3,340,087 | J5: 24,191,205 ± 1,739,102 | L5: 52.5 ± 3.3 | N5: Herculano-Houzel et al., 2011
A6: Mus musculus | B6: Glires | C6: 4 | D6: 40.4 ± 11.6 | F6: 0.402 ± 0.028 | H6: 67,873,741 ± 10,406,194 | J6: 33,858,759 ± 6,657,119 | L6: 65.3 ± 2.3 | N6: Herculano-Houzel et al., 2006
A7: Parascalops breweri | B7: Eulipotyphla | C7: 3 | D7: 42.7 ± 9.1 | F7: 0.759 ± 0.024 | H7: 123,600,000 ± 12,470,000 | J7: 78,260,000 ± 6,095,000 | L7: 61.2 ± 4.1 | N7: Sarko et al., 2009
A8: Condylura cristata | B8: Eulipotyphla | C8: 4 | D8: 41.1 ± 4.7 | F8: 0.802 ± 0.046 | H8: 131,330,000 ± 21,229,000 | J8: 83,040,000 ± 19,046,000 | L8: 61.3 ± 6.3 | N8: Sarko et al., 2009
A9: Amblysomus hottentotus | B9: Afrotheria | C9: 2 | D9: 79 | F9: 0.812 ± 0.044 | H9: 65,074,000 ± 2,124,000 | J9: 46,631,000 ± 527,000 | N9: Neves et al., 2014
A10: Mesocricetus auratus | B10: Glires | C10: 2 | D10: 168.1 ± 13.6 | F10: 0.965 ± 0.136 | H10: 84,220,000 ± 9,893,371 | J10: 70,640,000 ± 11,942,086 | L10: 54.3 ± 1.3 | N10: Herculano-Houzel et al., 2006
A11: Scalopus aquaticus | B11: Eulipotyphla | C11: 3 | D11: 95.3 ± 9.8 | F11: 0.999 ± 0.080 | H11: 203,520,000 ± 14,587,000 | J11: 101,740,000 ± 11,823,000 | L11: 66.7 ± 1.4 | N11: Sarko et al., 2009
A12: Elephantulus myurus | B12: Afrotheria | C12: 2 | D12: 45.1 | F12: 1.040 ± 0.082 | H12: 129,190,603 ± 4,424,000 | J12: 78,594,397 ± 7,733,000 | N12: Neves et al., 2014
A13: Rattus norvegicus | B13: Glires | C13: 4 | D13: 315.1 ± 102.9 | F13: 1.724 ± 0.292 | H13: 188,867,832 ± 12,622,383 | J13: 121,914,668 ± 7,106,729 | L13: 60.7 ± 2.4 | N13: Herculano-Houzel et al., 2006
A14: Microcebus murinus | B14: Primata | C14: 1 | D14: 60 | F14: 1.799 | H14: 254711180 | J14: 138948820 | L14: 64.7 | N14: Gabi et al., 2010
A15: Proechimys cayennensis | B15: Glires | C15: 2 | D15: 223.485 ± 16.6 | F15: 2.078 ± 0.071 | H15: 202,090,113 ± 2,931,245 | J15: 181,274,887 ± 4,310,103 | L15: 52.7 ± 1.0 | N15: Herculano-Houzel et al., 2011
A16: Petrodromus tetradactylus | B16: Afrotheria | C16: 2 | D16: 132.5 | F16: 2.440 ± 0.109 | H16: 156,830,795 ± 20,600,000 | J16: 103,349,000 ± 15,610,000 | N16: Neves et al., 2014
A17: Tupaia glis | B17: Scandentia | C17: 2 | D17: 172.5 ± 3.5 | F17: 2.752 ± 0.011 | H17: 261400000 | J17: 199650000 | L17: 56.7 | N17: Herculano-Houzel et al., 2007
A18: Cavia porcellus | B18: Glires | C18: 2 | D18: 311.0 ± 49.1 | F18: 3.656 ± 0.486 | H18: 233,557,275 ± 4,085,741 | J18: 228,087,725 ± 9,141,554 | L18: 50.6 ± 1.4 | N18: Herculano-Houzel et al., 2006
A19: Cynomys sp. | B19: Glires | C19: 3 | D19: 1,515 ± 230.6 | F19: 5.321 ± 0.197 | H19: 437,943,767 ± 78,742,230 | J19: 417,349,567 ± 27,350,023 | L19: 51.0 ± 4.2 | N19: Herculano-Houzel et al., 2011
A20: Sciurus carolinensis | B20: Glires | C20: 3 | D20: 500 | F20: 5.548 ± 0.306 | H20: 453,660,197 ± 59,752,698 | J20: 530,476,469 ± 5,605,837 | L20: 46.0 ± 3.0 | N20: Herculano-Houzel et al., 2011
A21: Callithrix jacchus | B21: Primata | C21: 3 | D21: 361.0 ± 1.4 | F21: 7.780 ± 0.654 | H21: 635,800,000 ± 115,730,000 | J21: 590,740,000 ± 70,810,000 | L21: 51.7 | N21: Herculano-Houzel et al., 2007
A22: Oryctolagus cuniculus | B22: Glires | C22: 1 | D22: 4600 | F22: 9.132 | H22: 494205000 | J22: 630795000 | L22: 43.9 | N22: Herculano-Houzel et al., 2011
A23: Otolemur garnettii | B23: Primata | C23: 3 | D23: 946.7 ± 102.6 | F23: 10.150 ± 0.060 | H23: 936,000,000 ± 115,360,000 | J23: 666,590,000 ± 63,500,000 | L23: 58.4 | N23: Herculano-Houzel et al., 2007
A24: Dendrohyrax dorsalis | B24: Afrotheria | C24: 1 | D24: 1150 | F24: 12.8 | H24: 504572834 | J24: 413574000 | N24: Neves et al., 2014
A25: Aotus trivirgatus | B25: Primata | C25: 2 | D25: 925 ± 35 | F25: 15.73 | H25: 1468410000 | J25: 1195130000 | L25: 55.1 | N25: Herculano-Houzel et al., 2007
A26: Procavia capensis | B26: Afrotheria | C26: 2 | D26: 2517 | F26: 16.853 ± 1.495 | H26: 755,653,000 ± 72,145,000 | J26: 620,622,000 ± 37,616,000 | N26: Neves et al., 2014
A27: Dasyprocta prymnolopha | B27: Glires | C27: 3 | D27: 2,843 ± 196 | F27: 17.628 ± 1.900 | H27: 795112070 | J27: 951677930 | L27: 45.5 | N27: Herculano-Houzel et al., 2006
A28: Saimiri sciureus | B28: Primata | C28: 2 | D28: 859 | F28: 30.216 | H28: 3246430000 | J28: 2073030000 | L28: 61 | N28: Herculano-Houzel et al., 2007
A29: Macaca fascicularis | B29: Primata | C29: 1 | D29: 5700 | F29: 46.162 | H29: 3439004620 | J29: 3154415380 | L29: 52.2 | N29: Gabi et al., 2010
A30: Cebus apella | B30: Primata | C30: 1 | D30: 3340 | F30: 52.208 | H30: 3690520000 | J30: 3297740000 | L30: 52.8 | N30: Herculano-Houzel et al., 2007
A31: Macaca radiata | B31: Primata | C31: 1 | D31: 8012 | F31: 61.47 | H31: 3755620300 | J31: 4878879700 | L31: 43.5 | N31: Gabi et al., 2010
A32: Sus scrofa domesticus | B32: Artiodactyla | C32: 1 | D32: 100000 | F32: 64.18 | H32: 2224112553 | J32: 4695783705 | L32: 32.1 | N32: Kazu et al., 2014
A33: Hydrochoerus hydrochaeris | B33: Glires | C33: 2 | D33: 47,500 ± 3,536 | F33: 74.734 ± 3.756 | H33: 1,572,560,385 ± 72,641,426 | J33: 3,197,929,615 ± 974,583,717 | L33: 33.6 ± 5.8 | N33: Herculano-Houzel et al., 2006
A34: Macaca mulatta | B34: Primata | C34: 1 | D34: 3900 | F34: 87.346 | H34: 6376160000 | J34: 7162900000 | L34: 47.1 | N34: Herculano-Houzel et al., 2007
A35: Antidorcas marsupialis | B35: Artiodactyla | C35: 1 | D35: 25000 | F35: 106.074 | H35: 2724595233 | J35: 5912784575 | L35: 31.5 | N35: Kazu et al., 2014
A36: Papio anubis cynocephalus | B36: Primata | C36: 2 | D36: 8000 | F36: 151.194 | H36: 10948086440 | J36: 9175538564 | L36: 54.4 | N36: Gabi et al., 2010
A37: Damaliscus dorcas phillipsi | B37: Artiodactyla | C37: 1 | D37: 60000 | F37: 154.718 | H37: 3058814227 | J37: 9343246559 | L37: 24.7 | N37: Kazu et al., 2014
A38: Tragelaphus strepsiceros | B38: Artiodactyla | C38: 1 | D38: 218000 | F38: 306.86 | H38: 4911651549 | J38: 16977183580 | L38: 22.4 | N38: Kazu et al., 2014
A39: Giraffa camelopardalis | B39: Artiodactyla | C39: 1 | D39: 470000 | F39: 537.218 | H39: 10751287650 | J39: 37912932350 | L39: 23.5 | N39: Kazu et al., 2014
A40: Homo sapiens | B40: Primata | C40: 4 | D40: 70000 | F40: 1,508.910 ± 299.140 | H40: 86,060,000,000 ± 8,120,000,000 | J40: 84,610,000,000 ± 9,830,000,000 | L40: 50.5 ± 3.6 | N40: Azevedo et al., 2009
...

Sheet reformattedTable1cerebrum
A1: Species | B1: Cerebral_Cortex_Order | C1: NA | D1: Cerebral_Cortex_Mass,_g | E1: Cerebral_Cortex_Mass,_g_SD_ | F1: Cerebral_Cortex_N,_n | G1: Cerebral_Cortex_N,_n_SD_ | H1: Cerebral_Cortex_O,_n | I1: Cerebral_Cortex_O,_n_SD_ | J1: Cerebral_Cortex_N/mg | K1: Cerebral_Cortex_N/mg_SD | L1: Cerebral_Cortex_O/mg | M1: Cerebral_Cortex_O/mg__SD | N1: Cerebral_Cortex_O/N | O1: Cerebral_Cortex_O/N_SD_ | P1: Cerebral_Cortex_Source | Q1: Cerebral_Cortex_Species
A2: Sorex fumeus | B2: Eulipotyphla | C2: NA | D2: 0.084 | E2: 0.009 | F2: 9730000 | G2: 352000 | H2: 9290000 | I2: 1112000 | J2: 116727 | K2: 9387 | L2: 111754 | M2: 18566 | N2: 0.958 | O2: 0.135 | P2: Sarko et al., 2009 | Q2: Sorex_fumeus
A3: Mus musculus | B3: Glires | C3: NA | D3: 0.173 | E3: 0.015 | F3: 13688162 | G3: 2242257 | H3: 12061838 | I3: 3668594 | J3: 78672 | K3: 7683 | L3: 68643 | M3: 15807 | N3: 0.87 | O3: 0.177 | P3: Herculano-Houzel et al., 2006 | Q3: Mus_musculus
A4: Blarina brevicauda | B4: Eulipotyphla | C4: NA | D4: 0.197 | E4: 0.012 | F4: 11876000 | G4: 1569000 | H4: 15820000 | I4: 1158000 | J4: 60214 | K4: 4935 | L4: 80729 | M4: 8731 | N4: 1.357 | O4: 0.25 | P4: Sarko et al., 2009 | Q4: Blarina_brevicauda
A5: Heterocephalus glaber | B5: Glires | C5: NA | D5: 0.184 | E5: 0.026 | F5: 6151875 | G5: 1065587 | H5: 8398125 | I5: 1197056 | J5: 33374 | K5: 2063 | L5: 45894 | M5: 11497 | N5: 1.365 | O5: 0.125 | P5: Herculano-Houzel et al., 2011 | Q5: Heterocephalus_glaber
A6: Condylura cristata | B6: Eulipotyphla | C6: NA | D6: 0.42 | E6: 0.024 | F6: 17250000 | G6: 3105000 | H6: 32010000 | I6: 8822000 | J6: 40777 | K6: 5145 | L6: 76995 | M6: 25019 | N6: 1.966 | O6: 0.924 | P6: Sarko et al., 2009 | Q6: Condylura_cristata
A7: Parascalops breweri | B7: Eulipotyphla | C7: NA | D7: 0.429 | E7: 0.019 | F7: 15690000 | G7: 2611000 | H7: 39870000 | I7: 4884000 | J7: 36727 | K7: 7359 | L7: 93185 | M7: 14583 | N7: 2.581 | O7: 0.109 | P7: Sarko et al., 2009 | Q7: Parascalops_breweri
A8: Amblysomus hottentotus | B8: Afrotheria | C8: NA | D8: 0.439 | E8: 0.035 | F8: 21516000 | G8: 2154000 | H8: 21370000 | I8: 4614000 | J8: 48932 | K8: 1004 | L8: 48146 | M8: 6674 | N8: 0.982 | O8: 0.116 | P8: Neves et al., 2014 | Q8: Amblysomus_hottentotus
A9: Scalopus aquaticus | B9: Eulipotyphla | C9: NA | D9: 0.476 | E9: 0.032 | F9: 26680000 | G9: 5113000 | H9: 38540000 | I9: 5567000 | J9: 60461 | K9: 12249 | L9: 80745 | M9: 6407 | N9: 1.383 | O9: 0.368 | P9: Sarko et al., 2009 | Q9: Scalopus_aquaticus
A10: Elephantulus myurus | B10: Afrotheria | C10: NA | D10: 0.471 | E10: 0.021 | F10: 25865000 | G10: 4020000 | H10: 26229000 | I10: 1104000 | J10: 54644 | K10: 6098 | L10: 55693 | M10: 138 | N10: 1.032 | O10: 0.119 | P10: Neves et al., 2014 | Q10: Elephantulus_myurus
A11: Mesocricetus auratus | B11: Glires | C11: NA | D11: 0.446 | E11: 0.048 | F11: 17140000 | G11: 3619934 | H11: 41870000 | I11: 1350121 | J11: 39099 | K11: 12332 | L11: 94271 | M11: 7136 | N11: 2.507 | O11: 0.608 | P11: Herculano-Houzel et al., 2006 | Q11: Mesocricetus_auratus
A12: Rattus norvegicus | B12: Glires | C12: NA | D12: 0.769 | E12: 0.113 | F12: 31017192 | G12: 3034654 | H12: 45687808 | I12: 5678958 | J12: 41092 | K12: 7999 | L12: 60426 | M12: 12477 | N12: 1.497 | O12: 0.328 | P12: Herculano-Houzel et al., 2006 | Q12: Rattus_norvegicus
A13: Microcebus murinus | B13: Primata | C13: NA | D13: 0.908 | E13: NA | F13: 22310400 | G13: NA | H13: 70649600 | I13: NA | J13: 24571 | K13: NA | L13: 77808 | M13: NA | N13: 3.167 | O13: NA | P13: Gabi et al., 2010 | Q13: Microcebus_murinus
A14: Proechimys cayennensis | B14: Glires | C14: NA | D14: 0.924 | E14: 0.05 | F14: 26086024 | G14: 2155723 | H14: 71833039 | I14: 6712722 | J14: 28321 | K14: 3870 | L14: 78011 | M14: 11497 | N14: 2.752 | O14: 0.03 | P14: Herculano-Houzel et al., 2011 | Q14: Proechimys_cayennensis
A15: Petrodromus tetradactylus | B15: Afrotheria | C15: NA | D15: 1.239 | E15: 0.059 | F15: 33947000 | G15: 5840000 | H15: 40486000 | I15: 1104000 | J15: 27236 | K15: 3416 | L15: 32550 | M15: 2661 | N15: 1.202 | O15: 0.053 | P15: Neves et al., 2014 | Q15: Petrodromus_tetradactylus
A16: Tupaia glis | B16: Scandentia | C16: NA | D16: 1.455 | E16: 0.174 | F16: 60390000 | G16: 26510000 | H16: 85580000 | I16: 8400000 | J16: 42900 | K16: 23350 | L16: 58900 | M16: 1270 | N16: 1.417 | O16: NA | P16: Herculano-Houzel et al., 2007 | Q16: Tupaia_glis
A17: Cavia porcellus | B17: Glires | C17: NA | D17: 1.938 | E17: 0.231 | F17: 43510525 | G17: 3169924 | H17: 108614475 | I17: 12775334 | J17: 22508 | K17: 1050 | L17: 56036 | M17: 93 | N17: 2.492 | O17: 0.112 | P17: Herculano-Houzel et al., 2006 | Q17: Cavia_porcellus
A18: Cynomys sp. | B18: Glires | C18: NA | D18: 2.586 | E18: 0.109 | F18: 53768353 | G18: 6044322 | H18: 183451647 | I18: 17959104 | J18: 20866 | K18: 3113 | L18: 71202 | M18: 9677 | N18: 3.432 | O18: 0.433 | P18: Herculano-Houzel et al., 2011 | Q18: Cynomys_sp.
A19: Sciurus carolinensis | B19: Glires | C19: NA | D19: 2.73 | E19: 0.178 | F19: 77334617 | G19: 2634444 | H19: 209654717 | I19: 13003170 | J19: 28384 | K19: 1487 | L19: 76877 | M19: 3859 | N19: 2.709 | O19: 0.076 | P19: Herculano-Houzel et al., 2011 | Q19: Sciurus_carolinensis
A20: Oryctolagus cuniculus | B20: Glires | C20: NA | D20: 4.448 | E20: NA | F20: 71448750 | G20: NA | H20: 254801250 | I20: NA | J20: 16063 | K20: NA | L20: 57284 | M20: NA | N20: 3.566 | O20: NA | P20: Herculano-Houzel et al., 2011 | Q20: Oryctolagus_cuniculus
A21: Callithrix jacchus | B21: Primata | C21: NA | D21: 5.561 | E21: 0.443 | F21: 244720000 | G21: 81180000 | H21: 395340000 | I21: 58790000 | J21: 44280 | K21: 15900 | L21: 71800 | M21: 14880 | N21: 1.615 | O21: NA | P21: Herculano-Houzel et al., 2007 | Q21: Callithrix_jacchus
A22: Otolemur garnettii | B22: Primata | C22: NA | D22: 6.29 | E22: 0.863 | F22: 226090000 | G22: 87570000 | H22: 402070000 | I22: 74790000 | J22: 37820 | K22: 20500 | L22: 63610 | M22: 3400 | N22: 1.778 | O22: NA | P22: Herculano-Houzel et al., 2007 | Q22: Otolemur_garnettii
A23: Dendrohyrax dorsalis | B23: Afrotheria | C23: NA | D23: 7.56 | E23: NA | F23: 98960000 | G23: NA | H23: 183540000 | I23: NA | J23: 13098 | K23: NA | L23: 24291 | M23: NA | N23: 1.855 | O23: NA | P23: Neves et al., 2014 | Q23: Dendrohyrax_dorsalis
A24: Dasyprocta prymnolopha | B24: Glires | C24: NA | D24: 8.913 | E24: 1.214 | F24: 110641950 | G24: 2576768 | H24: 416208050 | I24: 950422 | J24: 13250 | K24: 1633 | L24: 49939 | M24: 7422 | N24: 3.763 | O24: 0.096 | P24: Herculano-Houzel et al., 2006 | Q24: Dasyprocta_prymnolopha
A25: Procavia capensis | B25: Afrotheria | C25: NA | D25: 10.478 | E25: 0.646 | F25: 197933000 | G25: 29082000 | H25: 366620000 | I25: 13520000 | J25: 19134 | K25: 3955 | L25: 35203 | M25: 3461 | N25: 1.883 | O25: 0.208 | P25: Neves et al., 2014 | Q25: Procavia_capensis
A26: Aotus trivirgatus | B26: Primata | C26: NA | D26: 10.617 | E26: 0.61 | F26: 441900000 | G26: 111310000 | H26: 695420000 | I26: 130000000 | J26: 41990 | K26: 12900 | L26: 65330 | M26: 5950 | N26: 1.574 | O26: NA | P26: Herculano-Houzel et al., 2007 | Q26: Aotus_trivirgatus
A27: Callimico goeldii | B27: Primata | C27: NA | D27: 12.984 | E27: NA | F27: 357129180 | G27: NA | H27: 715330820 | I27: NA | J27: 27505 | K27: NA | L27: 55093 | M27: NA | N27: 2.003 | O27: NA | P27: Gabi et al., 2010 | Q27: Callimico_goeldii
A28: Saimiri sciureus | B28: Primata | C28: NA | D28: 20.652 | E28: 0.368 | F28: 1340000000 | G28: 20000000 | H28: 1610000000 | I28: 40000000 | J28: 64930 | K28: 7420 | L28: 77840 | M28: 790 | N28: 1.201 | O28: NA | P28: Herculano-Houzel et al., 2007 | Q28: Saimiri_sciureus
A29: Macaca fascicularis | B29: Primata | C29: NA | D29: 36.226 | E29: NA | F29: 800955000 | G29: NA | H29: 2758845000 | I29: NA | J29: 22110 | K29: NA | L29: 76156 | M29: NA | N29: 3.444 | O29: NA | P29: Gabi et al., 2010 | Q29: Macaca_fascicularis
A30: Cebus apella | B30: Primata | C30: NA | D30: 39.178 | E30: NA | F30: 1140000000 | G30: NA | H30: 2550000000 | I30: NA | J30: 29180 | K30: NA | L30: 64980 | M30: NA | N30: 2.237 | O30: NA | P30: Herculano-Houzel et al., 2007 | Q30: Cebus_apella
A31: Macaca radiata | B31: Primata | C31: NA | D31: 48.274 | E31: NA | F31: 1655707140 | G31: NA | H31: 3808672860 | I31: NA | J31: 34298 | K31: NA | L31: 78897 | M31: NA | N31: 2.3 | O31: NA | P31: Gabi et al., 2010 | Q31: Macaca_radiata
A32: Sus scrofa domesticus | B32: Artiodactyla | C32: NA | D32: 42.404 | E32: NA | F32: 307082404 | G32: NA | H32: 3250251354 | I32: NA | J32: 7276 | K32: NA | L32: 77016 | M32: NA | N32: 10.585 | O32: NA | P32: Kazu et al., 2014 | Q32: Sus_scrofa_domesticus
A33: Hydrochoerus hydrochaeris | B33: Glires | C33: NA | D33: 48.175 | E33: 2.714 | F33: 306501565 | G33: 62726120 | H33: 1847818435 | I33: 512392109 | J33: 6336 | K33: 945 | L33: 38117 | M33: 8489 | N33: 5.983 | O33: 0.447 | P33: Herculano-Houzel et al., 2006 | Q33: Hydrochoerus_hydrochaeris
A34: Antidorcas marsupialis | B34: Artiodactyla | C34: NA | D34: 68.806 | E34: NA | F34: 396896159 | G34: NA | H34: 4126259275 | I34: NA | J34: 5768 | K34: NA | L34: 59969 | M34: NA | N34: 10.396 | O34: NA | P34: Kazu et al., 2014 | Q34: Antidorcas_marsupialis
A35: Macaca mulatta | B35: Primata | C35: NA | D35: 69.832 | E35: NA | F35: 1710000000 | G35: NA | H35: 5270000000 | I35: NA | J35: 24470 | K35: NA | L35: 75400 | M35: NA | N35: 3.082 | O35: NA | P35: Herculano-Houzel et al., 2007 | Q35: Macaca_mulatta
A36: Damaliscus dorcas phillipsi | B36: Artiodactyla | C36: NA | D36: 111.31 | E36: NA | F36: 570673431 | G36: NA | H36: 6762256227 | I36: NA | J36: 5127 | K36: NA | L36: 60760 | M36: NA | N36: 11.851 | O36: NA | P36: Kazu et al., 2014 | Q36: Damaliscus_dorcas_phillipsi
A37: Papio anubis cynocephalus | B37: Primata | C37: NA | D37: 120.214 | E37: NA | F37: 2875028372 | G37: NA | H37: 7569751628 | I37: NA | J37: 23916 | K37: NA | L37: 62969 | M37: NA | N37: 2.633 | O37: NA | P37: Gabi et al., 2010 | Q37: Papio_anubis_cynocephalus
A38: Tragelaphus strepsiceros | B38: Artiodactyla | C38: NA | D38: 213.37 | E38: NA | F38: 762567178 | G38: NA | H38: 12302304448 | I38: NA | J38: 3574 | K38: NA | L38: 57657 | M38: NA | N38: 16.133 | O38: NA | P38: Kazu et al., 2014 | Q38: Tragelaphus_strepsiceros
A39: Giraffa camelopardalis | B39: Artiodactyla | C39: NA | D39: 398.808 | E39: NA | F39: 1730513460 | G39: NA | H39: 27513706540 | I39: NA | J39: 4339 | K39: NA | L39: 68990 | M39: NA | N39: 15.9 | O39: NA | P39: Kazu et al., 2014 | Q39: Giraffa_camelopardalis
A40: Homo sapiens | B40: Primata | C40: NA | D40: 1232.93 | E40: 233.68 | F40: 16340000000 | G40: 2170000000 | H40: 60840000000 | I40: 7020000000 | J40: 13520 | K40: 3636 | L40: 49230 | M40: 3755 | N40: 3.723 | O40: 0.675 | P40: Azevedo et al., 2009 | Q40: Homo_sapiens
...

Sheet reformattedTable2cerebellum
A1: Species | B1: Cerebellum_Order | C1: NA | D1: Cerebellum_Mass,_g | E1: Cerebellum_Mass,_g_SD_ | F1: Cerebellum_N,_n | G1: Cerebellum_N,_n_SD_ | H1: Cerebellum_O,_n | I1: Cerebellum_O,_n_SD_ | J1: Cerebellum_N/mg | K1: Cerebellum_N/mg_SD_ | L1: Cerebellum_O/mg | M1: Cerebellum_O/mg_SD_ | N1: Cerebellum_O/N | O1: Cerebellum_O/N_SD_ | P1: Cerebellum_Source | Q1: Cerebellum_Species
A2: Sorex fumeus | B2: Eulipotyphla | C2: NA | D2: 0.02 | E2: 0.002 | F2: 20870000 | G2: 4660000 | H2: 5290000 | I2: 2120000 | J2: 1038666 | K2: 214440 | L2: 258073 | M2: 85510 | N2: 0.253 | O2: NA | P2: Sarko et al., 2009 | Q2: Sorex_fumeus
A3: Blarina brevicauda | B3: Eulipotyphla | C3: NA | D3: 0.037 | E3: 0.005 | F3: 33430000 | G3: 5821000 | H3: 4410000 | I3: 1280000 | J3: 919942 | K3: 19721 | L3: 118736 | M3: 25620 | N3: 0.132 | O3: NA | P3: Sarko et al., 2009 | Q3: Blarina_brevicauda
A4: Heterocephalus glaber | B4: Glires | C4: NA | D4: 0.048 | E4: 0.004 | F4: 15742270 | G4: 2849254 | H4: 5482730 | I4: 1274352 | J4: 327280 | K4: 48331 | L4: 115748 | M4: 32952 | N4: 0.356 | O4: 0.106 | P4: Herculano-Houzel et al., 2011 | Q4: Heterocephalus_glaber
A5: Mus musculus | B5: Glires | C5: NA | D5: 0.056 | E5: 0.005 | F5: 42219708 | G5: 9277647 | H5: 6947791 | I5: 1502773 | J5: 746691 | K5: 128541 | L5: 123493 | M5: 25715 | N5: 0.165 | O5: 0.017 | P5: Herculano-Houzel et al., 2006 | Q5: Mus_musculus
A6: Amblysomus hottentotus | B6: Afrotheria | C6: NA | D6: 0.084 | E6: NA | F6: 34488379 | G6: 3207000 | H6: 8155621 | I6: 813000 | J6: 409687 | K6: 18667 | L6: 96849 | M6: 5069 | N6: 0.236 | O6: 0.002 | P6: Neves et al., 2014 | Q6: Amblysomus_hottentotus
A7: Parascalops breweri | B7: Eulipotyphla | C7: NA | D7: 0.102 | E7: 0.005 | F7: 100780000 | G7: 13850000 | H7: 7010000 | I7: 1100000 | J7: 997370 | K7: 173030 | L7: 68795 | M7: 7910 | N7: 0.07 | O7: NA | P7: Sarko et al., 2009 | Q7: Parascalops_breweri
A8: Condylura cristata | B8: Eulipotyphla | C8: NA | D8: 0.138 | E8: 0.012 | F8: 105920000 | G8: 22100000 | H8: 19480000 | I8: 6420000 | J8: 776460 | K8: 181530 | L8: 139912 | M8: 39720 | N8: 0.184 | O8: NA | P8: Sarko et al., 2009 | Q8: Condylura_cristata
A9: Mesocricetus auratus | B9: Glires | C9: NA | D9: 0.145 | E9: 0.03 | F9: 61210000 | G9: 12351246 | H9: 7430000 | I9: 1713108 | J9: 424002 | K9: 3743 | L9: 51332 | M9: 1054 | N9: 0.121 | O9: 0.004 | P9: Herculano-Houzel et al., 2006 | Q9: Mesocricetus_auratus
A10: Scalopus aquaticus | B10: Eulipotyphla | C10: NA | D10: 0.153 | E10: 0.008 | F10: 158550000 | G10: 13630000 | H10: 17510000 | I10: 3160000 | J10: 1037390 | K10: 63570 | L10: 114660 | M10: 20790 | N10: 0.11 | O10: NA | P10: Sarko et al., 2009 | Q10: Scalopus_aquaticus
A11: Elephantulus myurus | B11: Afrotheria | C11: NA | D11: 0.168 | E11: NA | F11: 89312372 | G11: 2852000 | H11: 23368628 | I11: 1279000 | J11: 531494 | K11: 10651 | L11: 139028 | M11: 5956 | N11: 0.261 | O11: 0.005 | P11: Neves et al., 2014 | Q11: Elephantulus_myurus
A12: Rattus norvegicus | B12: Glires | C12: NA | D12: 0.272 | E12: 0.038 | F12: 139171882 | G12: 11185675 | H12: 29005617 | I12: 6282204 | J12: 522688 | K12: 108847 | L12: 108555 | M12: 29355 | N12: 0.209 | O12: 0.047 | P12: Herculano-Houzel et al., 2006 | Q12: Rattus_norvegicus
A13: Petrodromus tetradactylus | B13: Afrotheria | C13: NA | D13: 0.304 | E13: NA | F13: 110653150 | G13: 14948000 | H13: 34657851 | I13: 15801000 | J13: 362537 | K13: 15780 | L13: 110153 | M13: 41831 | N13: 0.299 | O13: 0.102 | P13: Neves et al., 2014 | Q13: Petrodromus_tetradactylus
A14: Tupaia glis | B14: Scandentia | C14: NA | D14: 0.326 | E14: 0.018 | F14: 185280000 | G14: 16980000 | H14: 19980000 | I14: 1510000 | J14: 571460 | K14: 83200 | L14: 61600 | M14: 7990 | N14: 0.108 | O14: NA | P14: Herculano-Houzel et al., 2007 | Q14: Tupaia_glis
A15: Proechimys cayennensis | B15: Glires | C15: NA | D15: 0.33 | E15: 0.026 | F15: 162512050 | G15: 3553848 | H15: 36372950 | I15: 5094068 | J15: 494338 | K15: 28466 | L15: 110122 | M15: 6716 | N15: 0.224 | O15: 0.026 | P15: Herculano-Houzel et al., 2011 | Q15: Proechimys_cayennensis
A16: Microcebus murinus | B16: Primata | C16: NA | D16: 0.391 | E16: NA | F16: 221386140 | G16: NA | H16: 17433860 | I16: NA | J16: 566205 | K16: NA | L16: 44588 | M16: NA | N16: 0.079 | O16: NA | P16: Gabi et al., 2010 | Q16: Microcebus_murinus
A17: Cavia porcellus | B17: Glires | C17: NA | D17: 0.5 | E17: 0.077 | F17: 167854925 | G17: 2175973 | H17: 36290075 | I17: 4506186 | J17: 339755 | K17: 48069 | L17: 72824 | M17: 2216 | N17: 0.216 | O17: 0.024 | P17: Herculano-Houzel et al., 2006 | Q17: Cavia_porcellus
A18: Callithrix jacchus | B18: Primata | C18: NA | D18: 0.73 | E18: 0.039 | F18: 361370000 | G18: 28530000 | H18: 49490000 | I18: 6770000 | J18: 494970 | K18: 25740 | L18: 68170 | M18: 12210 | N18: 0.137 | O18: NA | P18: Herculano-Houzel et al., 2007 | Q18: Callithrix_jacchus
A19: Cynomys sp. | B19: Glires | C19: NA | D19: 0.789 | E19: 0.093 | F19: 350084813 | G19: 72177851 | H19: 66155187 | I19: 39268821 | J19: 440658 | K19: 39554 | L19: 84802 | M19: 54286 | N19: 0.192 | O19: 0.123 | P19: Herculano-Houzel et al., 2011 | Q19: Cynomys_sp.
A20: Sciurus carolinensis | B20: Glires | C20: NA | D20: 0.874 | E20: 0.069 | F20: 342832180 | G20: 71181798 | H20: 110797820 | I20: 9070639 | J20: 392363 | K20: 74294 | L20: 127682 | M20: 19212 | N20: 0.336 | O20: 0.09 | P20: Herculano-Houzel et al., 2011 | Q20: Sciurus_carolinensis
A21: Otolemur garnettii | B21: Primata | C21: NA | D21: 1.196 | E21: 0.105 | F21: 743500000 | G21: 52450000 | H21: 65960000 | I21: 20290000 | J21: 623080 | K21: 45720 | L21: 54460 | M21: 11890 | N21: 0.089 | O21: NA | P21: Herculano-Houzel et al., 2007 | Q21: Otolemur_garnettii
A22: Oryctolagus cuniculus | B22: Glires | C22: NA | D22: 1.412 | E22: NA | F22: 396671250 | G22: NA | H22: 124578750 | I22: NA | J22: 280929 | K22: NA | L22: 88229 | M22: NA | N22: 1.222 | O22: NA | P22: Herculano-Houzel et al., 2011 | Q22: Oryctolagus_cuniculus
A23: Aotus trivirgatus | B23: Primata | C23: NA | D23: 1.732 | E23: 0.218 | F23: 1040000000 | G23: 20000000 | H23: 145270000 | I23: 45030000 | J23: 605080 | K23: 90570 | L23: 82890 | M23: 15580 | N23: 0.14 | O23: NA | P23: Herculano-Houzel et al., 2007 | Q23: Aotus_trivirgatus
A24: Dendrohyrax dorsalis | B24: Afrotheria | C24: NA | D24: 1.918 | E24: NA | F24: 360929350 | G24: NA | H24: 77570650 | I24: NA | J24: 188180 | K24: NA | L24: 40444 | M24: NA | N24: 0.215 | O24: NA | P24: Neves et al., 2014 | Q24: Dendrohyrax_dorsalis
A25: Procavia capensis | B25: Afrotheria | C25: NA | D25: 2.058 | E25: NA | F25: 488373000 | G25: 42322000 | H25: 91005000 | I25: 30180000 | J25: 242415 | K25: 46950 | L25: 46365 | M25: 19711 | N25: 0.182 | O25: 0.046 | P25: Neves et al., 2014 | Q25: Procavia_capensis
A26: Dasyprocta prymnolopha | B26: Glires | C26: NA | D26: 2.742 | E26: NA | F26: 673488085 | G26: 48145960 | H26: 155986915 | I26: 32978520 | J26: 253208 | K26: 39447 | L26: 57945 | M26: 7405 | N26: 0.234 | O26: 0.066 | P26: Herculano-Houzel et al., 2006 | Q26: Dasyprocta_prymnolopha
A27: Saimiri sciureus | B27: Primata | C27: NA | D27: 4.3 | E27: NA | F27: 1820000000 | G27: NA | H27: 133020000 | I27: NA | J27: 424000 | K27: NA | L27: 30940 | M27: NA | N27: 0.073 | O27: NA | P27: Herculano-Houzel et al., 2007 | Q27: Saimiri_sciureus
A28: Cebus apella | B28: Primata | C28: NA | D28: 4.6 | E28: NA | F28: 2490000000 | G28: NA | H28: 245810000 | I28: NA | J28: 540310 | K28: NA | L28: 53440 | M28: NA | N28: 0.099 | O28: NA | P28: Herculano-Houzel et al., 2007 | Q28: Cebus_apella
A29: Macaca fascicularis | B29: Primata | C29: NA | D29: 5.642 | E29: NA | F29: 2572600000 | G29: NA | H29: 135400000 | I29: NA | J29: 455973 | K29: NA | L29: 23999 | M29: NA | N29: 0.053 | O29: NA | P29: Gabi et al., 2010 | Q29: Macaca_fascicularis
A30: Macaca radiata | B30: Primata | C30: NA | D30: 5.748 | E30: NA | F30: 2038554160 | G30: NA | H30: 453565840 | I30: NA | J30: 354655 | K30: NA | L30: 78908 | M30: NA | N30: 0.222 | O30: NA | P30: Gabi et al., 2010 | Q30: Macaca_radiata
A31: Hydrochoerus hydrochaeris | B31: Glires | C31: NA | D31: 6.632 | E31: 1.312 | F31: 1157810000 | G31: 5515433 | H31: 570940000 | I31: 81105148 | J31: 177982 | K31: 34889 | L31: 86574 | M31: 4902 | N31: 0.493 | O31: 0.068 | P31: Herculano-Houzel et al., 2006 | Q31: Hydrochoerus_hydrochaeris
A32: Macaca mulatta | B32: Primata | C32: NA | D32: 7.694 | E32: NA | F32: 4550000000 | G32: NA | H32: 931030000 | I32: NA | J32: 590800 | K32: NA | L32: 121010 | M32: NA | N32: 0.205 | O32: NA | P32: Herculano-Houzel et al., 2007 | Q32: Macaca_mulatta
A33: Sus scrofa domesticus | B33: Artiodactyla | C33: NA | D33: 8.128 | E33: NA | F33: 1858320313 | G33: NA | H33: 348710938 | I33: NA | J33: 228632 | K33: NA | L33: 42902 | M33: NA | N33: 0.188 | O33: NA | P33: Kazu et al., 2014 | Q33: Sus_scrofa_domesticus
A34: Antidorcas marsupialis | B34: Artiodactyla | C34: NA | D34: 11.458 | E34: NA | F34: 2257214074 | G34: NA | H34: 467244676 | I34: NA | J34: 196999 | K34: NA | L34: 40779 | M34: NA | N34: 0.207 | O34: NA | P34: Kazu et al., 2014 | Q34: Antidorcas_marsupialis
A35: Damaliscus dorcas phillipsi | B35: Artiodactyla | C35: NA | D35: 13.402 | E35: NA | F35: 2401712670 | G35: NA | H35: 443918456 | I35: NA | J35: 179206 | K35: NA | L35: 33123 | M35: NA | N35: 0.184 | O35: NA | P35: Kazu et al., 2014 | Q35: Damaliscus_dorcas_phillipsi
A36: Papio anubis cynocephalus | B36: Primata | C36: NA | D36: 13.745 | E36: NA | F36: 7794907300 | G36: NA | H36: 525977700 | I36: NA | J36: 567109 | K36: NA | L36: 38267 | M36: NA | N36: 0.067 | O36: NA | P36: Gabi et al., 2010 | Q36: Papio_anubis_cynocephalus
A37: Tragelaphus strepsiceros | B37: Artiodactyla | C37: NA | D37: 31.776 | E37: NA | F37: 4042494141 | G37: NA | H37: 1266099609 | I37: NA | J37: 127218 | K37: NA | L37: 39845 | M37: NA | N37: 0.313 | O37: NA | P37: Kazu et al., 2014 | Q37: Tragelaphus_strepsiceros
A38: Pongo pygmaeus | B38: Primata | C38: NA | D38: 35.06 | E38: 4.34 | F38: 26300000000 | G38: 2470000000 | H38: 2200000000 | I38: NA | J38: 750143 | K38: NA | L38: 62750 | M38: NA | N38: 0.084 | O38: NA | P38: Herculano-Houzel and Kaas, 2011 | Q38: Pongo_pygmaeus
A39: Gorilla gorilla | B39: Primata | C39: NA | D39: 37.56 | E39: NA | F39: 26400000000 | G39: NA | H39: 2900000000 | I39: NA | J39: 702875 | K39: NA | L39: 77210 | M39: NA | N39: 0.11 | O39: NA | P39: Herculano-Houzel and Kaas, 2011 | Q39: Gorilla_gorilla
A40: Giraffa camelopardalis | B40: Artiodactyla | C40: NA | D40: 67.73 | E40: NA | F40: 8878076563 | G40: NA | H40: 5520360938 | I40: NA | J40: 131080 | K40: NA | L40: 81505 | M40: NA | N40: 0.622 | O40: NA | P40: Kazu et al., 2014 | Q40: Giraffa_camelopardalis
...

Sheet reformattedTable3RoB
A1: Species | B1: RoB_Order | C1: NA | D1: RoB_Mass,_g | E1: RoB_Mass,_g_SD_ | F1: RoB_N,_n | G1: RoB_N,_n_SD_ | H1: RoB_O,_n | I1: RoB_O,_n_SD_ | J1: RoB_N/mg | K1: RoB_N/mg_SD_ | L1: RoB_O/mg | M1: RoB_O/mg_SD_ | N1: RoB_O/N | O1: RoB_O/N_SD_ | P1: RoB_Source | Q1: RoB_Species
A2: Sorex fumeus | B2: Eulipotyphla | C2: NA | D2: 0.072 | E2: 0.01 | F2: 5560000 | G2: 1490000 | H2: 8280000 | I2: 1440000 | J2: 75941 | K2: 11870 | L2: 114880 | M2: 17860 | N2: 1.489 | O2: 0.294 | P2: Sarko et al., 2009 | Q2: Sorex_fumeus
A3: Blarina brevicauda | B3: Eulipotyphla | C3: NA | D3: 0.113 | E3: 0.009 | F3: 6340000 | G3: 636200 | H3: 13320000 | I3: 1120000 | J3: 55924 | K3: 2130 | L3: 117736 | M3: 5840 | N3: 2.102 | O3: 0.096 | P3: Sarko et al., 2009 | Q3: Blarina_brevicauda
A4: Heterocephalus glaber | B4: Glires | C4: NA | D4: 0.16 | E4: 0.019 | F4: 4981317 | G4: 853026 | H4: 10310350 | I4: 1843572 | J4: 31674 | K4: 8484 | L4: 64145 | M4: 3790 | N4: 2.125 | O4: NA | P4: Herculano-Houzel et al., 2011 | Q4: Heterocephalus_glaber
A5: Mus musculus | B5: Glires | C5: NA | D5: 0.172 | E5: 0.019 | F5: 11960000 | G5: 1577022 | H5: 14850000 | I5: 3590591 | J5: 64301 | K5: 6623 | L5: 79839 | M5: 11249 | N5: 1.242 | O5: NA | P5: Herculano-Houzel et al., 2006 | Q5: Mus_musculus
A6: Parascalops breweri | B6: Eulipotyphla | C6: NA | D6: 0.228 | E6: 0.009 | F6: 7130000 | G6: 920000 | H6: 31380000 | I6: 1500000 | J6: 31276 | K6: 3180 | L6: 137960 | M6: 7180 | N6: 4.401 | O6: 0.375 | P6: Sarko et al., 2009 | Q6: Parascalops_breweri
A7: Condylura cristata | B7: Eulipotyphla | C7: NA | D7: 0.244 | E7: 0.026 | F7: 8160000 | G7: 2180000 | H7: 31550000 | I7: 5950000 | J7: 33475 | K7: 8560 | L7: 128990 | M7: 17820 | N7: 3.866 | O7: 1.692 | P7: Sarko et al., 2009 | Q7: Condylura_cristata
A8: Amblysomus hottentotus | B8: Afrotheria | C8: NA | D8: 0.289 | E8: 0.013 | F8: 9070358 | G8: 1069000 | H8: 16834642 | I8: 3276000 | J8: 31616 | K8: 5124 | L8: 58880 | M8: 13983 | N8: 1.839 | O8: 0.144 | P8: Neves et al., 2014 | Q8: Amblysomus_hottentotus
A9: Scalopus aquaticus | B9: Eulipotyphla | C9: NA | D9: 0.37 | E9: 0.042 | F9: 16560000 | G9: 2990000 | H9: 45690000 | I9: 4820000 | J9: 44620 | K9: 4900 | L9: 123600 | M9: 2550 | N9: 2.759 | O9: 0.379 | P9: Sarko et al., 2009 | Q9: Scalopus_aquaticus
A10: Mesocricetus auratus | B10: Glires | C10: NA | D10: 0.375 | E10: 0.057 | F10: 5870000 | G10: 1162059 | H10: 21330000 | I10: 8878857 | J10: 15611 | K10: 715 | L10: 55804 | M10: 15174 | N10: 3.556 | O10: NA | P10: Herculano-Houzel et al., 2006 | Q10: Mesocricetus_auratus
A11: Elephantulus myurus | B11: Afrotheria | C11: NA | D11: 0.401 | E11: 0.063 | F11: 14012533 | G11: 3258000 | H11: 28997467 | I11: 7906000 | J11: 34520 | K11: 2702 | L11: 70967 | M11: 8566 | N11: 2.048 | O11: 0.088 | P11: Neves et al., 2014 | Q11: Elephantulus_myurus
